Workbook

Sheet Sheet0
A1: PROLIFIC_PID | B1: Q4 | C1: Q5 | D1: Q15 | E1: QID18 | F1: QID72 | G1: QID62 | H1: QID53 | I1: QID43
A2: PROLIFIC_PID | B2: What is your age? | C2: What is your highest level of education? | D2: Please select the domain that best describes your current occupation: | E2: Petra and Ana are discussing politics: Petra: They all sort of group together. Ana: The workers. Petra: Yeah, yeah. No, it was more than that because, like, it was just people felt run down. Ana: Yeah. Petra: They felt like that as though the system had screwed them over. Ana: That's fair enough, yeah. That's cool, yeah. Petra: Sort of like, that's why they blew up the credit card companies. Ana: Oh, yeah, yeah. Petra: Cos they were sick of er... Ana: When he tried to blow those up. Petra: Yeah, yeah, yeah. I guess it is revolution-style. What do you think is conveyed by Petra in the underlined text? | F2: Maddie and Charlie are discussing crime and punishment: Maddie: I'm thinking there must be an alternative to slapping someone behind bars. Charlie: Mm. Maddie: Because the rate at which inmates are going into prison is far higher than the rate of releases, so. Charlie: Yes, and the reoffending rate is. Maddie: Is really high. Charlie: Very, very high. Maddie: Yes, so it doesn't take a rocket scientist to work out that unless we build more prisons this whole system is gonna crumble. Charlie: Yeah. Maddie: It's gonna, it's gonna, everything is going to come to a head. What do you think is conveyed by Maddie in the underlined text? | G2: Madeline and Katy are discussing the weather: Madeline: Don't know. Anyway, it's going to be hot, hot, hot. Katy: Yeah. Madeline: And I'm going to be wearing more clothes. Katy: Yeah, well that's going to be a bit of a shock to the system, isn't it? Madeline: But hopefully breezy. We're going to have to try on all our work clothes. Katy: Yeah. Gonna have to get used to going from air con to outside. What do you think is conveyed by Katy in the underlined text? | H2: Tanya and Max are discussing job skills: Tanya: For a lot of professions you need to be good at dealing with people. Max: You've gotta be- Tanya: But all our exams are about intellect and nothing to do with people. Max: Yes, that's right. Tanya: Cos we've never come up with a good system for measuring your capability with people. Max: No. Tanya: And a lot of jobs you need to be able to communicate, don't you? Max: If you're in charge of a firm of any description you've gotta be able to get on well with people, otherwise you're in trouble. What do you think is conveyed by Tanya in the underlined text? | I2: Abbie and Xander are discussing motorbikes: Abbie: There's this company who bought out the old Triumph. Xander: Yeah. Abbie: And sort of started off just making replacement parts and stuff like that. Xander: Yeah. Abbie: And then sort of slowly had one bike and then got some money from somewhere and redesigned the whole system. Xander: Yeah. Abbie: But they worked out the principle that they would make twins. I don't think they ma- no they don't make a single, they make twins, a triple, and a four-cylinder bike, you know, with different engines. Xander: Yeah. Abbie: You know these three different engines but nearly all the parts were interchangeable, like the pistons and the rods. What do you think is conveyed by Abbie in the underlined text?
A3: 5a25a9a3b51f2c0001e5d9ed | B3: 45 - 54 | C3: Master’s Degree (e.g. MA. MSc) | D3: Sales and Marketing
A4: 5c56159a9194d30001a4c498 | B4: 25 - 34 | C4: GCSE/O-level | D4: Finance and Banking | F4: Prisons are overcrowded and the system will collapse soon.
A5: 5cbb3393114fa50001ac523f | B5: 35 - 44 | C5: Bachelors Degree (e.g BA, BSc) | D5: Unemployed
A6: 665d81612779f576bd35047e | B6: 35 - 44 | C6: Vocational Qualifications (e.g. NVQs, BTEC) | D6: Information Technology and Software Development
A7: 5c345ebad4f77a0001a91ec0 | B7: 55 - 64 | C7: Higher National Certificate/higher National Diploma | D7: Information Technology and Software Development
A8: 63ed0d717ceb58b69ff6ce58 | B8: 25 - 34 | C8: Bachelors Degree (e.g BA, BSc) | D8: Engineering and Manufacturing
A9: 5ad3bcc05b53cb0001f3581c | B9: 25 - 34 | C9: Bachelors Degree (e.g BA, BSc) | D9: Nonprofit and Social Services | I9: She is really interested in the topic but has not noticed xander is not interested
A10: 5f1beeacb55680420cfcae9e | B10: 55 - 64 | C10: Master’s Degree (e.g. MA. MSc) | D10: Engineering and Manufacturing | G10: Kstybisvused to bring psrtosllt clothed or lifhtkt ck9thed as it has been warm
A11: 64135a5db4a0ab6ceb843e64 | B11: 35 - 44 | C11: A-levels/Highers | D11: Nonprofit and Social Services
A12: 5ee3be6ff942c407cd54e6ce | B12: 55 - 64 | C12: A-levels/Highers | D12: Retired
A13: 5d404c6a584cc80017e81001 | B13: 55 - 64 | C13: Bachelors Degree (e.g BA, BSc) | D13: Retired | E13: People thought that the powers that be/ the government had let them down badly.
A14: 63039343fd5a2e6fb88d2c61 | B14: 35 - 44 | C14: Bachelors Degree (e.g BA, BSc) | D14: Retail and Customer Service | F14: Maddie thinks we need a new way to deal with offenders other than prison.
A15: 5a455b091950a80001e7c49a | B15: 35 - 44 | C15: Vocational Qualifications (e.g. NVQs, BTEC) | D15: Law and Legal Services | G15: That wearing more clothes because of the work uniform will take some getting used to as they are most likely used to wearing whats comfortable
A16: 5b3648e7f726b2000192b3f4 | B16: 25 - 34 | C16: Bachelors Degree (e.g BA, BSc) | D16: Education and Training
A17: 60ddcc052137212419247c3c | B17: 35 - 44 | C17: GCSE/O-level | D17: Unemployed | H17: There has never been a system invented that measures someone's people skills
A18: 5e94acdc3d1b5780b00d12ff | B18: 35 - 44 | C18: Bachelors Degree (e.g BA, BSc) | D18: Healthcare and Medicine
A19: 6346c4b13753efab830182aa | B19: 25 - 34 | C19: Master’s Degree (e.g. MA. MSc) | D19: Consulting and Business Services | F19: that more prisons are needed to be built
A20: 62d133c506e7167dd2b29652 | B20: 25 - 34 | C20: Master’s Degree (e.g. MA. MSc) | D20: Government and Public Administration | E20: petra is saying that employees feel like they have been exploited by the system implemented by the government
A21: 6658ddf98f1ee667f426458f | B21: 35 - 44 | C21: Bachelors Degree (e.g BA, BSc) | D21: Government and Public Administration | E21: Im struggling to make sense of this one. I feel petra is angry. But maybe she doesnt quite fully understand what she is talking about.
A22: 6124112341a3ec8fdf0f4886 | B22: 35 - 44 | C22: Vocational Qualifications (e.g. NVQs, BTEC) | D22: Law and Legal Services
A23: 5b914e471c4a9b0001d2b9df | B23: 25 - 34 | C23: Bachelors Degree (e.g BA, BSc) | D23: Education and Training
A24: 60fd46f4d7e9142ecae97701 | B24: 25 - 34 | C24: Bachelors Degree (e.g BA, BSc) | D24: Finance and Banking | F24: That the amount of people going to prison is putting strain on the prison service, and that more prisons are required to house the number of people being convicted
A25: 5599dbe6fdf99b4a3c5bc628 | B25: 35 - 44 | C25: A-levels/Highers | D25: Unemployed
A26: 665f567da83b58036682b894 | B26: 25 - 34 | C26: Bachelors Degree (e.g BA, BSc) | D26: Education and Training
A27: 5ecbe220d068807a5425c4de | B27: 55 - 64 | C27: Bachelors Degree (e.g BA, BSc) | D27: Education and Training
A28: 5f2afec0781f2848ac688140 | B28: 35 - 44 | C28: A-levels/Highers | D28: Unemployed
A29: 5ffb432901d8311622530a52 | B29: 25 - 34 | C29: Bachelors Degree (e.g BA, BSc) | D29: Education and Training
A30: 5b086831a6f07e00018b8f08 | B30: 25 - 34 | C30: Vocational Qualifications (e.g. NVQs, BTEC) | D30: Healthcare and Medicine
A31: 5b99238d30357200010c9ddc | B31: 35 - 44 | C31: Bachelors Degree (e.g BA, BSc) | D31: Arts and Humanities | I31: updated the look of the bike
A32: 6668621f3facbbc4d81945ce | B32: 25 - 34 | C32: Vocational Qualifications (e.g. NVQs, BTEC) | D32: Information Technology and Software Development | F32: more prisons required rather than tackle the cause of the issue
A33: 5efda9898d99db1ffd211946 | B33: 25 - 34 | C33: Bachelors Degree (e.g BA, BSc) | D33: Education and Training | H33: That exams aren’t everything. Even if you have the highest grades, it doesn’t mean you will automatically do well in a workplace. There’s more factors to consider than their academic achievement.
A34: 6714b6ad76097533a378e7d3 | B34: 25 - 34 | C34: GCSE/O-level | D34: Construction and Skilled Trades | E34: The system is corrupt and used against you.
A35: 586a26807fbbcd00013974f1 | B35: 35 - 44 | C35: Bachelors Degree (e.g BA, BSc) | D35: Unemployed
A36: 6066d08253019ea549b1dd37 | B36: 35 - 44 | C36: Bachelors Degree (e.g BA, BSc) | D36: Education and Training | G36: That the fact that Madeline is going. To be wearing more clothes is going to be unusual and not what she has been used to
A37: 665878a26c1a7b4d33dcfeb4 | B37: 25 - 34 | C37: Vocational Qualifications (e.g. NVQs, BTEC) | D37: Retail and Customer Service
A38: 616829767ddec9e42886501d | B38: 35 - 44 | C38: Master’s Degree (e.g. MA. MSc) | D38: Nonprofit and Social Services
A39: 62e16099ec12fdc57a0cf63a | B39: 25 - 34 | C39: Bachelors Degree (e.g BA, BSc) | D39: Law and Legal Services
A40: 62bcc530c8492b5c9e448f74 | B40: 65 - 74 | C40: GCSE/O-level | D40: Transportation and Logistics | E40: That the system is broken
...

Sheet System Screwed them over
A1: QID18 | F1: Comment | G1: Certainty
A2: They felt like that as though the system had screwed them over. | B2: DPS | C2: SIT | D2: INF | E2: EVA
A3: People thought that the powers that be/ the government had let them down badly. | B3: TRUE | C3: FALSE | D3: FALSE | E3: FALSE | F3: paraphrase | G3: 3 | I3: Petra and Ana are discussing politics: Petra: They all sort of group together. Ana: The workers. Petra: Yeah, yeah. No, it was more than that because, like, it was just people felt run down. Ana: Yeah. Petra: They felt like that as though the system had screwed them over. Ana: That's fair enough, yeah. That's cool, yeah. Petra: Sort of like, that's why they blew up the credit card companies. Ana: Oh, yeah, yeah. Petra: Cos they were sick of er... Ana: When he tried to blow those up. Petra: Yeah, yeah, yeah. I guess it is revolution-style. What do you think is conveyed by Petra in the underlined text?
A4: petra is saying that employees feel like they have been exploited by the system implemented by the government | B4: TRUE | C4: FALSE | D4: FALSE | E4: FALSE | F4: paraphrase | G4: 3
A5: Im struggling to make sense of this one. I feel petra is angry. But maybe she doesnt quite fully understand what she is talking about. | B5: FALSE | C5: FALSE | D5: FALSE | E5: FALSE | G5: 3
A6: The system is corrupt and used against you. | B6: FALSE | C6: FALSE | D6: TRUE | E6: FALSE | F6: it being used against you is an inference | G6: 3
A7: That the system is broken | B7: FALSE | C7: FALSE | D7: TRUE | E7: FALSE | F7: broken not directly stated | G7: 3
A8: she’s sympathising with a group of people | B8: FALSE | C8: FALSE | D8: FALSE | E8: TRUE | F8: attributing emotion | G8: 3
A9: I really don’t know | B9: FALSE | C9: FALSE | D9: FALSE | E9: FALSE | G9: 3
A10: she was trying to explain how they felt | B10: FALSE | C10: FALSE | D10: FALSE | E10: FALSE | G10: 3
A11: A group of people felt systematically oppressed and angry | B11: TRUE | C11: FALSE | D11: FALSE | E11: FALSE | F11: paraphrase | G11: 3
A12: People feel that they are in hardship that is not their fault but a result of the way society is structured | B12: FALSE | C12: FALSE | D12: TRUE | E12: FALSE | F12: inference | G12: 3
A13: People was down because they didn’t get thier own way | B13: FALSE | C13: FALSE | D13: TRUE | E13: FALSE | F13: inference | G13: 3
A14: The system seems to be out for everyone. | B14: FALSE | C14: FALSE | D14: TRUE | E14: FALSE | F14: inference | G14: 3
A15: She is trying to explain public opinion about credit card companies and systems. | B15: FALSE | C15: FALSE | D15: FALSE | E15: FALSE | G15: 3
A16: Socialism or Marxism | B16: FALSE | C16: FALSE | D16: TRUE | E16: FALSE | F16: inference | G16: 3
A17: People are feeling angry at working conditions | B17: FALSE | C17: TRUE | D17: FALSE | E17: FALSE | F17: working conditions not the system | G17: 3
A18: petra is saying the workers felt like the system had screwed them over | B18: TRUE | C18: FALSE | D18: FALSE | E18: FALSE | F18: paraphrase | G18: 3
A19: They felt hard done by | B19: TRUE | C19: FALSE | D19: FALSE | E19: FALSE | F19: paraphrase | G19: 3
A20: that the system had screwed a group of people | B20: TRUE | C20: FALSE | D20: FALSE | E20: FALSE | F20: paraphrase | G20: 3
A21: that the system had screwed them over | B21: TRUE | C21: FALSE | D21: FALSE | E21: FALSE | F21: paraphrase | G21: 3
A22: no idea | B22: FALSE | C22: FALSE | D22: FALSE | E22: FALSE | G22: 3
A23: People felt let down and betrayed by institutions such as large companies. | B23: TRUE | C23: FALSE | D23: FALSE | E23: FALSE | F23: paraphrase | G23: 3
A24: Empathy with people who felt marginalised | B24: FALSE | C24: FALSE | D24: FALSE | E24: TRUE | F24: attributing emotion | G24: 3
A25: Petra is saying that workers are fed up of the system. | B25: dps | C25: FALSE | D25: FALSE | E25: FALSE | F25: paraphrase | G25: 3
A26: That the system in which the workers work had betrayed the workers | B26: TRUE | C26: FALSE | D26: FALSE | E26: FALSE | F26: paraphrase | G26: 3
A27: That the people they knew about weren't treated fairly by the policies/procedures that the company had. | B27: TRUE | C27: FALSE | D27: FALSE | E27: FALSE | F27: paraphrase | G27: 3
A28: WORKERS HAVE BEEN LET DOWN | B28: TRUE | C28: FALSE | D28: FALSE | E28: FALSE | F28: paraphrase | G28: 3 | I28: QUD: | J28: Why did they (the people) act out / rebel / engage in radical actions (e.g. blowing up credit card companies)?
A29: its like they want to blame everyone else other than themselves for the downfall | B29: FALSE | C29: FALSE | D29: TRUE | E29: FALSE | F29: inference | G29: 3
A30: She meant the workers the system or work environment had worked against them | B30: TRUE | C30: FALSE | D30: FALSE | E30: FALSE | F30: paraphrase | G30: 3 | I30: Discourse relations
A31: That they had been let down by systemic issues - that their jobs are not supported or praised by the government, maybe | B31: FALSE | C31: FALSE | D31: TRUE | E31: FALSE | F31: inference | G31: 3 | I31: Explanation
A32: The people felt like they had been let down by their company. I feel like she sympathises with the people. | B32: FALSE | C32: FALSE | D32: FALSE | E32: TRUE | F32: attributing emotion | G32: 3 | I32: This utterance provides an explanation for the feeling of being "run down"—a causal or motivating context.
B34: =COUNTIF(B3:B31, TRUE) -> 12 | C34: =COUNTIF(C3:C31, TRUE) -> 1 | D34: =COUNTIF(D3:D31, TRUE) -> 8 | E34: =COUNTIF(E3:E32, TRUE) -> 3 | F34: =SUM(B34:E34) -> 24
I35: DPS | J35: People felt betrayed, exploited, or harmed by the system.
J37: This is a direct paraphrase or description of the emotional and socio-political condition referred to by Petra: a sense of being wronged or oppressed by institutional structures.

Sheet build more prisons 
A1: QID72 | F1: Comment | G1: Certainty
A2: unless we build more prisons this system is going to crumble | B2: DPS | C2: SIT | D2: INF | E2: EVA
A3: Prisons are overcrowded and the system will collapse soon. | B3: TRUE | C3: FALSE | D3: FALSE | E3: FALSE | F3: paraphrase | G3: 3 | I3: Maddie and Charlie are discussing crime and punishment: Maddie: I'm thinking there must be an alternative to slapping someone behind bars. Charlie: Mm. Maddie: Because the rate at which inmates are going into prison is far higher than the rate of releases, so. Charlie: Yes, and the reoffending rate is. Maddie: Is really high. Charlie: Very, very high. Maddie: Yes, so it doesn't take a rocket scientist to work out that unless we build more prisons this whole system is gonna crumble. Charlie: Yeah. Maddie: It's gonna, it's gonna, everything is going to come to a head. What do you think is conveyed by Maddie in the underlined text?
A4: Maddie thinks we need a new way to deal with offenders other than prison. | B4: FALSE | C4: TRUE | D4: FALSE | E4: FALSE | F4: inference from earlier turn | G4: 2
A5: that more prisons are needed to be built | B5: dps | C5: FALSE | D5: FALSE | E5: FALSE | F5: paraphrase | G5: 3
A6: That the amount of people going to prison is putting strain on the prison service, and that more prisons are required to house the number of people being convicted | B6: TRUE | C6: FALSE | D6: FALSE | E6: FALSE | F6: paraphrase | G6: 3
A7: more prisons required rather than tackle the cause of the issue | B7: FALSE | C7: TRUE | D7: FALSE | E7: FALSE | F7: rather than tackle issue is inference | G7: 2
A8: That we need more prisons as the system is overcrowded at the moment | B8: TRUE | C8: FALSE | D8: FALSE | E8: FALSE | F8: paraphrase | G8: 3
A9: that therer is not enough prisons to house teh rising nuber of criminals and reoffendners | B9: TRUE | C9: FALSE | D9: FALSE | E9: FALSE | F9: paraphrase | G9: 3
A10: There are insufficient prison places | B10: TRUE | C10: FALSE | D10: FALSE | E10: FALSE | F10: paraphrase | G10: 3
A11: The country need to build more prisons to avoid them filling up and having to leave criminals on the street | B11: FALSE | C11: FALSE | D11: TRUE | E11: FALSE | F11: leaving criminals on the street is an inference | G11: 2
A12: we need to build more prisons quickly | B12: TRUE | C12: FALSE | D12: FALSE | E12: FALSE | F12: paraphrase | G12: 3
A13: Worry | B13: FALSE | C13: FALSE | D13: FALSE | E13: TRUE | F13: attributing emotion | G13: 3
A14: Maddie is conveying that we need to build more prisons as the justice system will fall apart in future | B14: TRUE | C14: FALSE | D14: FALSE | E14: FALSE | F14: paraphrase | G14: 3
A15: prisons are getting full | B15: TRUE | C15: FALSE | D15: FALSE | E15: FALSE | F15: paraphrase | G15: 3
A16: She's highlighting the fact that the prison system is flawed and by using the word crumble, her opinion shows that its just not going to be sustainable and there will be repercussions down the line | B16: FALSE | C16: FALSE | D16: TRUE | E16: FALSE | F16: unsustainable and reprecussions is an inference | G16: 3
A17: There are too many prisoners and not enough prisons to house them | B17: TRUE | C17: FALSE | D17: FALSE | E17: FALSE | F17: paraphrase | G17: 3
... A21: Maddie wants more prisons built to cope with the overcrowding of prisons. | B21: TRUE | C21: FALSE | D21: FALSE | E21: FALSE | F21: paraphrase | G21: 3
A22: More prisons are needed or else the system will stop working | B22: dps | C22: FALSE | D22: FALSE | E22: FALSE | F22: paraphrase | G22: 3
A23: The current prison system does not have the capacity to support all of the potential criminals that "need" to be sent there. Criminals are going to be released early to free up capacity. | B23: FALSE | C23: FALSE | D23: TRUE | E23: FALSE | F23: inference | G23: 3
A24: i think maddie is saying that we should build more prisons rather than focus on rehabilitation. | B24: FALSE | C24: FALSE | D24: TRUE | E24: FALSE | F24: inference | G24: 2
A25: That the prison system is broken and overwhelmed with the need for places. | B25: TRUE | C25: FALSE | D25: FALSE | E25: FALSE | F25: paraphrase | G25: 3
A26: there is too many people requiring prisons, no enough prisons to house them | B26: TRUE | C26: FALSE | D26: FALSE | E26: FALSE | F26: paraphrase | G26: 3
A27: Maddie is contradicting herself by advocating an alternative to prison, whilst firmly of the opinion that more prisons need be built. | B27: FALSE | C27: FALSE | D27: TRUE | E27: FALSE | F27: contradicting is an inference | G27: 2
A28: Although she believes that there must be better alternatives to prison, the argues that because the rate at which people are going into prison is greater than the rate at which prisoners are released, the system will collapse unless more prisons are built | B28: TRUE | C28: FALSE | D28: FALSE | E28: FALSE | F28: paraphrase | G28: 3 | I28: QUD | J28: What are the consequences of the current prison system's trajectory?
A29: That the justice system will no longer work. It will no longer be possible to imprison people that should be imprisoned | B29: FALSE | C29: sit | D29: FALSE | E29: FALSE | F29: paraphrase | G29: 2 | I29: Discourse relations | K29: Defeasible Consequence | N29: Maddie’s statement presents a conditional, predictive relationship: If we don’t build more prisons, the system will fail. This reflects a likely (but not guaranteed) outcome—a defeasible inference based on current trends in incarceration and recidivism.
B30: FALSE | C30: FALSE | D30: FALSE | E30: FALSE | I30: DPS | K30: The prison system is under strain because more people are being incarcerated than released, and reoffending rates are high.
B31: FALSE | C31: FALSE | D31: FALSE | E31: FALSE
B32: FALSE | C32: FALSE | D32: FALSE | E32: FALSE
B34: =COUNTIF(B3:B31, TRUE) -> 14 | C34: =COUNTIF(C3:C31, TRUE) -> 3 | D34: =COUNTIF(D3:D31, TRUE) -> 6 | E34: =COUNTIF(E3:E31, TRUE) -> 1 | F34: =SUM(B34:E34) -> 24

Sheet shock to the system
A1: QID62 | F1: Comment | G1: Certainty
A2: that's going to be a shock to the systen | B2: DPS | C2: SIT | D2: INF | E2: EVA
A3: Kstybisvused to bring psrtosllt clothed or lifhtkt ck9thed as it has been warm | B3: FALSE | C3: FALSE | D3: FALSE | E3: FALSE | I3: Madeline and Katy are discussing the weather: Madeline: Don't know. Anyway, it's going to be hot, hot, hot. Katy: Yeah. Madeline: And I'm going to be wearing more clothes. Katy: Yeah, well that's going to be a bit of a shock to the system, isn't it? Madeline: But hopefully breezy. We're going to have to try on all our work clothes. Katy: Yeah. Gonna have to get used to going from air con to outside. What do you think is conveyed by Katy in the underlined text?
A4: That wearing more clothes because of the work uniform will take some getting used to as they are most likely used to wearing whats comfortable | B4: TRUE | C4: FALSE | D4: FALSE | E4: FALSE | F4: paraphrase | G4: 3
A5: That the fact that Madeline is going. To be wearing more clothes is going to be unusual and not what she has been used to | B5: TRUE | C5: FALSE | D5: FALSE | E5: FALSE | F5: paraphrase | G5: 3
A6: they are going to be working in a climate that they're not used to | B6: FALSE | C6: TRUE | D6: FALSE | E6: FALSE | F6: not about clothing but broader discourse | G6: 2
A7: that it is going to be different to what her system is used to at the moment | B7: TRUE | C7: FALSE | D7: FALSE | E7: FALSE | F7: paraphrase | G7: 3
A8: madeline doesnt wear clothes often | B8: FALSE | C8: FALSE | D8: TRUE | E8: FALSE | F8: inference | G8: 3
A9: That her system is used to a colder temp and due to the extra clothes they have to wear for there job theybare going to get very hot which is going to shick there system as they r not used to heat | B9: TRUE | C9: FALSE | D9: FALSE | E9: FALSE | F9: paraphrase | G9: 3
A10: She is saying it’s going to be hot | B10: FALSE | C10: TRUE | D10: FALSE | E10: FALSE | F10: not about clothing but broader discourse | G10: 2
A11: Going against what is expected by wearing more clothes will be hard for Madeline's body to deal with. | B11: TRUE | C11: FALSE | D11: FALSE | E11: FALSE | F11: paraphrase | G11: 3
A12: that the weather is going to change dramaticaly | B12: FALSE | C12: TRUE | D12: FALSE | E12: FALSE | F12: not about clothing but broader discourse | G12: 3
A13: the termperature is going to be a shock | B13: FALSE | C13: TRUE | D13: FALSE | E13: FALSE | F13: not about clothing but broader discourse | G13: 2
A14: That wearing excess clothes in high heat is going to be uncomfortable | B14: TRUE | C14: FALSE | D14: FALSE | E14: FALSE | F14: paraphrase | G14: 3
A15: The difference in temperature may affect the body. | B15: TRUE | C15: FALSE | D15: FALSE | E15: FALSE | F15: paraphrase | G15: 3
... A18: Madeline usually wears little clothing | B18: FALSE | C18: FALSE | D18: TRUE | E18: FALSE | F18: inference | G18: 3
A19: Madeleine doesnt usually wear a lot of clothes | B19: FALSE | C19: FALSE | D19: inf | E19: FALSE | F19: inference | G19: 3
A20: The fact that the weather is going to be lot different than currently and so will be a shock to the body! | B20: TRUE | C20: FALSE | D20: FALSE | E20: FALSE | F20: paraphrase | G20: 3
A21: The difference in clothing and weather might confuse her body temperature | B21: TRUE | C21: FALSE | D21: FALSE | E21: FALSE | F21: paraphrase | G21: 3
A22: That she believes it is going to be a shock to the system trying on clothes and that they are going to need to adapt to different air temps such as air con and outside temperatures. | B22: TRUE | C22: FALSE | D22: FALSE | E22: FALSE | F22: paraphrase | G22: 3
A23: I think it suggest that Medline is often underdressed or wearing very little. Probably short skirts and tops | B23: FALSE | C23: FALSE | D23: TRUE | E23: FALSE | F23: inference (and a sexist one) | G23: 3
A24: Kath is conveying that although it is going to be warm she will be wearing more clothes which will make her body even warmer than it would like to be. | B24: TRUE | C24: FALSE | D24: FALSE | E24: FALSE | F24: paraphrase | G24: 3
A25: The change of weather being a shock to the body. | B25: TRUE | C25: FALSE | D25: FALSE | E25: FALSE | F25: paraphrase | G25: 3
A26: I think katy is making a joke of having to wear more clothes as they usually wear not a lot of clothes . | B26: FALSE | C26: FALSE | D26: TRUE | E26: FALSE | F26: inference | G26: 3
A27: Katy is trying to say is due to a drastic difference in the temperature or whether conditions, body which is used to one particular temperature for example if you are used to cold weather and you are going in hot country then your body may not be able to cope the new environment and the sudden change may affect your overall well being and your body system. That's why she is saying it will be a bit of a shock if it is going to be hot. | B27: TRUE | C27: FALSE | D27: FALSE | E27: FALSE | F27: paraphrase | G27: 3 | I27: QUD | J27: How will we adapt to the changes in weather, especially the heat?
A28: Slight sarcasm | B28: FALSE | C28: FALSE | D28: inf | E28: FALSE | F28: inference | G28: 2 | I28: Discourse relations | K28: The utterance "well that's going to be a bit of a shock to the system, isn't it?" provides a commentary or explanation of the situation that Madeline described (wearing more clothes in the heat). It doesn’t provide new information but adds interpretive value by offering a reaction to the situation, framing it as something that will be difficult to adjust to.
A29: That wearing work clothes in a hot environment will be a change from the usual. | B29: TRUE | C29: FALSE | D29: FALSE | E29: FALSE | F29: paraphrase | G29: 3 | I29: DPS | J29: This utterance is describing the challenge of adjusting to the new weather conditions, specifically the feeling of discomfort or surprise that might come from wearing more clothes in hot weather
J30: wearing more clothes will be a weird sensation
B34: =COUNTIF(B3:B31, TRUE) -> 15 | C34: =COUNTIF(C3:C31, TRUE) -> 4 | D34: =COUNTIF(D3:D31, TRUE) -> 5 | E34: =COUNTIF(E3:E31, TRUE) -> 0 | F34: =SUM(B34:E35) -> 24

Sheet measure people skills
B1: QID53 | G1: Comment | H1: Certainty
A2: Excluded? | B2: we've never come up with a good system for measuring your capability with people. | C2: PAR | D2: SIT | E2: INF | F2: EVA
B3: There has never been a system invented that measures someone's people skills | C3: TRUE | D3: FALSE | E3: FALSE | F3: FALSE | G3: paraphrase | H3: 3 | J3: Tanya and Max are discussing job skills: Tanya: For a lot of professions you need to be good at dealing with people. Max: You've gotta be- Tanya: But all our exams are about intellect and nothing to do with people. Max: Yes, that's right. Tanya: Cos we've never come up with a good system for measuring your capability with people. Max: No. Tanya: And a lot of jobs you need to be able to communicate, don't you? Max: If you're in charge of a firm of any description you've gotta be able to get on well with people, otherwise you're in trouble. What do you think is conveyed by Tanya in the underlined text?
A4: X | B4: That exams aren’t everything. Even if you have the highest grades, it doesn’t mean you will automatically do well in a workplace. There’s more factors to consider than their academic achievement. | C4: FALSE | D4: FALSE | E4: inf | F4: FALSE | G4: doing well in workplace is an inference | H4: 2
B5: frustration that technology hasn't achiveved sophistication | C5: FALSE | D5: FALSE | E5: FALSE | F5: TRUE | G5: attributing emotion | H5: 3
B6: Shortcomings in the educational institutions. | C6: FALSE | D6: FALSE | E6: TRUE | F6: FALSE | G6: inference | H6: 3
B7: That she isn't happy with max but saying that she could of come up with a better system | C7: FALSE | D7: FALSE | E7: FALSE | F7: TRUE | G7: attributing emotion | H7: 3
B8: Tanya is saying that school exams only test your intellectual capabilities and not your social and people skills. She seems to be suggesting that testing is inadequate. | C8: FALSE | D8: FALSE | E8: TRUE | F8: FALSE | G8: seems to be suggesting is an ifnerence | H8: 2
B9: Tanya conveys a critique of current evaluation systems, highlighting their inability to assess interpersonal skills effectively. She points out a significant gap in how skills are evaluated, suggesting that while interpersonal abilities are crucial for many professions, existing methods focus disproportionately on intellectual abilities. This reflects her view that the system overlooks an essential aspect of professional competency. | C9: TRUE | D9: FALSE | E9: FALSE | F9: FALSE | G9: paraphrase | H9: 2
B10: That people have trouble communicating | C10: FALSE | D10: FALSE | E10: TRUE | F10: FALSE | G10: inference | H10: 3
B11: That generally a system has not been invented that measures how well you deal with people | C11: TRUE | D11: FALSE | E11: FALSE | F11: FALSE | G11: paraphrase | H11: 3
B12: There is not a system to measure peoples capability with people | C12: TRUE | D12: FALSE | E12: FALSE | F12: FALSE | G12: paraphrase | H12: 3
B13: There is no good way of measuring capability with people | C13: TRUE | D13: FALSE | E13: FALSE | F13: FALSE | G13: paraphrase | H13: 3
B14: School doesn't teach some necessary skills | C14: FALSE | D14: FALSE | E14: TRUE | F14: FALSE | G14: inference | H14: 2
A15: X | B15: its hard to measure people's people skills and how they interact with people, job applications or schools system lack developing those | C15: FALSE | D15: sit | E15: FALSE | F15: FALSE | G15: goes broader than dps | H15: 2
B16: There's no sensible way of measuring someone's interpersonal skills | C16: TRUE | D16: FALSE | E16: FALSE | F16: FALSE | G16: paraphrase | H16: 3
B17: that it is unable to do a proper test to see how people capable they are | C17: TRUE | D17: FALSE | E17: FALSE | F17: FALSE | G17: paraphrase | H17: 3
B18: Tanya is saying that personality is key in a job and it is something you can't measure by exams etc | C18: FALSE | D18: TRUE | E18: FALSE | F18: FALSE | G18: personality goes bevyond dps | H18: 2
B19: exams dont train people to interact well with others | C19: FALSE | D19: TRUE | E19: FALSE | F19: FALSE | G19: beyond dps | H19: 2
B20: That people's ability for good communication has not generally been measured because there is not a good system to measure this. | C20: TRUE | D20: FALSE | E20: FALSE | F20: FALSE | G20: paraphrase | H20: 3
B21: That she think education should include more people skills training | C21: FALSE | D21: TRUE | E21: FALSE | F21: FALSE | G21: introducing a "should" | H21: 2
B22: needs to be a system to check social capabilities | C22: FALSE | D22: TRUE | E22: FALSE | F22: FALSE | G22: introducing a "should" | H22: 2
B23: Trying to convince that lots of profession involve dealing with people | C23: FALSE | D23: FALSE | E23: TRUE | F23: FALSE | G23: convincing is an inference | H23: 3
B24: Tanya says exams do not prepare us for the real world. They cover intellect but have nothing to do with meeting with and dealing with other people. I would agree with Tanya. | C24: FALSE | D24: TRUE | E24: FALSE | F24: FALSE | G24: inference | H24: 3
B25: Theres no single test that can dwtermine your ability to communicate with people effectively, compared to intellect which is typically measurable with tests | C25: TRUE | D25: FALSE | E25: FALSE | F25: FALSE | G25: paraphrase | H25: 3
B26: They have only learnt intellectual things rather than how to deal with people | C26: TRUE | D26: FALSE | E26: FALSE | F26: FALSE | G26: paraphrase | H26: 3
B27: The lack of interpersonal skills taught during exam processes | C27: TRUE | D27: FALSE | E27: FALSE | F27: FALSE | G27: paraphrase | H27: 3
A28: X | B28: Exams measure intellect, but not social skills which isn't measurable at academic level, but she believes it should be | C28: FALSE | D28: sit | E28: FALSE | F28: FALSE | G28: introducing a "should" | H28: 2 | J28: QUD | K28: How can we measure the skill of dealing with people in job settings?
B29: I would assume there is something wrong with Max and that she is dicussing that there are not good tests avalable that are customisable for Maxes specific issue. | C29: FALSE | D29: FALSE | E29: TRUE | F29: FALSE | G29: something wrong with max?? | H29: 3
C34: =COUNTIF(C3:C31, TRUE) -> 11 | D34: =COUNTIF(D3:D31, TRUE) -> 5 | E34: =COUNTIF(E3:E31, TRUE) -> 6 | F34: =COUNTIF(F3:F31, TRUE) -> 2 | G34: =SUM(C34:F34) -> 24

Sheet New motorbike system
B1: QID43 | G1: Comment | H1: Certainty
A2: Excluded? | B2: then got some money from somewhere and redesigned the whole system. | C2: PAR | D2: SIT | E2: INF | F2: EVA
B3: She is really interested in the topic but has not noticed xander is not interested | C3: FALSE | D3: FALSE | E3: FALSE | F3: TRUE | G3: attributing emotion | H3: 3 | J3: Abbie and Xander are discussing motorbikes: Abbie: There's this company who bought out the old Triumph. Xander: Yeah. Abbie: And sort of started off just making replacement parts and stuff like that. Xander: Yeah. Abbie: And then sort of slowly had one bike and then got some money from somewhere and redesigned the whole system. Xander: Yeah. Abbie: But they worked out the principle that they would make twins. I don't think they ma- no they don't make a single, they make twins, a triple, and a four-cylinder bike, you know, with different engines. Xander: Yeah. Abbie: You know these three different engines but nearly all the parts were interchangeable, like the pistons and the rods. What do you think is conveyed by Abbie in the underlined text?
B4: updated the look of the bike | C4: FALSE | D4: FALSE | E4: TRUE | F4: FALSE | G4: never said anything about the look | H4: 2
B5: changed the company | C5: FALSE | D5: TRUE | E5: FALSE | F5: FALSE | G5: said in the discourse | H5: 2
B6: The company got a loan or a grant or some funding which enabled them to upscale their work | C6: TRUE | D6: FALSE | E6: FALSE | F6: FALSE | G6: paraphrase | H6: 3
B7: They got investment from some one/companies and redesigned the engine | C7: TRUE | D7: FALSE | E7: FALSE | F7: FALSE | G7: paraphrase | H7: 3
B8: That he redesigned the bike | C8: TRUE | D8: FALSE | E8: FALSE | F8: FALSE | G8: paraphrase | H8: 3
B9: Abbie seems to be showing that she found money unexpectedly and used it to redo the whole system. | C9: TRUE | D9: FALSE | E9: FALSE | F9: FALSE | G9: paraphrase | H9: 3
B10: They had investment into the company and changed the business model | C10: TRUE | D10: FALSE | E10: FALSE | F10: FALSE | G10: paraphrase | H10: 3
A11: X | B11: Funding was from an unkown source and the whole engine system was redesigned | C11: dps | D11: FALSE | E11: FALSE | F11: FALSE | G11: paraphrase | H11: 3
B12: Dodgy money | C12: FALSE | D12: FALSE | E12: TRUE | F12: FALSE | G12: inference | H12: 3
B13: This company became successful and changed its product offering. | C13: FALSE | D13: FALSE | E13: TRUE | F13: FALSE | G13: becoming successful is an inference | H13: 3
B14: that the company expanded and branched out | C14: FALSE | D14: TRUE | E14: FALSE | F14: FALSE | G14: nothing about system | H14: 2
B15: The company suddenly had more money and then they were able to make changes. | C15: TRUE | D15: FALSE | E15: FALSE | F15: FALSE | G15: paraphrase | H15: 3
B16: Abbie is just talking about how this company redesigned the system. I think when she says “they got some money from somewhere” she could have a hint of suspicion, like they got a lot of money but she doesn’t know why. | C16: FALSE | D16: FALSE | E16: FALSE | F16: TRUE | G16: suspicion = evaluation | H16: 3
B17: They received funding externally and were able to redesign the entire system | C17: TRUE | D17: FALSE | E17: FALSE | F17: FALSE | G17: paraphrase | H17: 3
B18: that the company received an injection of money and were able to use it to improve their business | C18: TRUE | D18: FALSE | E18: FALSE | F18: FALSE | G18: paraphrase | H18: 3
B19: That a company has worked out how to design a new system for an old model of a Triumph motorbike which makes it easier to design different versions of the bike with interchangeable parts. | C19: FALSE | D19: TRUE | E19: FALSE | F19: FALSE | G19: callback to the interchangeable parts | H19: 2
B20: That a company got money from somewhere and redesigned the whole system | C20: TRUE | D20: FALSE | E20: FALSE | F20: FALSE | G20: paraphrase | H20: 3
B21: The company has money saved up from somewhere to upgrade their system | C21: TRUE | D21: FALSE | E21: FALSE | F21: FALSE | G21: paraphrase | H21: 3
B22: That they started by providing parts to repair a much loved classic bike but then moved on to completely changing the design which might not be appreciated by enthusiasts | C22: FALSE | D22: FALSE | E22: TRUE | F22: FALSE | G22: inference | H22: 3
A23: X | B23: Abbie is conveying her confusion as to how and where the company got the investment money from. | C23: FALSE | D23: FALSE | E23: FALSE | F23: eva | G23: attributing emotion | H23: 3
B24: she thinks the people who brought the Triumph are a little suspicious by stating the money is from "somewhere". Also that everything has been changed. | C24: FALSE | D24: FALSE | E24: TRUE | F24: FALSE | G24: inference | H24: 3
B25: That the person did aomething amazing because they got some money, something they would not have been able to do. | C25: FALSE | D25: FALSE | E25: TRUE | F25: FALSE | G25: inference | H25: 3
B26: she is discussing the interchanging of parts when you own this type of motorcycle | C26: FALSE | D26: TRUE | E26: FALSE | F26: FALSE | G26: broader discourse | H26: 3
B27: someone invested in them to make a whole new system | C27: TRUE | D27: FALSE | E27: FALSE | F27: FALSE | G27: paraphrase | H27: 3
B28: There was a significant investment from an unknown company that allowed the bike maker to redesign | C28: TRUE | D28: FALSE | E28: FALSE | F28: FALSE | G28: paraphrase | H28: 3 | J28: QUD | L28: How did the new Triumph company evolve and develop their motorcycles?
C34: =COUNTIF(C3:C31, TRUE) -> 12 | D34: =COUNTIF(D3:D31, TRUE) -> 4 | E34: =COUNTIF(E3:E31, TRUE) -> 6 | F34: =COUNTIF(F3:F31, TRUE) -> 2 | G34: =SUM(C34:F34) -> 24

Sheet Summary
A1: Column1 | B1: PAR | C1: SIT | D1: INF | E1: EVA
A2: D1 | B2: ='System Screwed them over'!B34 -> 12 | C2: ='System Screwed them over'!C34 -> 1 | D2: ='System Screwed them over'!D34 -> 8 | E2: ='System Screwed them over'!E34 -> 3
A3: d2 | B3: ='build more prisons '!B34 -> 14 | C3: ='build more prisons '!C34 -> 3 | D3: ='build more prisons '!D34 -> 6 | E3: ='build more prisons '!E34 -> 1
A4: d3 | B4: ='shock to the system'!B34 -> 15 | C4: ='shock to the system'!C34 -> 4 | D4: ='shock to the system'!D34 -> 5 | E4: ='shock to the system'!E34 -> 0
A5: d4 | B5: ='measure people skills'!C34 -> 11 | C5: ='measure people skills'!D34 -> 5 | D5: ='measure people skills'!E34 -> 6 | E5: ='measure people skills'!F34 -> 2
A6: d5 | B6: ='New motorbike system'!C34 -> 12 | C6: ='New motorbike system'!D34 -> 4 | D6: ='New motorbike system'!E34 -> 6 | E6: ='New motorbike system'!F34 -> 2
A8: Column1 | B8: PAR | C8: SIT | D8: INF | E8: EVA
A9: totals | B9: =SUM(Table6[PAR]) -> 64 | C9: =SUM(Table6[SIT]) -> 17 | D9: =SUM(Table6[INF]) -> 31 | E9: =SUM(Table6[EVA]) -> 8
A11: Column1 | B11: PAR | C11: SIT | D11: INF | E11: EVA | F11: Total
A12: D1 | B12: =B2/Table610[[#This Row],[Total]] -> 0.5 | C12: =C2/Table610[[#This Row],[Total]] -> 0.041666667 | D12: =D2/Table610[[#This Row],[Total]] -> 0.33333333 | E12: =E2/F12 -> 0.125 | F12: =SUM(B2:E2) -> 24
A13: d2 | B13: =B3/Table610[[#This Row],[Total]] -> 0.58333333 | C13: =C3/Table610[[#This Row],[Total]] -> 0.125 | D13: =D3/Table610[[#This Row],[Total]] -> 0.25 | E13: =E3/F13 -> 0.041666667 | F13: =SUM(B3:E3) -> 24
A14: d3 | B14: =B4/Table610[[#This Row],[Total]] -> 0.625 | C14: =C4/Table610[[#This Row],[Total]] -> 0.16666667 | D14: =D4/Table610[[#This Row],[Total]] -> 0.20833333 | E14: =E4/F14 -> 0 | F14: =SUM(B4:E4) -> 24
A15: d4 | B15: =B5/Table610[[#This Row],[Total]] -> 0.45833333 | C15: =C5/Table610[[#This Row],[Total]] -> 0.20833333 | D15: =D5/Table610[[#This Row],[Total]] -> 0.25 | E15: =E5/F15 -> 0.083333333 | F15: =SUM(B5:E5) -> 24
A16: d5 | B16: =B6/Table610[[#This Row],[Total]] -> 0.5 | C16: =C6/Table610[[#This Row],[Total]] -> 0.16666667 | D16: =D6/Table610[[#This Row],[Total]] -> 0.25 | E16: =E6/F16 -> 0.083333333 | F16: =SUM(B6:E6) -> 24
