Workbook

Sheet Sheet0
A1: Q4 | B1: Q5 | C1: Q15 | D1: QID112 | E1: QID103 | F1: QID94 | G1: QID84 | H1: QID23
A2: What is your age? | B2: What is your highest level of education? | C2: Please select the domain that best describes your current occupation: | D2: Alison, Carol, and Brian are discussing their recent holiday: Alison: Which country is it close to? Brian: Er oh dear. I really don't know dear I'm not that well up on that part of Europe. Alison: Right, we'll have to get an atlas. Carol: Steve might have it, he'll get it on the- Brian: Oh on the- Carol: Computer I can show you where it is. Brian: Tablet yeah. Alison: You can get it on the computer easily. Brian: Mm. What do you think is conveyed by Alison in the underlined text? | E2: Becca and Uma are discussing Uma's job as a teacher: Becca: What was that last semester? Uma: I had erm yeah about seventeen. Becca: What, two thousand words? Uma: Yeah. Becca: Oh my god. Uma: Had about seventy-five to mark. Becca: Mmm. Uma: Plus individual comments for each one. Becca: Mmm. Uma: Plus then putting the grades into the computer. Becca: Mmm oh. What do you think is conveyed by Uma in the underlined text? | F2: Stephen and Wade are discussing gaming: Stephen: Did you say you were gonna show me chess? Wade: Yes, er, Chinese chess, yeah. Stephen: You've got the actual board, haven't you? Wade: Yeah, I've got the board, yeah, but it'll be easier to show you on the iPad. Stephen: Why is that? Wade: Because you can keep going backwards and forwards and showing... it'll take the move back and it'll show you how it's moving. Stephen: Oh, okay. Wade: I mean, I can show you physically, but you'll see it on that 'cos it's easier. Stephen: Okay, give it a try... You say you can win against the computer sometimes? Wade: I can easy. I've only ever beaten it once at normal, probably over about five hundred games. Stephen: Do we, on the iPad, do we play against each other then, or what? Wade: No, you play against the computer. What do you think is conveyed by Wade in the underlined text? | G2: Lucy and Dave are discussing technology: Lucy: How much space have you got on yours? Dave: Hm, don't know. Lucy: Is it on now? Dave: How much space do I need? Lucy: Erm, I don't know. I guess my music comes to— Dave: But then it's annoying because you can't listen to music and do stuff on the computer at the same time. We need another computer. Lucy: You'll probably need about fifty-sixty gigs. Dave: Fifty-sixty gigs. Lucy: It's a guess. What do you think is conveyed by Dave in the underlined text? | H2: Steph and Marco are discussing technology: Steph: I've got all my, all my documents are on the... er... two shilabyte? trialabyte? trilabyte? Marco: Terabyte. Steph: Two terabyte, terabyte. Marco: Two terabytes. Steph: External drive. I've got buy-one-get-one-free from Maplins. Marco: Yeah. Steph: And I really ought to copy that onto... I've got none of the other one, the free one. Marco: No, if you've got one, that's fine. Steph: No, but if that goes tits up... Marco: Well, how many copy backups do you need? People only have one backup. Steph: The external drive is my drive, it's not on the computer. I don't keep anything on the computer. Marco: Why not? Steph: I'm jolly lucky, cos if it had been all on the computer, I would have nothing now. What do you think is conveyed by Steph in the underlined text?
A3: 45 - 54 | B3: Master’s Degree (e.g. MA. MSc) | C3: Sales and Marketing | D3: that the info is easy to find, it doesn't matter what device
A4: 25 - 34 | B4: GCSE/O-level | C4: Finance and Banking
A5: 35 - 44 | B5: Bachelors Degree (e.g BA, BSc) | C5: Unemployed | E5: That after marking her students' work she had to manually type the grades up for each student
A6: 35 - 44 | B6: Vocational Qualifications (e.g. NVQs, BTEC) | C6: Information Technology and Software Development | G6: That another computer will be needed in order to be able to listen to music and complete other computer-related tasks
A7: 55 - 64 | B7: Higher National Certificate/higher National Diploma | C7: Information Technology and Software Development | F7: it's you against the machine which is always difficult when starting something new
A8: 25 - 34 | B8: Bachelors Degree (e.g BA, BSc) | C8: Engineering and Manufacturing
A9: 25 - 34 | B9: Bachelors Degree (e.g BA, BSc) | C9: Nonprofit and Social Services
A10: 55 - 64 | B10: Master’s Degree (e.g. MA. MSc) | C10: Engineering and Manufacturing
A11: 35 - 44 | B11: A-levels/Highers | C11: Nonprofit and Social Services | G11: They need another computer
A12: 55 - 64 | B12: A-levels/Highers | C12: Retired
A13: 55 - 64 | B13: Bachelors Degree (e.g BA, BSc) | C13: Retired | H13: All Steph's info, programs etc are not kept on the computer's hard drive.
A14: 35 - 44 | B14: Bachelors Degree (e.g BA, BSc) | C14: Retail and Customer Service
A15: 35 - 44 | B15: Vocational Qualifications (e.g. NVQs, BTEC) | C15: Law and Legal Services
A16: 25 - 34 | B16: Bachelors Degree (e.g BA, BSc) | C16: Education and Training | F16: You play against the Chess AI if you play on the ipad
A17: 35 - 44 | B17: GCSE/O-level | C17: Unemployed
A18: 35 - 44 | B18: Bachelors Degree (e.g BA, BSc) | C18: Healthcare and Medicine | F18: He is saying that when they practice playing Chinese chess on the iPad, you don’t play Addinsell another person, you play against the computer game.
A19: 25 - 34 | B19: Master’s Degree (e.g. MA. MSc) | C19: Consulting and Business Services
A20: 25 - 34 | B20: Master’s Degree (e.g. MA. MSc) | C20: Government and Public Administration | H20: steph is saying she keeps all storage separate from her computer and uses an external drive to do so
A21: 35 - 44 | B21: Bachelors Degree (e.g BA, BSc) | C21: Government and Public Administration | H21: That something has happened to her computer. She is trying her best to back up her work and stay safe, but may not completely understand it.
A22: 35 - 44 | B22: Vocational Qualifications (e.g. NVQs, BTEC) | C22: Law and Legal Services | E22: That she had a lot of work to mark, including having to input the grades into the computer for all 75 of them.
A23: 25 - 34 | B23: Bachelors Degree (e.g BA, BSc) | C23: Education and Training
A24: 25 - 34 | B24: Bachelors Degree (e.g BA, BSc) | C24: Finance and Banking
A25: 35 - 44 | B25: A-levels/Highers | C25: Unemployed | E25: She had to record the students' grades into offcial computerised records.
A26: 25 - 34 | B26: Bachelors Degree (e.g BA, BSc) | C26: Education and Training | E26: That the workload in teaching is high and demanding
A27: 55 - 64 | B27: Bachelors Degree (e.g BA, BSc) | C27: Education and Training | G27: That there is insufficient memory of their current computer
A28: 35 - 44 | B28: A-levels/Highers | C28: Unemployed | D28: Alison is choosing a quicker and easier method to resolve the issue .
A29: 25 - 34 | B29: Bachelors Degree (e.g BA, BSc) | C29: Education and Training
A30: 25 - 34 | B30: Vocational Qualifications (e.g. NVQs, BTEC) | C30: Healthcare and Medicine
A31: 35 - 44 | B31: Bachelors Degree (e.g BA, BSc) | C31: Arts and Humanities
A32: 25 - 34 | B32: Vocational Qualifications (e.g. NVQs, BTEC) | C32: Information Technology and Software Development
A33: 25 - 34 | B33: Bachelors Degree (e.g BA, BSc) | C33: Education and Training
A34: 25 - 34 | B34: GCSE/O-level | C34: Construction and Skilled Trades | H34: Keeps stuff just on his external hard drive
A35: 35 - 44 | B35: Bachelors Degree (e.g BA, BSc) | C35: Unemployed | E35: Uma is suggesting that the extra work of putting grades into a computer adds to the already considerable workload
A36: 35 - 44 | B36: Bachelors Degree (e.g BA, BSc) | C36: Education and Training
A37: 25 - 34 | B37: Vocational Qualifications (e.g. NVQs, BTEC) | C37: Retail and Customer Service | F37: A simple answer to who you're playing on the ipad to clear up the understanding for Stephen
A38: 35 - 44 | B38: Master’s Degree (e.g. MA. MSc) | C38: Nonprofit and Social Services
A39: 25 - 34 | B39: Bachelors Degree (e.g BA, BSc) | C39: Law and Legal Services | F39: He is better than Stephen so telling him to play the computer to win
A40: 65 - 74 | B40: GCSE/O-level | C40: Transportation and Logistics | H40: Doesn't trust the computer
...

Sheet Find it on the computer...
A1: Randomly | B1: QID112 | G1: Comment | H1: Certainty
A2: Excluded? | B2: you can get it on the computer easily | C2: PAR | D2: SIT | E2: INF | F2: EVA
A3: X | B3: that the info is easy to find, it doesn't matter what device | C3: FALSE | D3: FALSE | E3: INF | F3: FALSE | G3: not specific to the situation | H3: 2 | N3: Alison, Carol, and Brian are discussing their recent holiday: Alison: Which country is it close to? Brian: Er oh dear. I really don't know dear I'm not that well up on that part of Europe. Alison: Right, we'll have to get an atlas. Carol: Steve might have it, he'll get it on the- Brian: Oh on the- Carol: Computer I can show you where it is. Brian: Tablet yeah. Alison: You can get it on the computer easily. Brian: Mm. What do you think is conveyed by Alison in the underlined text?
A4: X | B4: Alison is choosing a quicker and easier method to resolve the issue . | C4: FALSE | D4: FALSE | E4: INF | F4: FALSE | G4: does not explicitly say it's quicker on the computer | H4: 2
B5: best to use the computer | C5: FALSE | D5: FALSE | E5: TRUE | F5: FALSE | G5: does not explicitly say it's better on the computer | H5: 2
B6: Sarcasm | C6: FALSE | D6: FALSE | E6: FALSE | F6: TRUE | G6: ascribing an evaluation | H6: 3
B7: that the information would be easy to find on the computer. | C7: TRUE | D7: FALSE | E7: FALSE | F7: FALSE | G7: paraphrase | H7: 3
B8: You can use the computer to find out the location of the country they are discussing | C8: TRUE | D8: FALSE | E8: FALSE | F8: FALSE | G8: paraphrase | H8: 3
B9: That the location can easily be found on the computer | C9: TRUE | D9: FALSE | E9: FALSE | F9: FALSE | G9: paraphrase | H9: 3
B10: Alison is determined to find out which country it is close to. | C10: FALSE | D10: FALSE | E10: FALSE | F10: TRUE | G10: determination is an atttiude | H10: 3
B11: It is a really simple task on the computer you don't need a tablet | C11: FALSE | D11: FALSE | E11: TRUE | F11: FALSE | G11: not needing a tablet not said, specific to situation | H11: 2
B12: location of a country | C12: TRUE | D12: FALSE | E12: FALSE | F12: FALSE | G12: paraphrase | H12: 3
A13: X | B13: Alison believes it's easier to access an atlas on a computer | C13: FALSE | D13: FALSE | E13: INF | F13: FALSE | G13: does not explicitly say it's easier on the computer | H13: 2
B14: Computers are easier to work with than the map they were going to find | C14: FALSE | D14: FALSE | E14: TRUE | F14: FALSE | G14: does not explicitly say it's easier on the computer | H14: 2
B15: Do the old 'Google It' thing. No knowledge of anything. | C15: FALSE | D15: FALSE | E15: FALSE | F15: TRUE | G15: evaluation | H15: 3
B16: THAT SHE WANTED BRIAN TO USE THE COMPUTER, MAYBE BECAUSE CAROL ALSO SUGGESTED USING THE COMPUTER | C16: FALSE | D16: FALSE | E16: FALSE | F16: TRUE | G16: ascribing desires/wants to alison | H16: 3
B17: That computers are quicker and easier to use to search for things | C17: FALSE | D17: FALSE | E17: TRUE | F17: FALSE | G17: does not explicitly say it's easier on the computer | H17: 2
B18: It is easier to look it up on the computer than it is in a book | C18: FALSE | D18: FALSE | E18: TRUE | F18: FALSE | G18: does not explicitly say it's easier on the computer | H18: 2
B19: She is telling Brian the information is easy to find using a computer | C19: TRUE | D19: FALSE | E19: FALSE | F19: FALSE | G19: paraphrase | H19: 3
B20: Advice being given to Brian that it would be easy to get it on the computer. | C20: TRUE | D20: FALSE | E20: FALSE | F20: FALSE | G20: paraphrase | H20: 3
A21: X | B21: perhaps she is better off using a computer compared to a tablet to browse the internet for the world map/atlas. | C21: FALSE | D21: FALSE | E21: INF | F21: FALSE | G21: does not explicitly say it's easier on the computer | H21: 2
B22: It is simple to find out information on the computer, i.e. by searching on the internet, or looking at google maps in this case. | C22: TRUE | D22: FALSE | E22: FALSE | F22: FALSE | G22: paraphrase | H22: 3
B23: She isnt interested in using the PC, prefers a book | C23: FALSE | D23: FALSE | E23: FALSE | F23: TRUE | G23: guessing speaker's interests | H23: 3
B24: alison wants brian to do himself | C24: FALSE | D24: FALSE | E24: FALSE | F24: TRUE | G24: guessing speaker's interests | H24: 3
B25: That tablet and computer can equally do the same thing but the computer is easier i think, | C25: FALSE | D25: FALSE | E25: TRUE | F25: FALSE | G25: does not mention doing things easier | H25: 2
A26: X | B26: That you can find a map of the area they wish to see easily on the computer | C26: PAR | D26: FALSE | E26: FALSE | F26: FALSE | G26: paraphrase | H26: 3
B27: You can find where the country is easily on the computer | C27: TRUE | D27: FALSE | E27: FALSE | F27: FALSE | G27: paraphrase | H27: 3
B28: knowledge and confidence as she knows exactly where to find it | C28: FALSE | D28: FALSE | E28: FALSE | F28: TRUE | G28: giving her attributes and emotions | H28: 3
B29: that it is easier to find it that way | C29: FALSE | D29: FALSE | E29: TRUE | F29: FALSE | G29: does not mention doing things easier | H29: 2 | N29: QUD: | O29: How can we find out where [that country] is?
B30: She wants to look at a map online | C30: FALSE | D30: FALSE | E30: FALSE | F30: TRUE | G30: attributing desire | H30: 3
B31: She wants to bring up a map on the computer to look at | C31: FALSE | D31: FALSE | E31: FALSE | F31: TRUE | G31: attributing desire | H31: 3
C34: =COUNTIF(C3:C31, TRUE) -> 8 | D34: =COUNTIF(D3:D31, TRUE) -> 0 | E34: =COUNTIF(E3:E31, TRUE) -> 7 | F34: =COUNTIF(F3:F31, TRUE) -> 9 | G34: =SUM(C34:F34) -> 24

Sheet Inputting grades...
B1: QID103
A2: Randomly | B2: Plus then putting the grades into the computer. | G2: Comment | H2: Certainty
A3: Excluded? | C3: PAR | D3: SIT | E3: INF | F3: EVA | M3: Becca and Uma are discussing Uma's job as a teacher: Becca: What was that last semester? Uma: I had erm yeah about seventeen. Becca: What, two thousand words? Uma: Yeah. Becca: Oh my god. Uma: Had about seventy-five to mark. Becca: Mmm. Uma: Plus individual comments for each one. Becca: Mmm. Uma: Plus then putting the grades into the computer. Becca: Mmm oh. What do you think is conveyed by Uma in the underlined text?
B4: That after marking her students' work she had to manually type the grades up for each student | C4: FALSE | D4: TRUE | E4: FALSE | F4: FALSE | H4: 3
B5: That she had a lot of work to mark, including having to input the grades into the computer for all 75 of them. | C5: FALSE | D5: TRUE | E5: FALSE | F5: FALSE | G5: referring back to the quantity of the work | H5: 3
B6: She had to record the students' grades into offcial computerised records. | C6: TRUE | D6: FALSE | E6: FALSE | F6: FALSE | G6: paraphrase | H6: 3
B7: That the workload in teaching is high and demanding | C7: FALSE | D7: FALSE | E7: TRUE | F7: FALSE | G7: inference, not stated but not affective | H7: 3
B8: Uma is suggesting that the extra work of putting grades into a computer adds to the already considerable workload | C8: FALSE | D8: FALSE | E8: TRUE | F8: FALSE | G8: inference, not stated but not affective | H8: 3
B9: She had to input the grades of work she had marked into a database via computer. | C9: TRUE | D9: FALSE | E9: FALSE | F9: FALSE | G9: paraphrase | H9: 3
B10: Uma was saying she had lots of clerical computer work to do having marked so many lengthy papers | C10: FALSE | D10: TRUE | E10: FALSE | F10: FALSE | G10: SIT, goes broader into the discourse than the actual statement | H10: 3
B11: Uma has a very demanding job and she might be stressed due to the pressures of work. | C11: FALSE | D11: FALSE | E11: FALSE | F11: TRUE | G11: ascribing uma emotions | H11: 3
B12: That putting the grade into the computer is extra effort on top of marking the papers | C12: FALSE | D12: FALSE | E12: TRUE | F12: FALSE | G12: inferred that it's extra effort, not actually said | H12: 3
B13: entering scores from papers into computer takes a lot of time | C13: FALSE | D13: TRUE | E13: FALSE | F13: FALSE | G13: wider discourse | H13: 3
B14: Uma is highlighting the amount of work they have to do as a teaching professional. | C14: FALSE | D14: TRUE | E14: FALSE | F14: FALSE | G14: unsure if SIT pr INF | H14: 2
B15: That her job as a teacher is long | C15: FALSE | D15: FALSE | E15: TRUE | F15: FALSE | G15: inferred | H15: 2
B16: too much work | C16: FALSE | D16: FALSE | E16: TRUE | F16: FALSE | G16: ascribing uma emotions | H16: 3
... B23: She had to put the grades from each of the papers she marked into the computer system to record them | C23: TRUE | D23: FALSE | E23: FALSE | F23: FALSE | G23: paraphrase | H23: 3
A24: X | B24: A high workload | C24: FALSE | D24: FALSE | E24: INF | F24: FALSE | G24: inferred | H24: 3
B25: She says that the grades of the papers she marked had to be inputted into the computer. | C25: TRUE | D25: FALSE | E25: FALSE | F25: FALSE | G25: paraphrase | H25: 3
B26: That she had additional work load. | C26: FALSE | D26: TRUE | E26: FALSE | F26: FALSE | G26: not said if this was additional, ifnerence | H26: 3
B27: she had a lot of work to do and she was annoyed by how much | C27: FALSE | D27: FALSE | E27: FALSE | F27: TRUE | G27: ascribing uma emotions | H27: 3
B28: That she has additional work on top of her actually roles and responsibilities. | C28: FALSE | D28: FALSE | E28: TRUE | F28: FALSE | G28: never said this was additional work | H28: 3
H29: 3 | M29: QUD: | N29: "What was your workload like last semester?"
H30: 3
H31: 3
H32: 3
C35: =COUNTIF(C4:C32, TRUE) -> 4 | D35: =COUNTIF(D4:D32, TRUE) -> 7 | E35: =COUNTIF(E4:E32, TRUE) -> 8 | F35: =COUNTIF(F4:F32, TRUE) -> 5

Sheet play against computer...
A1: Randomly | B1: QID94 | G1: Comment | H1: Certainty
A2: Excluded? | B2: No, you play against the computer. | C2: PAR | D2: SIT | E2: INF | F2: EVA
B3: it's you against the machine which is always difficult when starting something new | C3: FALSE | D3: FALSE | E3: TRUE | F3: FALSE | G3: inferred that it's difficult | H3: 2 | K3: Stephen and Wade are discussing gaming: Stephen: Did you say you were gonna show me chess? Wade: Yes, er, Chinese chess, yeah. Stephen: You've got the actual board, haven't you? Wade: Yeah, I've got the board, yeah, but it'll be easier to show you on the iPad. Stephen: Why is that? Wade: Because you can keep going backwards and forwards and showing... it'll take the move back and it'll show you how it's moving. Stephen: Oh, okay. Wade: I mean, I can show you physically, but you'll see it on that 'cos it's easier. Stephen: Okay, give it a try... You say you can win against the computer sometimes? Wade: I can easy. I've only ever beaten it once at normal, probably over about five hundred games. Stephen: Do we, on the iPad, do we play against each other then, or what? Wade: No, you play against the computer. What do you think is conveyed by Wade in the underlined text?
B4: You play against the Chess AI if you play on the ipad | C4: TRUE | D4: FALSE | E4: FALSE | F4: FALSE | G4: paraphrase | H4: 3
B5: He is saying that when they practice playing Chinese chess on the iPad, you don’t play Addinsell another person, you play against the computer game. | C5: TRUE | D5: FALSE | E5: FALSE | F5: FALSE | G5: paraphrase | H5: 3
B6: A simple answer to who you're playing on the ipad to clear up the understanding for Stephen | C6: TRUE | D6: FALSE | E6: FALSE | F6: FALSE | G6: paraphrase | H6: 3
B7: He is better than Stephen so telling him to play the computer to win | C7: FALSE | D7: FALSE | E7: TRUE | F7: FALSE | G7: inference not directly said | H7: 3
B8: You don't play another person | C8: TRUE | D8: FALSE | E8: FALSE | F8: FALSE | G8: paraphrase | H8: 3
B9: we play chess against an ai oppoment | C9: TRUE | D9: FALSE | E9: FALSE | F9: FALSE | G9: paraphrase | H9: 3
A10: X | B10: Stephen finds the computer easier to beat than a human, so prefers the computer game to tge board game | C10: FALSE | D10: FALSE | E10: FALSE | F10: EVA | H10: 2
B11: he forgot the board | C11: FALSE | D11: FALSE | E11: TRUE | F11: FALSE | G11: inference not directly said | H11: 3
B12: That Stephen is going to play against a computer. | C12: TRUE | D12: FALSE | E12: FALSE | F12: FALSE | G12: paraphrase | H12: 3
B13: Th ipad games will be against a computer adverrsary , we will not play against each other, despite my statement that I will show you chess | C13: TRUE | D13: FALSE | E13: FALSE | F13: FALSE | G13: paraphrase | H13: 3
B14: That weird doesn't want Stefan to play with him on the game. Instead he wants Stefan to play with the computer | C14: TRUE | D14: FALSE | E14: FALSE | F14: FALSE | G14: paraphrase | H14: 3
B15: Wade telling Stephen to play the game against the computer | C15: TRUE | D15: FALSE | E15: FALSE | F15: FALSE | G15: paraphrase | H15: 3
B16: No, you play against the computer. | C16: TRUE | D16: FALSE | E16: FALSE | F16: FALSE | G16: paraphrase | H16: 3
B17: Can't play against a friend | C17: FALSE | D17: TRUE | E17: FALSE | F17: FALSE | G17: extended consequence of the situation | H17: 3
B18: The computer is your opponent, you are not playing against another human being. | C18: TRUE | D18: FALSE | E18: FALSE | F18: FALSE | G18: paraphrase | H18: 3
B19: Wade is explaining that when you play chess on a computer, you play not against your friends but against the computer | C19: TRUE | D19: FALSE | E19: FALSE | F19: FALSE | G19: paraphrase | H19: 3
A20: X | B20: Wade is explaining to Stephen that when you play on the iPad you play against a non-human player that is part of the game software. | C20: DPS | D20: FALSE | E20: FALSE | F20: FALSE | G20: paraphrase | H20: 3
B21: that there will be no human interaction | C21: FALSE | D21: TRUE | E21: FALSE | F21: FALSE | G21: extended consequence of the situation | H21: 3
B22: That you play the game with the computer. | C22: TRUE | D22: FALSE | E22: FALSE | F22: FALSE | G22: paraphrase | H22: 3
B23: That they aren't playing against each other, instead against the compute. | C23: TRUE | D23: FALSE | E23: FALSE | F23: FALSE | G23: paraphrase | H23: 3
B24: This is a computer game, you are not playing a real person. | C24: TRUE | D24: FALSE | E24: FALSE | F24: FALSE | G24: paraphrase | H24: 3
B25: Wade is trying to help his friends but seems very pushing in doing what he wants to do. | C25: FALSE | D25: FALSE | E25: FALSE | F25: TRUE | G25: unsure actually, is calling him pushy EVA? | H25: 2
B26: Wade doesn't seem to like losing as shown in that he's only playing against normal level in the game and not moving to a more difficult level like he should because he wins 99% of the time. He is worried about losing to Stephen so only wants to play against the computer. | C26: FALSE | D26: FALSE | E26: FALSE | F26: TRUE | G26: ascribes emotions to wade and steven | H26: 3
B27: Wade means the player competes against the computer. The "you" could be singular, as in Stephen, or plural, meaning both/either Wade and Stephen could play against the computer. | C27: TRUE | D27: FALSE | E27: FALSE | F27: FALSE | G27: paraphrase | H27: 3
B28: That it is a player versus the computer, and not player versus player | C28: TRUE | D28: FALSE | E28: FALSE | F28: FALSE | G28: paraphrase | H28: 3 | K28: QUD: | L28: shifts various times, but at the key utterance, it's "who do we play against on the IPAD"
C34: =COUNTIF(C3:C31, TRUE) -> 17 | D34: =COUNTIF(D3:D31, TRUE) -> 2 | E34: =COUNTIF(E3:E31, TRUE) -> 3 | F34: =COUNTIF(F3:F31, TRUE) -> 2 | G34: =SUM(C34:F34) -> 24

Sheet need a new computer...
A1: Randomly | B1: QID84 | G1: Comment | H1: Certainty
A2: Excluded? | B2: We need another computer. | C2: PAR | D2: SIT | E2: INF | F2: EVA
B3: That another computer will be needed in order to be able to listen to music and complete other computer-related tasks | C3: FALSE | D3: TRUE | E3: FALSE | F3: FALSE | G3: the need for another computer is tied to the concrete event of requiring more storage, which is part of the ongoing situation of using technology. It's not just a restatement or paraphrase of the situation; it’s about how the event (the need for another computer) relates to a tangible outcome (increased storage capacity) | H3: 2 | K3: Lucy and Dave are discussing technology: Lucy: How much space have you got on yours? Dave: Hm, don't know. Lucy: Is it on now? Dave: How much space do I need? Lucy: Erm, I don't know. I guess my music comes to— Dave: But then it's annoying because you can't listen to music and do stuff on the computer at the same time. We need another computer. Lucy: You'll probably need about fifty-sixty gigs. Dave: Fifty-sixty gigs. Lucy: It's a guess. What do you think is conveyed by Dave in the underlined text?
B4: They need another computer | C4: TRUE | D4: FALSE | E4: FALSE | F4: FALSE | G4: paraohrase | H4: 3
B5: That there is insufficient memory of their current computer | C5: FALSE | D5: TRUE | E5: FALSE | F5: FALSE | G5: the need for another computer is tied to the concrete event of requiring more storage, which is part of the ongoing situation of using technology. It's not just a restatement or paraphrase of the situation; it’s about how the event (the need for another computer) relates to a tangible outcome (increased storage capacity) | H5: 2
B6: Another computer is required to help store all the music. | C6: FALSE | D6: TRUE | E6: FALSE | F6: FALSE | G6: the need for another computer is tied to the concrete event of requiring more storage, which is part of the ongoing situation of using technology. It's not just a restatement or paraphrase of the situation; it’s about how the event (the need for another computer) relates to a tangible outcome (increased storage capacity) | H6: 2
B7: he needs a bigger hard drive or computer | C7: TRUE | D7: FALSE | E7: FALSE | F7: FALSE | G7: paraphrase | H7: 3
B8: He has concluded that they need a new computer due to a lack of storage space. He is quite definite about this claim, and seems to have concluded it suddenly. | C8: FALSE | D8: FALSE | E8: FALSE | F8: TRUE | G8: his certainty isEVA | H8: 3
B9: that they need another computer to listen to music on | C9: FALSE | D9: TRUE | E9: FALSE | F9: FALSE | G9: the need for another computer is tied to the concrete event of requiring more storage, which is part of the ongoing situation of using technology. It's not just a restatement or paraphrase of the situation; it’s about how the event (the need for another computer) relates to a tangible outcome (increased storage capacity) | H9: 2
B10: The gig space on the computer is not enough to support alot of storage | C10: FALSE | D10: TRUE | E10: FALSE | F10: FALSE | G10: paraphrase | H10: 3
B11: Dave needs more storage so he was suggesting getting a new system | C11: FALSE | D11: TRUE | E11: FALSE | F11: FALSE | G11: the purpose of the computer, is that SIT or DPS? I'm not entirely sure | H11: 2
B12: They need to buy a new computer. | C12: TRUE | D12: FALSE | E12: FALSE | F12: FALSE | G12: paraphrase | H12: 3
B13: dave wants another computer | C13: TRUE | D13: FALSE | E13: FALSE | F13: FALSE | G13: paraphrase | H13: 3
B14: thay they need to upgrade their computer as its not good enough for the task they want to do. | C14: FALSE | D14: TRUE | E14: FALSE | F14: FALSE | G14: the need for another computer is tied to the concrete event of requiring more storage, which is part of the ongoing situation of using technology. It's not just a restatement or paraphrase of the situation; it’s about how the event (the need for another computer) relates to a tangible outcome (increased storage capacity) | H14: 2
B15: That they need another device with planty of storage space on it. | C15: FALSE | D15: TRUE | E15: FALSE | F15: FALSE | G15: the need for another computer is tied to the concrete event of requiring more storage, which is part of the ongoing situation of using technology. It's not just a restatement or paraphrase of the situation; it’s about how the event (the need for another computer) relates to a tangible outcome (increased storage capacity) | H15: 2
B16: Their computer doesn’t serve their purpose anymore as it doesn’t have enough data storage. They need to buy a computer with more available storage. | C16: FALSE | D16: TRUE | E16: FALSE | F16: FALSE | H16: 2
B17: Sarcasm | C17: FALSE | D17: FALSE | E17: FALSE | F17: TRUE | G17: definitely EVA | H17: 3
B18: he would like a new additional computer | C18: TRUE | D18: FALSE | E18: FALSE | F18: FALSE | G18: paraphrase | H18: 3
B19: That he needs another computer for more storage capacity | C19: FALSE | D19: TRUE | E19: FALSE | F19: FALSE | G19: the need for another computer is tied to the concrete event of requiring more storage, which is part of the ongoing situation of using technology. It's not just a restatement or paraphrase of the situation; it’s about how the event (the need for another computer) relates to a tangible outcome (increased storage capacity) | H19: 2
B20: That they need another computer | C20: TRUE | D20: FALSE | E20: FALSE | F20: FALSE | G20: paraphrase | H20: 3
B21: He feels they need an additional device - computer it seems, so it could be laptop or desktop | C21: TRUE | D21: FALSE | E21: FALSE | F21: FALSE | G21: paraphrase | H21: 2
B22: Dave has run out of memory on his computer and wants a new one | C22: FALSE | D22: TRUE | E22: FALSE | F22: FALSE | G22: the need for another computer is tied to the concrete event of requiring more storage, which is part of the ongoing situation of using technology. It's not just a restatement or paraphrase of the situation; it’s about how the event (the need for another computer) relates to a tangible outcome (increased storage capacity) | H22: 3
B23: That there isn't enough storage on the one computer they are sharing for both Dave and Lucy to do everything they want to do on it, so it would be better if they had a computer each | C23: FALSE | D23: FALSE | E23: TRUE | F23: FALSE | G23: having a computer each is inferred somehow | H23: 2
B24: He is frustrated about the space on the computer so says he needs another one | C24: FALSE | D24: FALSE | E24: FALSE | F24: TRUE | G24: frusttration ascription is EVA | H24: 3
B25: Dave is suggesting he needs another computer (to allow multiple tasks to be undertaken at same time) | C25: FALSE | D25: TRUE | E25: FALSE | F25: FALSE | G25: the need for another computer is tied to the concrete event of requiring more storage, which is part of the ongoing situation of using technology. It's not just a restatement or paraphrase of the situation; it’s about how the event (the need for another computer) relates to a tangible outcome (increased storage capacity) | H25: 2
B26: Needing another computer to allow for listening to music - existing device doesn't have the space | C26: FALSE | D26: TRUE | E26: FALSE | F26: FALSE | G26: the need for another computer is tied to the concrete event of requiring more storage, which is part of the ongoing situation of using technology. It's not just a restatement or paraphrase of the situation; it’s about how the event (the need for another computer) relates to a tangible outcome (increased storage capacity) | H26: 2
A27: X | B27: Says exactly what they mean, they need an extra computer | C27: DPS | D27: FALSE | E27: FALSE | F27: FALSE | G27: paraphrase | H27: 3
C28: FALSE | D28: FALSE | E28: FALSE | F28: FALSE | H28: 2
K29: QUD: | L29: shifts various times, but at the key utterance, it's " “What’s the solution to this storage/functionality problem?”
C34: =COUNTIF(C3:C31, TRUE) -> 7 | D34: =COUNTIF(D3:D31, TRUE) -> 13 | E34: =COUNTIF(E3:E31, TRUE) -> 1 | F34: =COUNTIF(F3:F31, TRUE) -> 3 | G34: =SUM(C34:F34) -> 24

Sheet Don't keep anything on...
A1: Randomly | B1: QID23 | G1: Comment | H1: Certainty
A2: Excluded? | B2: I don't keep anything on the computer. | C2: PAR | D2: SIT | E2: INF | F2: EVA
B3: All Steph's info, programs etc are not kept on the computer's hard drive. | C3: TRUE | D3: FALSE | E3: FALSE | F3: FALSE | H3: 3 | J3: Steph and Marco are discussing technology: Steph: I've got all my, all my documents are on the... er... two shilabyte? trialabyte? trilabyte? Marco: Terabyte. Steph: Two terabyte, terabyte. Marco: Two terabytes. Steph: External drive. I've got buy-one-get-one-free from Maplins. Marco: Yeah. Steph: And I really ought to copy that onto... I've got none of the other one, the free one. Marco: No, if you've got one, that's fine. Steph: No, but if that goes tits up... Marco: Well, how many copy backups do you need? People only have one backup. Steph: The external drive is my drive, it's not on the computer. I don't keep anything on the computer. Marco: Why not? Steph: I'm jolly lucky, cos if it had been all on the computer, I would have nothing now. What do you think is conveyed by Steph in the underlined text?
B4: steph is saying she keeps all storage separate from her computer and uses an external drive to do so | C4: TRUE | D4: FALSE | E4: FALSE | F4: FALSE | H4: 3
B5: That something has happened to her computer. She is trying her best to back up her work and stay safe, but may not completely understand it. | C5: FALSE | D5: FALSE | E5: TRUE | F5: FALSE | G5: Inferred Situation, possibly with a slight Att shading — this suggests an evaluation, but it’s framed as part of interpreting the situation (e.g. deduced from her hesitancy over tech terms). | H5: 3
B6: Keeps stuff just on his external hard drive | C6: TRUE | D6: FALSE | E6: FALSE | F6: FALSE | H6: 3
B7: Doesn't trust the computer | C7: FALSE | D7: FALSE | E7: FALSE | F7: TRUE | H7: 3
B8: he’s a cautious person who thinks ahead | C8: FALSE | D8: FALSE | E8: FALSE | F8: TRUE | H8: 3
B9: She doesn’t think that anything is stored in computer | C9: TRUE | D9: FALSE | E9: FALSE | F9: FALSE | H9: 3
A10: X | B10: she isnt confident in the safety of online things | C10: FALSE | D10: FALSE | E10: FALSE | F10: EVA | G10: While it is inferred, the focus is on Steph’s attitude or stance — her lack of confidence, which is an evaluative or mental-state interpretation. | H10: 3
A11: X | B11: They keep everything in the cloud | C11: DPS | D11: FALSE | E11: FALSE | F11: FALSE | H11: 3
B12: They don't store anything on the internal drives of the computer, it is all on the external drive. | C12: TRUE | D12: FALSE | E12: FALSE | F12: FALSE | H12: 3
B13: She doesn’t trust saving data on a laptop | C13: FALSE | D13: FALSE | E13: FALSE | F13: TRUE | G13: It expresses an attitude of distrust toward a particular storage method (saving data on a laptop). | H13: 3
B14: Steph is happy to leave his data on an external drive, as the normal computer has had issues with losing data, so using an external drive insures data to be safe | C14: FALSE | D14: FALSE | E14: TRUE | F14: FALSE | H14: 3
B15: She is trying to explain how she backs up her data using the external drive. | C15: TRUE | D15: FALSE | E15: FALSE | F15: FALSE | H15: 3
B16: She keeps her files on a separate hard drive | C16: TRUE | D16: FALSE | E16: FALSE | F16: FALSE | H16: 3
A17: X | B17: She only has one copy backed up and keeps nothing stored on her computer | C17: DPS | D17: FALSE | E17: FALSE | F17: FALSE | H17: 3
B18: steph seems like she doesn't trust technology so she doesn't keep anything important on her computer | C18: FALSE | D18: FALSE | E18: FALSE | F18: TRUE | G18: t reflects an inference about Steph's general attitude toward technology (specifically, distrust). | H18: 3
B19: That all documents/pictures etc are not saved directly onto her completed but onto an external hard drive | C19: TRUE | D19: FALSE | E19: FALSE | F19: FALSE | H19: 3
A20: X | B20: that they do not keep anything on their computer | C20: DPS | D20: FALSE | E20: FALSE | F20: FALSE | H20: 3
B21: that her computer was broken | C21: FALSE | D21: FALSE | E21: TRUE | F21: FALSE | H21: 3
A22: X | B22: That her computer crashed | C22: FALSE | D22: FALSE | E22: INF | F22: FALSE | H22: 3
B23: Steph does not keep any saved documents or photos, etc on a computer. She just uses the computer to browse and does not save anything to the hard drive. | C23: FALSE | D23: TRUE | E23: FALSE | F23: FALSE | G23: Highlighting an actual habitual behaviour involving file storage and computer usage — not merely paraphrasing the utterance. | H23: 3
B24: that he doesn't trust a computer hard drive as secure storage | C24: FALSE | D24: FALSE | E24: TRUE | F24: FALSE | H24: 3
B25: She doesn't know much about computers, but she needs to copy her work. | C25: FALSE | D25: FALSE | E25: TRUE | F25: FALSE | H25: 3
B26: That Steph doesn't trust saving anything on her computer | C26: FALSE | D26: FALSE | E26: FALSE | F26: TRUE | H26: 3
B27: That she doesn't hold any information or personal files on her computer. | C27: TRUE | D27: FALSE | E27: FALSE | F27: FALSE | H27: 3
B28: SHE ISN'T AU FAI WITH SAFE DATA STORAGE | C28: FALSE | D28: FALSE | E28: TRUE | F28: FALSE | H28: 3
B29: shes not very good at technology in terms of backing her work up and dosent seem to understance | C29: FALSE | D29: FALSE | E29: FALSE | F29: TRUE | H29: 3 | J29: QUD: | K29: What kind of storage does Steph have for her files?
B30: Either the Computer has crashed, ben infected or stolen. In which case she would have lost all work | C30: FALSE | D30: FALSE | E30: TRUE | F30: FALSE | H30: 3
B31: She doesn't have these particular files, which she deems important to back up, on the harddrive on her computer | C31: TRUE | D31: FALSE | E31: FALSE | F31: FALSE | H31: 3
B32: I think she is saying she is very worried about data protection and online security. I imagine she is quite technically limited and doesn't understand computers | C32: FALSE | D32: FALSE | E32: FALSE | F32: TRUE | H32: 3
C34: =COUNTIF(C3:C31, TRUE) -> 10 | D34: =COUNTIF(D3:D31, TRUE) -> 1 | E34: =COUNTIF(E3:E31, TRUE) -> 7 | F34: =COUNTIF(F3:F31, TRUE) -> 6 | G34: =SUM(C34:F34) -> 24

Sheet Overview
A1: Dialogue | B1: PAR | C1: SIT | D1: INF | E1: EVA
A2: D1 | B2: ='Find it on the computer...'!C34 -> 8 | C2: ='Find it on the computer...'!D34 -> 0 | D2: ='Find it on the computer...'!E34 -> 7 | E2: ='Find it on the computer...'!F34 -> 9
A3: D2 | B3: ='Inputting grades...'!C35 -> 4 | C3: ='Inputting grades...'!D35 -> 7 | D3: ='Inputting grades...'!E35 -> 8 | E3: ='Inputting grades...'!F35 -> 5
A4: D3 | B4: ='play against computer...'!C34 -> 17 | C4: ='play against computer...'!D34 -> 2 | D4: ='play against computer...'!E34 -> 3 | E4: ='play against computer...'!F34 -> 2
A5: D4 | B5: ='need a new computer...'!C34 -> 7 | C5: ='need a new computer...'!D34 -> 13 | D5: ='need a new computer...'!E34 -> 1 | E5: ='need a new computer...'!F34 -> 3
A6: D5 | B6: ='Don''t keep anything on...'!C34 -> 10 | C6: ='Don''t keep anything on...'!D34 -> 1 | D6: ='Don''t keep anything on...'!E34 -> 7 | E6: ='Don''t keep anything on...'!F34 -> 6
A13: Response Type | B13: PAR | C13: SIT | D13: INF | E13: EVA
A14: Totals | B14: =SUM(Table6[PAR]) -> 46 | C14: =SUM(Table6[SIT]) -> 23 | D14: =SUM(Table6[INF]) -> 26 | E14: =SUM(Table6[EVA]) -> 25
A18: Column1 | B18: PAR | C18: SIT | D18: INF | E18: EVA | F18: total
A19: D1 | B19: =B2/Table69[[#This Row],[total]] -> 0.33333333 | C19: =C2/Table69[[#This Row],[total]] -> 0 | D19: =D2/Table69[[#This Row],[total]] -> 0.29166667 | E19: =E2/Table69[[#This Row],[total]] -> 0.375 | F19: =SUM(B2:E2) -> 24
A20: D2 | B20: =B3/Table69[[#This Row],[total]] -> 0.16666667 | C20: =C3/Table69[[#This Row],[total]] -> 0.29166667 | D20: =D3/Table69[[#This Row],[total]] -> 0.33333333 | E20: =E3/Table69[[#This Row],[total]] -> 0.20833333 | F20: =SUM(B3:E3) -> 24
A21: D3 | B21: =B4/Table69[[#This Row],[total]] -> 0.70833333 | C21: =C4/Table69[[#This Row],[total]] -> 0.083333333 | D21: =D4/Table69[[#This Row],[total]] -> 0.125 | E21: =E4/Table69[[#This Row],[total]] -> 0.083333333 | F21: =SUM(B4:E4) -> 24
A22: D4 | B22: =B5/Table69[[#This Row],[total]] -> 0.29166667 | C22: =C5/Table69[[#This Row],[total]] -> 0.54166667 | D22: =D5/Table69[[#This Row],[total]] -> 0.041666667 | E22: =E5/Table69[[#This Row],[total]] -> 0.125 | F22: =SUM(B5:E5) -> 24
A23: D5 | B23: =B6/Table69[[#This Row],[total]] -> 0.41666667 | C23: =C6/Table69[[#This Row],[total]] -> 0.041666667 | D23: =D6/Table69[[#This Row],[total]] -> 0.29166667 | E23: =E6/Table69[[#This Row],[total]] -> 0.25 | F23: =SUM(B6:E6) -> 24
