Workbook

Sheet Sheet0
A1: Q4 | B1: Q5 | C1: Q15 | D1: QID39 | E1: QID30 | F1: QID114 | G1: QID105 | H1: QID96
A2: What is your age? | B2: What is your highest level of education? | C2: Please select the domain that best describes your current occupation: | D2: Ethan and Kevin are discussing their friends: Kevin: I was like, for fuck's sake Mary, you've gotta buy all this shopping because I bought you that pizza. I bought you that glass of wine and the bus fare. Ethan: Mm. Kevin: "Oh yeah of course, no worries." Ethan: Yeah. Kevin: Cos she's generous. Ethan: Yeah. Kevin: She's generous but she'll just never- Ethan: She's just a bit scatty. Kevin: Yeah. Ethan: Which is the same as Jenny. You know, money isn't an issue, she's not tight. She just isn't engaged on the same planet. Kevin: Yeah. What do you think is conveyed by Ethan in the underlined text? | E2: Leah and Simon are discussing their future plans: Leah: Yeah, we'll see. I just want to go and have some adventures. Simon: I don't blame you. You only live once, don't you? You're only on this planet for a certain amount of time. Just go and experience it and enjoy the time. Leah: Mm-hm. Simon: Perhaps have memories if you live long enough, if you don't at least you enjoyed yourself. Leah: That's the idea. What do you think is conveyed by Simon in the underlined text? | F2: Deepthi and Marcus are discussing what they learnt about physics in primary school: Marcus: Mercury, Venus, Earth, Mars, Jupiter, Saturn, Uranus, Neptune Deepthi: What were you doing, in terms of planets? Marcus: Well she just wanted us to remember. Deepthi: But why? Marcus: I don't know. Deepthi: When I was little we also learnt Pluto but they've got rid of that now. They said it was too small to be a planet. Marcus: Pluto? Deepthi: I was alive when it was. Marcus: It was when you were born, Pluto? Deepthi: It was thought of as a planet. What do you think is conveyed by Deepthi in the underlined text? | G2: Miguel and Brigitte are discussing some documentaries Brigitte watched recently: Brigitte: The first one was looking at the effects on health and the second one was looking at the effects on the environment. Miguel: Ah mm. Brigitte: And to me, it was very impressive because- Miguel: I heard about this. Brigitte: It wasn't saying 'xyz', it was talking to lots of different people who have done different studies and some of them contradicted each other, you know. Miguel: Mm. Brigitte: And quite a lot of it was "well actually we don't we're not quite sure about this yet." Miguel: Right. Brigitte: But the general consensus was, the planet would be better if more people ate more vegetables and fewer less meat. Miguel: Yeah yeah yeah. Brigitte: And most people's health would be better if they ate less meat than they do. What do you think is conveyed by Brigitte in the underlined text? | H2: Murphy and Leo are discussing their views on London: Murphy: I lived in London for about six months and didn't like how vast it was. Leo: How old were you? Was that a long time? Murphy: Ah, it was, it was when I was eighteen, sorry, eighteen years ago. Leo: It's interesting cos I used to work for Helen. Murphy: Aha. Leo: A long time ago. And I worked at their office for about six months actually, and I hated London. Murphy: Really? Leo: With a passion. I think it's just dirty. I think it's the loneliest place on the planet, where so many people seem to be around. Murphy: Yeah, yeah. What do you think is conveyed by Leo in the underlined text?
A3: 45 - 54 | B3: Master’s Degree (e.g. MA. MSc) | C3: Sales and Marketing | F3: their teacher said Pluto wasn't big enough to be a planet
A4: 25 - 34 | B4: GCSE/O-level | C4: Finance and Banking
A5: 35 - 44 | B5: Bachelors Degree (e.g BA, BSc) | C5: Unemployed | G5: That the documentary suggested that the rate of climate change could be improved by cutting down meat consumption
A6: 35 - 44 | B6: Vocational Qualifications (e.g. NVQs, BTEC) | C6: Information Technology and Software Development
A7: 55 - 64 | B7: Higher National Certificate/higher National Diploma | C7: Information Technology and Software Development | H7: Leo had a hard time living in London
A8: 25 - 34 | B8: Bachelors Degree (e.g BA, BSc) | C8: Engineering and Manufacturing | E8: In the underlined text, Simon is saying that life is short, and while it’s great to make memories if you live long enough, the important thing is to enjoy life now, even if you don’t live for a long time.
A9: 25 - 34 | B9: Bachelors Degree (e.g BA, BSc) | C9: Nonprofit and Social Services | D9: He’s rude about people behind their back
A10: 55 - 64 | B10: Master’s Degree (e.g. MA. MSc) | C10: Engineering and Manufacturing
A11: 35 - 44 | B11: A-levels/Highers | C11: Nonprofit and Social Services
A12: 55 - 64 | B12: A-levels/Highers | C12: Retired | E12: Simon is suggesting to ‘live for the day’ that it, enjoy yourself each day as none of us know how long we shall live for
A13: 55 - 64 | B13: Bachelors Degree (e.g BA, BSc) | C13: Retired
A14: 35 - 44 | B14: Bachelors Degree (e.g BA, BSc) | C14: Retail and Customer Service
A15: 35 - 44 | B15: Vocational Qualifications (e.g. NVQs, BTEC) | C15: Law and Legal Services
A16: 25 - 34 | B16: Bachelors Degree (e.g BA, BSc) | C16: Education and Training | H16: London is very isolating
A17: 35 - 44 | B17: GCSE/O-level | C17: Unemployed
A18: 35 - 44 | B18: Bachelors Degree (e.g BA, BSc) | C18: Healthcare and Medicine | H18: He really dislikes London, and is saying that even though there are lots of people there, it is a really lonely place, or at least it was lonely for him.
A19: 25 - 34 | B19: Master’s Degree (e.g. MA. MSc) | C19: Consulting and Business Services
A20: 25 - 34 | B20: Master’s Degree (e.g. MA. MSc) | C20: Government and Public Administration
A21: 35 - 44 | B21: Bachelors Degree (e.g BA, BSc) | C21: Government and Public Administration
A22: 35 - 44 | B22: Vocational Qualifications (e.g. NVQs, BTEC) | C22: Law and Legal Services | G22: That people should eat less meat for the planet
A23: 25 - 34 | B23: Bachelors Degree (e.g BA, BSc) | C23: Education and Training | E23: Your life has a limited time span.
A24: 25 - 34 | B24: Bachelors Degree (e.g BA, BSc) | C24: Finance and Banking
A25: 35 - 44 | B25: A-levels/Highers | C25: Unemployed | G25: Eating less meat is better for the planet and people
A26: 25 - 34 | B26: Bachelors Degree (e.g BA, BSc) | C26: Education and Training | G26: That the meat industry and overproduction of meat is a leading cause for climate change
A27: 55 - 64 | B27: Bachelors Degree (e.g BA, BSc) | C27: Education and Training
A28: 35 - 44 | B28: A-levels/Highers | C28: Unemployed | F28: Deepthi provided a reason .
A29: 25 - 34 | B29: Bachelors Degree (e.g BA, BSc) | C29: Education and Training | E29: We don't live forever
A30: 25 - 34 | B30: Vocational Qualifications (e.g. NVQs, BTEC) | C30: Healthcare and Medicine | E30: To enjoy life while you can
A31: 35 - 44 | B31: Bachelors Degree (e.g BA, BSc) | C31: Arts and Humanities | D31: that Jenny is a little scatter brained
A32: 25 - 34 | B32: Vocational Qualifications (e.g. NVQs, BTEC) | C32: Information Technology and Software Development
A33: 25 - 34 | B33: Bachelors Degree (e.g BA, BSc) | C33: Education and Training
A34: 25 - 34 | B34: GCSE/O-level | C34: Construction and Skilled Trades
A35: 35 - 44 | B35: Bachelors Degree (e.g BA, BSc) | C35: Unemployed | G35: She is relating what she heard in the documentary
A36: 35 - 44 | B36: Bachelors Degree (e.g BA, BSc) | C36: Education and Training
A37: 25 - 34 | B37: Vocational Qualifications (e.g. NVQs, BTEC) | C37: Retail and Customer Service | H37: A justification as to why he hated London to make Murphy understand why he feels this way.
A38: 35 - 44 | B38: Master’s Degree (e.g. MA. MSc) | C38: Nonprofit and Social Services | E38: Life is short
A39: 25 - 34 | B39: Bachelors Degree (e.g BA, BSc) | C39: Law and Legal Services | H39: London is lonely
A40: 65 - 74 | B40: GCSE/O-level | C40: Transportation and Logistics
...

Sheet Not on the same planet
B1: QID39 | G1: Comment | H1: Certainty
A2: Excluded? | B2: she just isn't engaged on the same planet | C2: PAR | D2: SIT | E2: INF | F2: EVA
B3: He’s rude about people behind their back | C3: FALSE | D3: FALSE | E3: FALSE | F3: TRUE | G3: evaluation of speaker | H3: 3 | I3: Ethan and Kevin are discussing their friends: Kevin: I was like, for fuck's sake Mary, you've gotta buy all this shopping because I bought you that pizza. I bought you that glass of wine and the bus fare. Ethan: Mm. Kevin: "Oh yeah of course, no worries." Ethan: Yeah. Kevin: Cos she's generous. Ethan: Yeah. Kevin: She's generous but she'll just never- Ethan: She's just a bit scatty. Kevin: Yeah. Ethan: Which is the same as Jenny. You know, money isn't an issue, she's not tight. She just isn't engaged on the same planet. Kevin: Yeah. What do you think is conveyed by Ethan in the underlined text?
B4: that Jenny is a little scatter brained | C4: TRUE | D4: FALSE | E4: FALSE | F4: FALSE | G4: paraphrase | H4: 3
B5: she doesnt think the same way | C5: TRUE | D5: FALSE | E5: FALSE | F5: FALSE | G5: paraphrase | H5: 3
A6: X | B6: You can't talk to Jenny sensibly | C6: FALSE | D6: FALSE | E6: inf | F6: FALSE | G6: inference | H6: 3
B7: Shes a bit of an air head, not very smart | C7: FALSE | D7: FALSE | E7: TRUE | F7: FALSE | G7: inference | H7: 3
B8: He saying she isn't stingy with her money | C8: FALSE | D8: TRUE | E8: FALSE | F8: FALSE | G8: beyond DPS but within discourse | H8: 3
B9: Ethan is trying to state that she doesn't put in the effort when spending on him | C9: FALSE | D9: FALSE | E9: TRUE | F9: FALSE | G9: inference | H9: 3
B10: That she is not practical | C10: FALSE | D10: FALSE | E10: TRUE | F10: FALSE | G10: inference | H10: 3
B11: That money isnt something she actively thinks about in any goven moment | C11: FALSE | D11: TRUE | E11: FALSE | F11: FALSE | G11: beyond DPS but within discourse | H11: 3
A12: X | B12: She doesn’t get things like money - a bit flighty and not aerious | C12: FALSE | D12: sit | E12: FALSE | F12: FALSE | G12: beyond DPS but within discourse | H12: 3
B13: His friend is not fully engaged and grounded in the ‘real world’- she’s ditzy and acts in unusual ways. | C13: TRUE | D13: FALSE | E13: FALSE | F13: FALSE | G13: paraphrase | H13: 3
B14: that Jenny doesn't think the same way as other people | C14: TRUE | D14: FALSE | E14: FALSE | F14: FALSE | G14: paraphrase | H14: 3
B15: Jenny doesn't follow the social norms. | C15: FALSE | D15: FALSE | E15: TRUE | F15: FALSE | G15: inference | H15: 3
B16: I think by “isn’t engaged on the same planet” Ethan means she has unrealistic expectations compared to him, so it feels like she’s on another planet sometimes | C16: FALSE | D16: FALSE | E16: TRUE | F16: FALSE | G16: unrealistic expectations is an inference | H16: 3
B17: Meaning she doesn't recognise the societal expectations around roles and responsibilities | C17: FALSE | D17: FALSE | E17: TRUE | F17: FALSE | G17: inference | H17: 3
B18: that Mary doesn't really give much thought to her actions or their consequences | C18: FALSE | D18: FALSE | E18: TRUE | F18: FALSE | G18: inference | H18: 3
B19: Ethan is trying not to agree with what Kevin is saying by not really answering but then kind of sticking up for Mary by saying she is just a bit scatty. He then doesn't really engage much when talking about Jenny. | C19: FALSE | D19: TRUE | E19: FALSE | F19: FALSE | G19: beyond DPS but within discourse | H19: 3
A20: X | B20: That Mary isn't on the same planet as everyone else | C20: dps | D20: FALSE | E20: FALSE | F20: FALSE | G20: paraphrase | H20: 3
B21: He is saying how their other friends don't put the same amount of commitment as he does for the friendships. | C21: FALSE | D21: TRUE | E21: FALSE | F21: FALSE | G21: beyond DPS but within discourse | H21: 3
B22: That people have different perceptions of money, particularly if you are quite comfortable you might not think about the burden other people paying for you might put on them | C22: FALSE | D22: FALSE | E22: TRUE | F22: FALSE | G22: inference | H22: 3
B23: Ethan is displaying contempt | C23: FALSE | D23: FALSE | E23: FALSE | F23: TRUE | G23: attitude ascription | H23: 3
B24: She's not quite with it. She's kind of living in her own day dream. | C24: TRUE | D24: FALSE | E24: FALSE | F24: FALSE | G24: paraphrase | H24: 3
B25: That both jenny and sarah would never offer to do or pay for something unless they are asked to. They never use their judgement to offer but sont mind if they are asked which isnt always nice for the person doing the asking. | C25: FALSE | D25: TRUE | E25: FALSE | F25: FALSE | G25: beyond DPS but within discourse | H25: 3
B26: he is calling out jenny saying shes not engaged in another planet | C26: TRUE | D26: FALSE | E26: FALSE | F26: FALSE | G26: paraphrase | H26: 3
A27: X | B27: she doesnt realise that she is going over board with stuff | C27: FALSE | D27: FALSE | E27: inf | F27: FALSE | G27: inference | H27: 3
B28: That Jenny doesn't really think the same as they do. They are being quite negative towards them, and that Jenny should be spending more on them | C28: TRUE | D28: FALSE | E28: FALSE | F28: TRUE | G28: paraphrase | H28: 3 | I28: QUD: | J28: Why does Mary behave this way regarding money and generosity?
B29: Implying that Mary Does not have the same economic restrictions that most people in their social circle have | C29: FALSE | D29: FALSE | E29: TRUE | F29: FALSE | G29: inference | H29: 3
C30: FALSE | D30: FALSE | E30: FALSE | F30: FALSE | H30: 3
C31: FALSE | D31: FALSE | E31: FALSE | F31: FALSE | H31: 3
H32: 3
C33: =COUNTIF(C2:C30, TRUE) -> 7 | D33: =COUNTIF(D2:D30, TRUE) -> 5 | E33: =COUNTIF(E2:E30, TRUE) -> 9 | F33: =COUNTIF(F2:F30, TRUE) -> 3 | G33: =SUM(C33:F33) -> 24

Sheet you only live once
B1: QID30 | G1: Comment | H1: Certainty
A2: Excluded? | B2: you're only on this planet for a certain amount of time | C2: PAR | D2: SIT | E2: INF | F2: EVA
B3: In the underlined text, Simon is saying that life is short, and while it’s great to make memories if you live long enough, the important thing is to enjoy life now, even if you don’t live for a long time. | C3: FALSE | D3: TRUE | E3: FALSE | F3: FALSE | G3: make the most of it” is explicitly endorsed later in the dialogue (e.g., “that’s the idea”) supports the interpretation that it's not just an unstated implication (INF), but part of the structured trajectory of the conversation. It reflects a shared pragmatic orientation: Simon proposes a view, and Leah ratifies it, reinforcing that it's part of the joint reasoning or framing, which is characteristic of SIT. | H3: 2 | J3: Leah and Simon are discussing their future plans: Leah: Yeah, we'll see. I just want to go and have some adventures. Simon: I don't blame you. You only live once, don't you? You're only on this planet for a certain amount of time. Just go and experience it and enjoy the time. Leah: Mm-hm. Simon: Perhaps have memories if you live long enough, if you don't at least you enjoyed yourself. Leah: That's the idea. What do you think is conveyed by Simon in the underlined text?
B4: Simon is suggesting to ‘live for the day’ that it, enjoy yourself each day as none of us know how long we shall live for | C4: FALSE | D4: TRUE | E4: FALSE | F4: FALSE | G4: making the most = ES | H4: 3
B5: Your life has a limited time span. | C5: TRUE | D5: FALSE | E5: FALSE | F5: FALSE | G5: paraphrase | H5: 3
B6: We don't live forever | C6: TRUE | D6: FALSE | E6: FALSE | F6: FALSE | G6: paraphrase | H6: 3
B7: To enjoy life while you can | C7: FALSE | D7: TRUE | E7: FALSE | F7: FALSE | G7: making the most = ES | H7: 2
B8: Life is short | C8: TRUE | D8: FALSE | E8: FALSE | F8: FALSE | G8: paraphrase | H8: 3
B9: That you should go out and experience the world, as life is short. | C9: FALSE | D9: TRUE | E9: FALSE | F9: FALSE | G9: making the most = ES | H9: 2
B10: life is short | C10: TRUE | D10: FALSE | E10: FALSE | F10: FALSE | G10: paraphrase | H10: 3
B11: To go have fun and experiences | C11: FALSE | D11: TRUE | E11: FALSE | F11: FALSE | G11: making the most = ES | H11: 2
B12: Live life to the fullest | C12: FALSE | D12: TRUE | E12: FALSE | F12: FALSE | G12: making the most = ES | H12: 2
A13: X | B13: Life is short | C13: dps | D13: FALSE | E13: FALSE | F13: FALSE | G13: paraphrase | H13: 3
B14: you should do what you want, be adventerous because you don't live forever | C14: FALSE | D14: FALSE | E14: TRUE | F14: FALSE | G14: doing what ever you want is an inference | H14: 3
B15: Life is short so live whilst you can | C15: FALSE | D15: TRUE | E15: FALSE | F15: FALSE | G15: making the most = ES | H15: 2
B16: That we are only here on a temporary basis and must make the most of it. | C16: FALSE | D16: TRUE | E16: FALSE | F16: FALSE | G16: making the most = ES | H16: 2
B17: life is short so make the most of everyday. | C17: FALSE | D17: TRUE | E17: FALSE | F17: FALSE | G17: making the most = ES | H17: 2
B18: Time is fleeting and some experiences are worth having young and by all so do it now and worry about the consequences later. | C18: FALSE | D18: FALSE | E18: TRUE | F18: FALSE | G18: not worrying about the consequences is an inference | H18: 3
B19: Life is short. | C19: TRUE | D19: FALSE | E19: FALSE | F19: FALSE | G19: paraphrase | H19: 3
B20: Enjoy yourself because you only live a certain amount of time | C20: FALSE | D20: TRUE | E20: FALSE | F20: FALSE | G20: making the most = ES | H20: 2
B21: That people are only on this planet for a certain amount of time therefore Leah should go and have some adventures and create memories. | C21: FALSE | D21: TRUE | E21: FALSE | F21: FALSE | G21: making the most = ES | H21: 3
B22: Life is short. | C22: TRUE | D22: FALSE | E22: FALSE | F22: FALSE | G22: paraphrase | H22: 2
B23: Simon is conveying that life is short and you do not know what the near future holds so you should live for the moment. | C23: FALSE | D23: TRUE | E23: FALSE | F23: FALSE | G23: making the most = ES | H23: 3
B24: That you may aswell just enjoy things and try not to worry so much about the uncertainty of what may or may not be | C24: FALSE | D24: FALSE | E24: TRUE | F24: FALSE | G24: worrying is an implicature | H24: 2
B25: you are only alive for a short time so you may as well enjoy it | C25: FALSE | D25: TRUE | E25: FALSE | F25: FALSE | G25: making the most = ES | H25: 2
... B27: Simon is stating that life is finite. | C27: TRUE | D27: FALSE | E27: FALSE | F27: FALSE | G27: paraphrase | H27: 3
J28: QUD | K28: Why does Leah want to go and have adventures?
C33: =COUNTIF(C2:C30, TRUE) -> 7 | D33: =COUNTIF(D2:D30, TRUE) -> 14 | E33: =COUNTIF(E2:E30, TRUE) -> 3 | F33: =COUNTIF(F2:F30, TRUE) -> 0 | G33: =SUM(C33:F33) -> 24

Sheet pluto demotion
B1: QID114 | G1: Comment | H1: Certainty
A2: Excluded? | B2: they said it was too small to be a planet | C2: PAR | D2: SIT | E2: INF | F2: EVA
B3: their teacher said Pluto wasn't big enough to be a planet | C3: TRUE | D3: FALSE | E3: FALSE | F3: FALSE | G3: paraphrase | H3: 3 | J3: Deepthi and Marcus are discussing what they learnt about physics in primary school: Marcus: Mercury, Venus, Earth, Mars, Jupiter, Saturn, Uranus, Neptune Deepthi: What were you doing, in terms of planets? Marcus: Well she just wanted us to remember. Deepthi: But why? Marcus: I don't know. Deepthi: When I was little we also learnt Pluto but they've got rid of that now. They said it was too small to be a planet. Marcus: Pluto? Deepthi: I was alive when it was. Marcus: It was when you were born, Pluto? Deepthi: It was thought of as a planet. What do you think is conveyed by Deepthi in the underlined text?
A4: X | B4: Deepthi provided a reason . | C4: FALSE | D4: FALSE | E4: FALSE | F4: FALSE | H4: 3
B5: pluto is not a planet as too small | C5: TRUE | D5: FALSE | E5: FALSE | F5: FALSE | G5: paraphrase | H5: 3
A6: X | B6: More factual | C6: FALSE | D6: FALSE | E6: FALSE | F6: FALSE | H6: 3
B7: that the planet was too small to be counted amongst the rest. | C7: TRUE | D7: FALSE | E7: FALSE | F7: FALSE | G7: paraphrase | H7: 3
B8: That pluto used to be a planet buit isnt now as it is too small | C8: TRUE | D8: FALSE | E8: FALSE | F8: FALSE | G8: paraphrase | H8: 3
B9: Sesotho is explains why Pluto is no longer considered to be a planet due to its size, which is too small for a planet | C9: TRUE | D9: FALSE | E9: FALSE | F9: FALSE | G9: paraphrase | H9: 3
B10: Deepthi is showing a display of understanding of recent updates regarding the planet pluto | C10: FALSE | D10: TRUE | E10: FALSE | F10: FALSE | G10: broader discourse thing | H10: 3
B11: It wasn't big enough to be classed as a planet | C11: TRUE | D11: FALSE | E11: FALSE | F11: FALSE | G11: paraphrase | H11: 3
B12: pluto does not extist? | C12: FALSE | D12: FALSE | E12: TRUE | F12: FALSE | G12: weird inference | H12: 3
B13: Deepthi is referring to an unnamed authority that judged Pluto to be too small to be classed as a planet. | C13: TRUE | D13: FALSE | E13: FALSE | F13: FALSE | G13: paraphrase | H13: 3
B14: He disagrees with the reclassification of Pluto | C14: FALSE | D14: FALSE | E14: FALSE | F14: TRUE | G14: attributing emotion | H14: 3
A15: X | B15: Deepthi must have a refined sense of the absurd. I honestly cannot get anything out of that, no matter how many times I read it. | C15: FALSE | D15: FALSE | E15: FALSE | F15: FALSE | H15: 3
B16: THAT PLUTO WAS NOT IMPORTANT BECAUSE IT WAS SMALLER THAN THE REST OF THE PLANETS. THAT HE KNEW MORE THAN MARCUS | C16: FALSE | D16: FALSE | E16: TRUE | F16: FALSE | G16: more important is an inference | H16: 3
B17: Things change and get reclassified, but they sound bit disappointed | C17: FALSE | D17: FALSE | E17: FALSE | F17: TRUE | G17: attributing emotion | H17: 3
B18: That Pluto is no longer classified as a planet due to its small size | C18: TRUE | D18: FALSE | E18: FALSE | F18: FALSE | G18: paraphrase | H18: 3
B19: He's trying to explain that Pluto used to be thought of as a planet but no longer is | C19: TRUE | D19: FALSE | E19: FALSE | F19: FALSE | G19: paraphrase | H19: 3
B20: They are reiterating a fact which was taught to them. | C20: FALSE | D20: TRUE | E20: FALSE | F20: FALSE | G20: beyond dps, within discourse | H20: 3
B21: sharing knowledge to his friend, that he might not be aware of. | C21: FALSE | D21: FALSE | E21: TRUE | F21: FALSE | G21: not being aware is an inference | H21: 3
B22: He is stating the reason that Pluto was downgraded from being a planet, but he doesn't really feel that it is justified. | C22: FALSE | D22: FALSE | E22: FALSE | F22: TRUE | G22: attributing emotion | H22: 3
B23: That Pluto used to be a planet and now isnt | C23: TRUE | D23: FALSE | E23: FALSE | F23: FALSE | G23: paraphrase | H23: 3
A24: X | B24: giving someone elses opinion on the planet pluto | C24: FALSE | D24: FALSE | E24: FALSE | F24: FALSE | H24: 3
B25: That Pluto used to be a planet, and maybe he's old. | C25: FALSE | D25: FALSE | E25: TRUE | F25: FALSE | G25: him being old is inference | H25: 3
B26: That pluto is no longer regarded as a planet as it has been classified as too small. | C26: TRUE | D26: FALSE | E26: FALSE | F26: FALSE | G26: paraphrase | H26: 3
B27: Pluto is a dwarf planet apparently | C27: TRUE | D27: FALSE | E27: FALSE | F27: FALSE | G27: paraphrase | H27: 3
B28: That he has knowledge of certain events | C28: FALSE | D28: FALSE | E28: TRUE | F28: FALSE | G28: inference | H28: 3 | J28: QUD | K28: Why isn't Pluto considered a planet anymore?
A29: X | B29: a fact about the planet | C29: FALSE | D29: FALSE | E29: FALSE | F29: FALSE | H29: 3
B30: That scientists have decided Pluto is not a planet | C30: TRUE | D30: FALSE | E30: FALSE | F30: FALSE | G30: paraphrase | H30: 3
B31: The teachers advised Pluto used to be a planet but due to being small isn't anymore | C31: TRUE | D31: FALSE | E31: FALSE | F31: FALSE | G31: paraphrase | H31: 3
C34: =COUNTIF(C3:C31, TRUE) -> 14 | D34: =COUNTIF(D3:D31, TRUE) -> 2 | E34: =COUNTIF(E3:E31, TRUE) -> 5 | F34: =COUNTIF(F3:F31, TRUE) -> 3 | G34: =SUM(C34:F34) -> 24

Sheet save the planet
B1: QID105 | G1: Comment | H1: Certainty
A2: Excluded? | B2: the planet would be better if more people ate more vegetables and fewer less meat. | C2: PAR | D2: SIT | E2: INF | F2: EVA
B3: That the documentary suggested that the rate of climate change could be improved by cutting down meat consumption | C3: TRUE | D3: FALSE | E3: FALSE | F3: FALSE | G3: paraphrase | H3: 3 | J3: Miguel and Brigitte are discussing some documentaries Brigitte watched recently: Brigitte: The first one was looking at the effects on health and the second one was looking at the effects on the environment. Miguel: Ah mm. Brigitte: And to me, it was very impressive because- Miguel: I heard about this. Brigitte: It wasn't saying 'xyz', it was talking to lots of different people who have done different studies and some of them contradicted each other, you know. Miguel: Mm. Brigitte: And quite a lot of it was "well actually we don't we're not quite sure about this yet." Miguel: Right. Brigitte: But the general consensus was, the planet would be better if more people ate more vegetables and fewer less meat. Miguel: Yeah yeah yeah. Brigitte: And most people's health would be better if they ate less meat than they do. What do you think is conveyed by Brigitte in the underlined text?
B4: That people should eat less meat for the planet | C4: TRUE | D4: FALSE | E4: FALSE | F4: FALSE | G4: paraphrase | H4: 3
B5: Eating less meat is better for the planet and people | C5: TRUE | D5: FALSE | E5: FALSE | F5: FALSE | G5: paraphrase | H5: 3
B6: That the meat industry and overproduction of meat is a leading cause for climate change | C6: FALSE | D6: FALSE | E6: TRUE | F6: FALSE | G6: inference | H6: 3
A7: X | B7: She is relating what she heard in the documentary | C7: FALSE | D7: FALSE | E7: FALSE | F7: FALSE | H7: 3
B8: The documentary suggested that the world would be a better place if more people were vegetarian. | C8: TRUE | D8: FALSE | E8: FALSE | F8: FALSE | G8: paraphrase | H8: 3
B9: Environmental aspects Wouk£ be better if people decreased meat eating to protect the planet and are more vegetables | C9: TRUE | D9: FALSE | E9: FALSE | F9: FALSE | G9: paraphrase | H9: 3
B10: People's diets need to change to incoporate more veg and less meat as it's healthier. Too many people are eating meat excessively. | C10: FALSE | D10: TRUE | E10: FALSE | F10: FALSE | G10: too manuy people eatingmeat is an inference | H10: 3
B11: According to the study, eating vegetables and less meat is better for the environment | C11: TRUE | D11: FALSE | E11: FALSE | F11: FALSE | G11: paraphrase | H11: 3
B12: That they should be eating less meat to help save the planet | C12: TRUE | D12: FALSE | E12: FALSE | F12: FALSE | G12: paraphrase | H12: 3
B13: Brigitte learned that the Earth's environmental issues could be improved if humans reduced their meat consumption. | C13: TRUE | D13: FALSE | E13: FALSE | F13: FALSE | G13: paraphrase | H13: 3
B14: That the environmental impact of eating meat is greater than eating vegetables | C14: FALSE | D14: TRUE | E14: FALSE | F14: FALSE | G14: beyond dps | H14: 3
B15: saving the planet | C15: FALSE | D15: TRUE | E15: FALSE | F15: FALSE | G15: beyond dps | H15: 3
B16: Brigitte is elaborating on the one point that the researchers of the documentary she was watching agree on which is the impact that meat has on the planet hence they encourage people consume more vegetables than meat for the benefit of everyone. | C16: TRUE | D16: FALSE | E16: FALSE | F16: FALSE | G16: paraphrase | H16: 3
B17: that meat eating is bad for the environment | C17: FALSE | D17: TRUE | E17: FALSE | F17: FALSE | G17: beyond dps | H17: 3
B18: She offers a general conclusion of the research conducted, but not a conclusive one. | C18: FALSE | D18: FALSE | E18: TRUE | F18: FALSE | G18: inference | H18: 3
B19: She is explaining the main takeaway from the documentary as the other arguments contradicted each other. | C19: FALSE | D19: TRUE | E19: FALSE | F19: FALSE | G19: beyond dps | H19: 3
... B27: That we should be thinking more about the environment and one solution would be to eat more vegetables instead of meat | C27: TRUE | D27: FALSE | E27: FALSE | F27: FALSE | G27: paraphrase | H27: 3
J28: QUD | K28: What was the main message or conclusion of the documentaries?
C34: =COUNTIF(C3:C31, TRUE) -> 15 | D34: =COUNTIF(D3:D31, TRUE) -> 5 | E34: =COUNTIF(E3:E31, TRUE) -> 3 | F34: =COUNTIF(F3:F31, TRUE) -> 1 | G34: =SUM(C34:F34) -> 24

Sheet london is lonely 
B1: QID96 | G1: Comment | H1: Certainty
A2: Excluded? | B2: I think its the loneliest place on the planet | C2: PAR | D2: SIT | E2: INF | F2: EVA
B3: Leo had a hard time living in London | C3: FALSE | D3: TRUE | E3: FALSE | F3: FALSE | G3: kind of an inference of the utterance, but definitely seen in the rest of the dialogue | H3: 3 | J3: Murphy and Leo are discussing their views on London: Murphy: I lived in London for about six months and didn't like how vast it was. Leo: How old were you? Was that a long time? Murphy: Ah, it was, it was when I was eighteen, sorry, eighteen years ago. Leo: It's interesting cos I used to work for Helen. Murphy: Aha. Leo: A long time ago. And I worked at their office for about six months actually, and I hated London. Murphy: Really? Leo: With a passion. I think it's just dirty. I think it's the loneliest place on the planet, where so many people seem to be around. Murphy: Yeah, yeah. What do you think is conveyed by Leo in the underlined text?
B4: London is very isolating | C4: TRUE | D4: FALSE | E4: FALSE | F4: FALSE | G4: paraphrase | H4: 3
B5: He really dislikes London, and is saying that even though there are lots of people there, it is a really lonely place, or at least it was lonely for him. | C5: TRUE | D5: FALSE | E5: FALSE | F5: FALSE | G5: paraphrase | H5: 3
B6: A justification as to why he hated London to make Murphy understand why he feels this way. | C6: FALSE | D6: TRUE | E6: FALSE | F6: FALSE | G6: kind of an inference of the utterance, but definitely seen in the rest of the dialogue | H6: 3
B7: London is lonely | C7: TRUE | D7: FALSE | E7: FALSE | F7: FALSE | G7: paraphrase | H7: 3
B8: That London is too big and unfriendly | C8: FALSE | D8: FALSE | E8: TRUE | F8: FALSE | G8: not said, inference | H8: 3
B9: london is isolative | C9: TRUE | D9: FALSE | E9: FALSE | F9: FALSE | G9: paraphrase | H9: 3
B10: He only worked in London for 6 months. He thought it was a lonely place because there where so many people, but the where all strangers just getting on with there lives. | C10: TRUE | D10: FALSE | E10: FALSE | F10: FALSE | G10: paraphrase | H10: 3
A11: X | B11: he doesnt like london | C11: FALSE | D11: sit | E11: FALSE | F11: FALSE | G11: kind of an inference of the utterance, but definitely seen in the rest of the dialogue | H11: 3
B12: I think Leo is saying he was very lonely when he was in London | C12: TRUE | D12: FALSE | E12: FALSE | F12: FALSE | G12: paraphrase | H12: 3
B13: It is hard to make social connections in London outside of work. | C13: FALSE | D13: FALSE | E13: TRUE | F13: FALSE | G13: inference | H13: 3
B14: That Leo thinks London is the loneliest place on the planet and who particularly doesn't like it | C14: FALSE | D14: TRUE | E14: FALSE | F14: FALSE | G14: kind of an inference of the utterance, but definitely seen in the rest of the dialogue | H14: 3
B15: Leo is saying his impression about not having any connections despite of having so busy city many people around | C15: FALSE | D15: TRUE | E15: FALSE | F15: FALSE | G15: kind of an inference of the utterance, but definitely seen in the rest of the dialogue | H15: 3
B16: I think its the loneliest place on the planet | C16: TRUE | D16: FALSE | E16: FALSE | F16: FALSE | G16: paraphrase | H16: 3
B17: He felt lonely | C17: TRUE | D17: FALSE | E17: FALSE | F17: FALSE | G17: paraphrase | H17: 3
B18: London is a vast place and can seem really lonely even though it is full of other people. | C18: TRUE | D18: FALSE | E18: FALSE | F18: FALSE | G18: paraphrase | H18: 3
B19: Leo is saying he feels that London is the limiest place on the planet | C19: TRUE | D19: FALSE | E19: FALSE | F19: FALSE | G19: paraphrase | H19: 3
B20: Leo is expressing that even though London is swimming with people, he feels alone perhaps alluding to people not being friendly. | C20: FALSE | D20: FALSE | E20: TRUE | F20: FALSE | G20: alluding is a good sign of an inference | H20: 3
B21: he didn't integrate properly and failed to make friends or have a decent social life | C21: FALSE | D21: FALSE | E21: TRUE | F21: FALSE | G21: inference | H21: 3
B22: That London is a lonely place to live. | C22: TRUE | D22: FALSE | E22: FALSE | F22: FALSE | G22: paraphrase | H22: 3
B23: They felt lonely when they lived in London. | C23: TRUE | D23: FALSE | E23: FALSE | F23: FALSE | G23: paraphrase | H23: 3
B24: Although there are many people in London, it can be very lonely for people new to the city | C24: TRUE | D24: FALSE | E24: FALSE | F24: FALSE | G24: paraphrase | H24: 3
A25: X | B25: Getting someone else’s opinion while having a strong one of his own. | C25: FALSE | D25: FALSE | E25: FALSE | F25: FALSE | H25: 3
B26: Leo was emphasising how lonely he felt when he lived in London. | C26: TRUE | D26: FALSE | E26: FALSE | F26: FALSE | G26: paraphrase | H26: 3
B27: Leo is remarking on his dislike of London. He considers it a lonely place, probably because he was unhappy whilst working there. | C27: FALSE | D27: TRUE | E27: FALSE | F27: FALSE | G27: kind of an inference of the utterance, but definitely seen in the rest of the dialogue | H27: 3 | J27: QUD: | K27: What is it like to live in London?
B28: That even though there are many people that live there, people don't really associate with each other | C28: FALSE | D28: TRUE | E28: FALSE | F28: FALSE | G28: kind of an inference of the utterance, but definitely seen in the rest of the dialogue | H28: 3
C34: =COUNTIF(C3:C31, TRUE) -> 14 | D34: =COUNTIF(D3:D31, TRUE) -> 6 | E34: =COUNTIF(E3:E31, TRUE) -> 4 | F34: =COUNTIF(F3:F31, TRUE) -> 0 | G34: =SUM(C34:F34) -> 24

Sheet Summary
A1: Column1 | B1: PAR | C1: SIT | D1: INF | E1: EVA
A2: d1 | B2: ='Not on the same planet'!C33 -> 7 | C2: ='Not on the same planet'!D33 -> 5 | D2: ='Not on the same planet'!E33 -> 9 | E2: ='Not on the same planet'!F33 -> 3
A3: d2 | B3: ='you only live once'!C33 -> 7 | C3: ='you only live once'!D33 -> 14 | D3: ='you only live once'!E33 -> 3 | E3: ='you only live once'!F33 -> 0
A4: d3 | B4: ='pluto demotion'!C34 -> 14 | C4: ='pluto demotion'!D34 -> 2 | D4: ='pluto demotion'!E34 -> 5 | E4: ='pluto demotion'!F34 -> 3
A5: d4 | B5: ='save the planet'!C34 -> 15 | C5: ='save the planet'!D34 -> 5 | D5: ='save the planet'!E34 -> 3 | E5: ='save the planet'!F34 -> 1
A6: d5 | B6: ='london is lonely '!C34 -> 14 | C6: ='london is lonely '!D34 -> 6 | D6: ='london is lonely '!E34 -> 4 | E6: ='london is lonely '!F34 -> 0
A8: totals | B8: PAR | C8: SIT | D8: INF | E8: EVA
A9: totals | B9: =SUM(Table6[PAR]) -> 57 | C9: =SUM(Table6[SIT]) -> 32 | D9: =SUM(Table6[INF]) -> 24 | E9: =SUM(Table6[EVA]) -> 7
A11: Column1 | B11: PAR | C11: SIT | D11: INF | E11: EVA | F11: totals
A12: d1 | B12: =B2/Table69[[#This Row],[totals]] -> 0.29166667 | C12: =C2/Table69[[#This Row],[totals]] -> 0.20833333 | D12: =D2/Table69[[#This Row],[totals]] -> 0.375 | E12: =E2/Table69[[#This Row],[totals]] -> 0.125 | F12: =SUM(B2:E2) -> 24
A13: d2 | B13: =B3/Table69[[#This Row],[totals]] -> 0.29166667 | C13: =C3/Table69[[#This Row],[totals]] -> 0.58333333 | D13: =D3/Table69[[#This Row],[totals]] -> 0.125 | E13: =E3/Table69[[#This Row],[totals]] -> 0 | F13: =SUM(B3:E3) -> 24
A14: d3 | B14: =B4/Table69[[#This Row],[totals]] -> 0.58333333 | C14: =C4/Table69[[#This Row],[totals]] -> 0.083333333 | D14: =D4/Table69[[#This Row],[totals]] -> 0.20833333 | E14: =E4/Table69[[#This Row],[totals]] -> 0.125 | F14: =SUM(B4:E4) -> 24
A15: d4 | B15: =B5/Table69[[#This Row],[totals]] -> 0.625 | C15: =C5/Table69[[#This Row],[totals]] -> 0.20833333 | D15: =D5/Table69[[#This Row],[totals]] -> 0.125 | E15: =E5/Table69[[#This Row],[totals]] -> 0.041666667 | F15: =SUM(B5:E5) -> 24
A16: d5 | B16: =B6/Table69[[#This Row],[totals]] -> 0.58333333 | C16: =C6/Table69[[#This Row],[totals]] -> 0.25 | D16: =D6/Table69[[#This Row],[totals]] -> 0.16666667 | E16: =E6/Table69[[#This Row],[totals]] -> 0 | F16: =SUM(B6:E6) -> 24
