Workbook

Sheet Sheet0
A1: Q4 | B1: Q5 | C1: Q15 | D1: QID29 | E1: QID113 | F1: QID104 | G1: QID95 | H1: QID85
A2: What is your age? | B2: What is your highest level of education? | C2: Please select the domain that best describes your current occupation: | D2: Two friends are chatting about scientific struggles: Samantha: They spend like a lifetime working on one little aspect, and they know everything about it and they've worked it all out in their head. Tom: That's right. Samantha: I mean, it would be a real bugger if someone came along and said, "Oh, sorry, I’ve just proved you wrong".... Oh, my lifetime's work...Which must happen. Tom: That’s gotta happen. Well, it did happen once or twice, didn’t it? I mean... Samantha: Yeah. Tom: Somebody tried to prove Einstein’s theory wrong, didn’t they? Samantha: Well, I don’t think they tried to prove it wrong but they sort of like.... Tom: Well, they didn't prove it. What do you think is conveyed by Tom in the underlined text? | E2: Two close friends are talking about philosophers: Jordan: How can they sleep at night? Sam: Yeah I know. Jordan: Like, "this bed is not real." Jordan: That's why I would never ever want to be a philosopher. Jordan: Yeah. Sam: But then again it might be quite satisfying. Jordan: I mean, that’s just like the simple stuff. That was literally in our first lecture to get us introduced to it, and then after that it was all just, like, theory. Sam: Mm. Jordan: And it was so confusing like you don't even know. What do you think is conveyed by Jordan in the underlined text? | F2: Alice and Emma are arguing: Alice: I mean you're still accusing me of sleeping with Tim and that's bizarre. Emma: No, okay, alright, let's leave that now for now. Alice: And I don't know how many times I can tell you the same thing. Emma: Okay. Alice: And I told you to speak to him. Emma: Okay, I'm sorry. Alice: But you think we've got some kind of conspiracy theory going on. Emma: I'm sorry, okay. Alice: Where we've worked out some story that we'll lie to you. And you know, for what purpose I'm not quite sure. Emma: Can I just say what I was gonna say? What do you think is conveyed by Alice in the underlined text? | G2: Chrissy and Tay are discussing a holiday Tay is taking: Chrissy: Do they have Wi-Fi? Tay: They don’t have Wi-Fi. Unless you’re near the main house. Chrissy: Aha. Tay: So you can go to the main house and get Wi-Fi, and then in theory the log cabin has an Ethernet cable, but I took my computer one time and plugged it in and it didn't work, so... Chrissy: Oh, okay. Tay: And then it's got a little wood burner, and that's the only heating. Water is alright, the shower has a boiler where you don’t touch a thing. Don’t change the temperature, do nothing, and you should get warm water. Chrissy: Right, erm, that's funny. What do you think is conveyed by Tay in the underlined text? | H2: Iris and Matt are discussing Matt's future career: Iris: You could become a full-time philosopher. Matt: Yeah, cos there's lots of work for full-time philosophers... philosophising all day. Iris: Is there a lot of work for English literature students? Matt: Of course there is. Iris: Is there? Matt: Because you can go into anything. Iris: Like what? Matt: Well, anything that's not science, and you can just get additional training for anything, but to be a philosopher, like— Iris: Well, philosophers in theory should be able to go into anything as well. Matt: Well, yeah, if you do a philosophy degree. What do you think is conveyed by Iris in the underlined text?
A3: 45 - 54 | B3: Master’s Degree (e.g. MA. MSc) | C3: Sales and Marketing | E3: theory is too big and vast to comprehend
A4: 25 - 34 | B4: GCSE/O-level | C4: Finance and Banking
A5: 35 - 44 | B5: Bachelors Degree (e.g BA, BSc) | C5: Unemployed | F5: Alice is suggesting that Emma is being paranoid
A6: 35 - 44 | B6: Vocational Qualifications (e.g. NVQs, BTEC) | C6: Information Technology and Software Development | H6: That philosophers cannot really choose what field they work in, and that is somewhat ironic
A7: 55 - 64 | B7: Higher National Certificate/higher National Diploma | C7: Information Technology and Software Development | G7: the ethernet cable is broken
A8: 25 - 34 | B8: Bachelors Degree (e.g BA, BSc) | C8: Engineering and Manufacturing | D8: Tom is saying that someone tried to challenge Einstein’s theory, but they didn’t manage to disprove it.
A9: 25 - 34 | B9: Bachelors Degree (e.g BA, BSc) | C9: Nonprofit and Social Services
A10: 55 - 64 | B10: Master’s Degree (e.g. MA. MSc) | C10: Engineering and Manufacturing
A11: 35 - 44 | B11: A-levels/Highers | C11: Nonprofit and Social Services | H11: Philosophy has a broad range of transferable skills and information, suitable for a variety of jobs
A12: 55 - 64 | B12: A-levels/Highers | C12: Retired | D12: He is suggesting that people can be wrong in their scientific studies and that someone had challenged Einsteins theories
A13: 55 - 64 | B13: Bachelors Degree (e.g BA, BSc) | C13: Retired
A14: 35 - 44 | B14: Bachelors Degree (e.g BA, BSc) | C14: Retail and Customer Service
A15: 35 - 44 | B15: Vocational Qualifications (e.g. NVQs, BTEC) | C15: Law and Legal Services
A16: 25 - 34 | B16: Bachelors Degree (e.g BA, BSc) | C16: Education and Training | G16: There is an ethernet cable in the log cabin but it isn't reliable
A17: 35 - 44 | B17: GCSE/O-level | C17: Unemployed
A18: 35 - 44 | B18: Bachelors Degree (e.g BA, BSc) | C18: Healthcare and Medicine | G18: The place they are staying is supposed to have an Ethernet cable but that claim might not be true in practice
A19: 25 - 34 | B19: Master’s Degree (e.g. MA. MSc) | C19: Consulting and Business Services
A20: 25 - 34 | B20: Master’s Degree (e.g. MA. MSc) | C20: Government and Public Administration
A21: 35 - 44 | B21: Bachelors Degree (e.g BA, BSc) | C21: Government and Public Administration
A22: 35 - 44 | B22: Vocational Qualifications (e.g. NVQs, BTEC) | C22: Law and Legal Services | F22: That Emma has a conspiracy theory regarding Alice and Tim sleeping with each other but denying it.
A23: 25 - 34 | B23: Bachelors Degree (e.g BA, BSc) | C23: Education and Training | D23: Another scientist worked to disprove Einstein's theory, so someone could do the same for someone else's.
A24: 25 - 34 | B24: Bachelors Degree (e.g BA, BSc) | C24: Finance and Banking
A25: 35 - 44 | B25: A-levels/Highers | C25: Unemployed | F25: She's angry at Emma thinking she's been plotting to lie to her
A26: 25 - 34 | B26: Bachelors Degree (e.g BA, BSc) | C26: Education and Training | F26: That she thinks her friend is paranoid and distrusts her
A27: 55 - 64 | B27: Bachelors Degree (e.g BA, BSc) | C27: Education and Training | H27: That philosophy is equivalent to any other humanities degree
A28: 35 - 44 | B28: A-levels/Highers | C28: Unemployed | E28: I think Jordan means that everything that came after was a lot easier and just reading and learning based.
A29: 25 - 34 | B29: Bachelors Degree (e.g BA, BSc) | C29: Education and Training | D29: Einstein's work was disputed by someone
A30: 25 - 34 | B30: Vocational Qualifications (e.g. NVQs, BTEC) | C30: Healthcare and Medicine | D30: That someone might come and try and prove you wrong if you have a certain theory about something
A31: 35 - 44 | B31: Bachelors Degree (e.g BA, BSc) | C31: Arts and Humanities
A32: 25 - 34 | B32: Vocational Qualifications (e.g. NVQs, BTEC) | C32: Information Technology and Software Development
A33: 25 - 34 | B33: Bachelors Degree (e.g BA, BSc) | C33: Education and Training
A34: 25 - 34 | B34: GCSE/O-level | C34: Construction and Skilled Trades
A35: 35 - 44 | B35: Bachelors Degree (e.g BA, BSc) | C35: Unemployed | F35: Alice is hurt that Emma is accusing her of lying and concocting a plot to deceive
A36: 35 - 44 | B36: Bachelors Degree (e.g BA, BSc) | C36: Education and Training
A37: 25 - 34 | B37: Vocational Qualifications (e.g. NVQs, BTEC) | C37: Retail and Customer Service | G37: A slight passive aggressive comment conveying that there shpuld ve wifi but they weren't able to use it. A slight anger in the tone
A38: 35 - 44 | B38: Master’s Degree (e.g. MA. MSc) | C38: Nonprofit and Social Services | D38: People get things wrong
A39: 25 - 34 | B39: Bachelors Degree (e.g BA, BSc) | C39: Law and Legal Services | G39: There is a cable but it’s broken
A40: 65 - 74 | B40: GCSE/O-level | C40: Transportation and Logistics
...

Sheet Einstein's Theory
B1: QID29 | G1: Comment | H1: Certainty
A2: Excluded? | B2: someone tried to prove Einstein's theory wrong | C2: PAR | D2: SIT | E2: INF | F2: EVA
B3: Tom is saying that someone tried to challenge Einstein’s theory, but they didn’t manage to disprove it. | C3: TRUE | D3: FALSE | E3: FALSE | F3: FALSE | G3: paraphrase | H3: 3 | I3: Two friends are chatting about scientific struggles: Samantha: They spend like a lifetime working on one little aspect, and they know everything about it and they've worked it all out in their head. Tom: That's right. Samantha: I mean, it would be a real bugger if someone came along and said, "Oh, sorry, I’ve just proved you wrong".... Oh, my lifetime's work...Which must happen. Tom: That’s gotta happen. Well, it did happen once or twice, didn’t it? I mean... Samantha: Yeah. Tom: Somebody tried to prove Einstein’s theory wrong, didn’t they? Samantha: Well, I don’t think they tried to prove it wrong but they sort of like.... Tom: Well, they didn't prove it. What do you think is conveyed by Tom in the underlined text?
B4: He is suggesting that people can be wrong in their scientific studies and that someone had challenged Einsteins theories | C4: FALSE | D4: FALSE | E4: TRUE | F4: FALSE | G4: "people can be wrong" not stated, inference | H4: 2
B5: Another scientist worked to disprove Einstein's theory, so someone could do the same for someone else's. | C5: TRUE | D5: FALSE | E5: FALSE | F5: FALSE | G5: paraphrase | H5: 2
B6: Einstein's work was disputed by someone | C6: TRUE | D6: FALSE | E6: FALSE | F6: FALSE | G6: paraphrase | H6: 3
A7: X | B7: That someone might come and try and prove you wrong if you have a certain theory about something | C7: FALSE | D7: sit | E7: FALSE | F7: FALSE | G7: broader than dps | H7: 2
B8: People get things wrong | C8: FALSE | D8: FALSE | E8: TRUE | F8: FALSE | G8: inference | H8: 2
B9: That people try to undermine other people's hard work | C9: FALSE | D9: FALSE | E9: TRUE | F9: FALSE | G9: inference, undermining is an inference | H9: 3
B10: that even famous theories could be proved wrong | C10: TRUE | D10: FALSE | E10: FALSE | F10: FALSE | G10: captures core communicated content | H10: 2
B11: Not all theories are correct | C11: FALSE | D11: FALSE | E11: TRUE | F11: FALSE | G11: inference | H11: 3
B12: He always wants to prove people wrong | C12: FALSE | D12: FALSE | E12: TRUE | F12: FALSE | G12: inference | H12: 3
B13: Trying to use examples to prove a point | C13: FALSE | D13: TRUE | E13: FALSE | F13: FALSE | G13: broader than dps | H13: 2
B14: that scientist's theories are always being changed and disproven, even if it took someone's entire life to create a theory | C14: TRUE | D14: FALSE | E14: FALSE | F14: FALSE | G14: paraphrase | H14: 2
B15: Even great people can be proved wrong | C15: FALSE | D15: FALSE | E15: TRUE | F15: FALSE | G15: great people i don't think is in DPS | H15: 2
B16: A belief that someone tried to prove Einstein was incorrect | C16: TRUE | D16: FALSE | E16: FALSE | F16: FALSE | G16: paraphrase | H16: 3
B17: that science is ever evolving and theories that we thought were cirrect have later been proven wrong yet einstiens has yet to be proven wrong | C17: FALSE | D17: FALSE | E17: TRUE | F17: FALSE | G17: ever-evolving is an inference | H17: 2
B18: He is trying to use an example of 'somebody, sometime' trying to disprove Einstein's theory wrong and using this as a blanket exertion that lifetime research and studies by scientists are often overturned. | C18: FALSE | D18: TRUE | E18: FALSE | F18: FALSE | G18: broader than dps | H18: 2
B19: Another scientist worked to find a different outcome to Einstein's theory wrong, something that Einstein is famous for. | C19: TRUE | D19: FALSE | E19: FALSE | F19: FALSE | G19: paraphrase | H19: 3
... B23: Tom is conveying that he believes in Einstein's theory and someone wrongly tried to rubbish his theory. | C23: TRUE | D23: FALSE | E23: FALSE | F23: FALSE | G23: paraphrase | H23: 3
A24: X | B24: That there is always going to be somebody who doesnt believe or trust in you, it doesnt matter who you are it happens. | C24: FALSE | D24: FALSE | E24: inf | F24: FALSE | G24: inference | H24: 3
B25: that somebody tried to prove Einstein's theory wrong | C25: TRUE | D25: FALSE | E25: FALSE | F25: FALSE | G25: paraphrase | H25: 3
B26: I think Tom is referring to the fact that somebody tried to challenge or disprove Einstein's theory and by doing so he acknowledges that scientific theories are often tested | C26: FALSE | D26: TRUE | E26: FALSE | F26: FALSE | G26: broader than dps | H26: 2
B27: Tom is saying that some one will always think they know better than you. | C27: FALSE | D27: FALSE | E27: TRUE | F27: FALSE | G27: inference | H27: 3
B28: That someone tried to prove a theory to be wrong. | C28: TRUE | D28: FALSE | E28: FALSE | F28: FALSE | G28: paraphrase | H28: 3 | I28: QUD: | J28: What happens when a scientist’s lifetime work is challenged or disproven?"
C34: =COUNTIF(C3:C32, TRUE) -> 12 | D34: =COUNTIF(D3:D32, TRUE) -> 3 | E34: =COUNTIF(E3:E32, TRUE) -> 9 | F34: =COUNTIF(F3:F32, TRUE) -> 0 | G34: =SUM(C34:F34) -> 24

Sheet Philosophy
B1: QID113 | G1: COMMENT | H1: CERTAINTY
A2: Excluded? | B2: after that it was all just like theory | C2: PAR | D2: SIT | E2: INF | F2: EVA
B3: theory is too big and vast to comprehend | C3: FALSE | D3: FALSE | E3: TRUE | F3: FALSE | G3: inference | H3: 3 | J3: Two close friends are talking about philosophers: Jordan: How can they sleep at night? Sam: Yeah I know. Jordan: Like, "this bed is not real." Jordan: That's why I would never ever want to be a philosopher. Jordan: Yeah. Sam: But then again it might be quite satisfying. Jordan: I mean, that’s just like the simple stuff. That was literally in our first lecture to get us introduced to it, and then after that it was all just, like, theory. Sam: Mm. Jordan: And it was so confusing like you don't even know. What do you think is conveyed by Jordan in the underlined text?
B4: I think Jordan means that everything that came after was a lot easier and just reading and learning based. | C4: FALSE | D4: FALSE | E4: TRUE | F4: FALSE | G4: inference | H4: 3
B5: fed up with doing theory | C5: FALSE | D5: FALSE | E5: FALSE | F5: TRUE | G5: attributing emotion | H5: 3
A6: X | B6: His belief and theory | C6: FALSE | D6: FALSE | E6: FALSE | F6: FALSE
B7: the rest of the lecture was of a theoretical nature | C7: TRUE | D7: FALSE | E7: FALSE | F7: FALSE | G7: paraphrase | H7: 3
B8: The first lecture, hes either seriously upset about the philosopher's words or thinks it's ridiculous. Then seems to be frustrated that its was all theory suggesting it is boring or tedious | C8: FALSE | D8: FALSE | E8: FALSE | F8: TRUE | G8: attributing emotion | H8: 3
A9: X | B9: Jordan seems to be expressing disappointment that his philosophy course was all theory based | C9: FALSE | D9: FALSE | E9: FALSE | F9: eva | G9: attributing emotion | H9: 3
A10: X | B10: Jordan is displaying a real intrigue and curiosity into the mindset of philosophers. | C10: FALSE | D10: FALSE | E10: FALSE | F10: FALSE
B11: It is really confusing stuff | C11: FALSE | D11: TRUE | E11: FALSE | F11: FALSE | G11: beyond DPS but in discourse | H11: 2
B12: that profession is not meaningful | C12: FALSE | D12: FALSE | E12: TRUE | F12: FALSE | G12: inference | H12: 3
B13: Jordan is dissatisfied that the subsequent lectures were mostly theory based rather than practical | C13: FALSE | D13: FALSE | E13: FALSE | F13: TRUE | G13: attributing emotion | H13: 3
B14: I think he was disappointed in his lectures | C14: FALSE | D14: FALSE | E14: FALSE | F14: TRUE | G14: attributing emotion | H14: 3
B15: Gibberish. | C15: FALSE | D15: FALSE | E15: FALSE | F15: TRUE | G15: attributing emotion | H15: 3
B16: THAT HE PREFERS A MORE PRACTICAL WAY OF LEARNING AND HE WAS NOT IN TO THEORY BASED LEARNING | C16: FALSE | D16: FALSE | E16: TRUE | F16: FALSE | G16: inference | H16: 3
B17: That they weren't really understanding the lectures and found it not very exciting but confusing | C17: FALSE | D17: TRUE | E17: FALSE | F17: FALSE | G17: beyond DPS but in discourse | H17: 2
B18: philosophy is just a bundle of theories | C18: FALSE | D18: FALSE | E18: TRUE | F18: FALSE | G18: inference | H18: 3
B19: He doesn't understand philosophy | C19: FALSE | D19: FALSE | E19: TRUE | F19: FALSE | G19: inference | H19: 3
A20: X | B20: They are providing their experience of what happened. | C20: FALSE | D20: FALSE | E20: FALSE | F20: FALSE
B21: That the lecturer was sharing basic information during the lecture, perhaps throwing perspectives from other philosophers, as opposed to getting the class involved and giving them real life examples of philosophy. | C21: FALSE | D21: FALSE | E21: TRUE | F21: FALSE | G21: inference | H21: 3
B22: The study content is all theoretical, there is no practical substance to the topics and anything discussed is completely open to individual interpretation. | C22: FALSE | D22: FALSE | E22: TRUE | F22: FALSE | G22: inference | H22: 3
B23: his disinterest in the subject | C23: FALSE | D23: FALSE | E23: FALSE | F23: TRUE | G23: attributing emotion | H23: 3
A24: X | B24: not giving answers but rather presumption | C24: FALSE | D24: FALSE | E24: FALSE | F24: FALSE
B25: That Philosophy is difficult and he would not like to live like aPhilosepher. also that it is very confusing. | C25: FALSE | D25: FALSE | E25: FALSE | F25: TRUE | G25: attributing emotion | H25: 3
B26: That the majority of their lecturers have mean theoretical rather than practical. | C26: TRUE | D26: FALSE | E26: FALSE | F26: FALSE | G26: paraphrase | H26: 3
B27: All of the rest of the lecture was about theory in philosophy rather than what they found interesting. | C27: TRUE | D27: FALSE | E27: FALSE | F27: FALSE | G27: paraphrase | H27: 3 | J27: QUD | K27: Why is philosophy so difficult or unsatisfying for some people?
B28: Confusion but with a side of him trying to explain in a way he knows what he is talking about | C28: FALSE | D28: FALSE | E28: FALSE | F28: TRUE | G28: evaluation | H28: 3
B29: how much harder the content is now | C29: FALSE | D29: FALSE | E29: TRUE | F29: FALSE | G29: inference | H29: 3
B30: That philosophy became confusing and abstract? | C30: FALSE | D30: FALSE | E30: TRUE | F30: FALSE | G30: inference | H30: 3
B31: Theory of philosophy is confusing | C31: FALSE | D31: TRUE | E31: FALSE | F31: FALSE | G31: beyond DPS but in discourse | H31: 2
C34: =COUNTIF(C3:C32, TRUE) -> 3 | D34: =COUNTIF(D3:D32, TRUE) -> 3 | E34: =COUNTIF(E3:E32, TRUE) -> 10 | F34: =COUNTIF(F3:F32, TRUE) -> 8 | G34: =SUM(C34:F34) -> 24

Sheet Conspiracy Theory
B1: QID104 | G1: COMMENT | H1: CERTAINTY
A2: Excluded? | B2: you think we've got some kind of conspiracy theory going on | C2: PAR | D2: SIT | E2: INF | F2: EVA
B3: Alice is suggesting that Emma is being paranoid | C3: FALSE | D3: FALSE | E3: TRUE | F3: FALSE | G3: inference | H3: 3 | J3: Alice and Emma are arguing: Alice: I mean you're still accusing me of sleeping with Tim and that's bizarre. Emma: No, okay, alright, let's leave that now for now. Alice: And I don't know how many times I can tell you the same thing. Emma: Okay. Alice: And I told you to speak to him. Emma: Okay, I'm sorry. Alice: But you think we've got some kind of conspiracy theory going on. Emma: I'm sorry, okay. Alice: Where we've worked out some story that we'll lie to you. And you know, for what purpose I'm not quite sure. Emma: Can I just say what I was gonna say? What do you think is conveyed by Alice in the underlined text?
B4: That Emma has a conspiracy theory regarding Alice and Tim sleeping with each other but denying it. | C4: TRUE | D4: FALSE | E4: FALSE | F4: FALSE | G4: paraphrase | H4: 3
B5: She's angry at Emma thinking she's been plotting to lie to her | C5: FALSE | D5: FALSE | E5: FALSE | F5: TRUE | G5: attributing emotion | H5: 3
B6: That she thinks her friend is paranoid and distrusts her | C6: FALSE | D6: FALSE | E6: FALSE | F6: TRUE | G6: attributing emotion | H6: 3
B7: Alice is hurt that Emma is accusing her of lying and concocting a plot to deceive | C7: FALSE | D7: FALSE | E7: FALSE | F7: TRUE | G7: attributing emotion | H7: 3
B8: Alice is annoyed because Emma thinks she had sex with Tim who is probably Emma's partner. Alice thinks that Emma thinks that her and Tim are both covering up about it. | C8: FALSE | D8: FALSE | E8: FALSE | F8: TRUE | G8: attributing emotion | H8: 3
B9: That Emma thinks they are making things up about them | C9: TRUE | D9: FALSE | E9: FALSE | F9: FALSE | G9: paraphrase | H9: 3
B10: Emma thinks Alice is sleeping with her boyfriend and Alice is denying this. | C10: FALSE | D10: TRUE | E10: FALSE | F10: FALSE | G10: not the utterance but in discourse | H10: 3
B11: Alice thinks that Emma is suspicious of there being some kind of plot going on between them. | C11: TRUE | D11: FALSE | E11: FALSE | F11: FALSE | G11: paraphrase | H11: 3
B12: That Emma has a whole scenario in her head that is untrue | C12: FALSE | D12: TRUE | E12: FALSE | F12: FALSE | G12: not the utterance but in discourse | H12: 2
B13: Emma thinks that Alice and Tim are deliberately lying to her to hurt her feelings. | C13: TRUE | D13: FALSE | E13: FALSE | F13: FALSE | G13: paraphrase | H13: 2
B14: That Emma is believing a conspiracy that she created in her head | C14: TRUE | D14: FALSE | E14: FALSE | F14: FALSE | G14: paraphrase | H14: 3
B15: no trust | C15: FALSE | D15: FALSE | E15: TRUE | F15: FALSE | G15: inference | H15: 3
... B18: She is asserting that Emma has become obsessed with her friends colluding. | C18: FALSE | D18: FALSE | E18: TRUE | F18: FALSE | G18: inference | H18: 3
A19: X | B19: That she is defending herself and questioning Emma | C19: FALSE | D19: FALSE | E19: FALSE | F19: FALSE
B20: That she is telling the truth but conspiring with Tim to both tell lies to cover up their affair | C20: TRUE | D20: FALSE | E20: FALSE | F20: FALSE | G20: paraphrase | H20: 3
B21: That she's annoyed by being asked about the subject, wants to end the conversation by making Emma look unhinged. There may also be a suspicion of some kind of involvment between Emma and Tim | C21: FALSE | D21: FALSE | E21: FALSE | F21: TRUE | G21: attributing emotion | H21: 3
B22: That Emma is not trusting her and thinks there is a conspiracy theory about Alice and Tim | C22: TRUE | D22: FALSE | E22: FALSE | F22: FALSE | G22: paraphrase | H22: 3
B23: Lack of trust within the relationships | C23: FALSE | D23: FALSE | E23: TRUE | F23: FALSE | G23: inference | H23: 3
B24: The she and Tim had planned to lie to Emma about them sleeping together. | C24: TRUE | D24: FALSE | E24: FALSE | F24: FALSE | G24: paraphrase | H24: 3
B25: The she is being underhand and hiding information. | C25: FALSE | D25: FALSE | E25: TRUE | F25: FALSE | G25: inference | H25: 3
B26: Alice thinks that Emma believe something fishy is going on and she is being lied to | C26: TRUE | D26: FALSE | E26: FALSE | F26: FALSE | G26: paraphrase | H26: 3
B27: That Emma thinks she's not being truthful and they are lying to cover their backs, | C27: TRUE | D27: FALSE | E27: FALSE | F27: FALSE | G27: paraphrase | H27: 3
J28: QUD | K28: Why is Emma still suspicious or disbelieving of Alice and Tim?
C34: =COUNTIF(C3:C32, TRUE) -> 12 | D34: =COUNTIF(D3:D32, TRUE) -> 2 | E34: =COUNTIF(E3:E32, TRUE) -> 5 | F34: =COUNTIF(F3:F32, TRUE) -> 5 | G34: =SUM(C34:F34) -> 24

Sheet Ethernet cable
B1: QID95 | G1: COMMENT | H1: CERTAINTY
A2: Excluded? | B2: In theory the log cabin has an ethernet cable | C2: PAR | D2: SIT | E2: INF | F2: EVA
B3: the ethernet cable is broken | C3: TRUE | D3: FALSE | E3: FALSE | F3: FALSE | G3: paraphrase | H3: 2 | J3: Chrissy and Tay are discussing a holiday Tay is taking: Chrissy: Do they have Wi-Fi? Tay: They don’t have Wi-Fi. Unless you’re near the main house. Chrissy: Aha. Tay: So you can go to the main house and get Wi-Fi, and then in theory the log cabin has an Ethernet cable, but I took my computer one time and plugged it in and it didn't work, so... Chrissy: Oh, okay. Tay: And then it's got a little wood burner, and that's the only heating. Water is alright, the shower has a boiler where you don’t touch a thing. Don’t change the temperature, do nothing, and you should get warm water. Chrissy: Right, erm, that's funny. What do you think is conveyed by Tay in the underlined text?
A4: X | B4: There is an ethernet cable in the log cabin but it isn't reliable | C4: dps | D4: FALSE | E4: FALSE | F4: FALSE | G4: paraphrase | H4: 3
B5: The place they are staying is supposed to have an Ethernet cable but that claim might not be true in practice | C5: TRUE | D5: FALSE | E5: FALSE | F5: FALSE | G5: paraphrase | H5: 3
B6: A slight passive aggressive comment conveying that there shpuld ve wifi but they weren't able to use it. A slight anger in the tone | C6: FALSE | D6: FALSE | E6: FALSE | F6: TRUE | G6: emotions ascribed | H6: 3
B7: There is a cable but it’s broken | C7: TRUE | D7: FALSE | E7: FALSE | F7: FALSE | G7: paraphrase | H7: 3
B8: There probably isn't useable wifi in the log cabin | C8: FALSE | D8: TRUE | E8: FALSE | F8: FALSE | G8: inference | H8: 2
B9: there is an ethernet cable, it might not work | C9: TRUE | D9: FALSE | E9: FALSE | F9: FALSE | G9: paraphrase | H9: 3
B10: Tay isn't impressed by the place he is staying in. With its lack of WiFi, basis heating and boiler | C10: FALSE | D10: FALSE | E10: FALSE | F10: TRUE | G10: emotions ascribed | H10: 3
B11: that the holiday place is not great | C11: FALSE | D11: FALSE | E11: TRUE | F11: FALSE | G11: inference | H11: 3
B12: That he is unsure if the cabin does have an Ethernet cable | C12: FALSE | D12: FALSE | E12: TRUE | F12: FALSE | G12: inference and wrong | H12: 2
B13: The ethernet connection advertised does not work in practice | C13: TRUE | D13: FALSE | E13: FALSE | F13: FALSE | G13: paraphrase | H13: 3
B14: That the cabin should have a ethernet cable | C14: TRUE | D14: FALSE | E14: FALSE | F14: FALSE | G14: paraphrase | H14: 2
A15: X | B15: Tay is talking about the facility of Ethernet cable available within the log cabin | C15: FALSE | D15: FALSE | E15: FALSE | F15: FALSE
B16: In theory the log cabin has an ethernet cable | C16: TRUE | D16: FALSE | E16: FALSE | F16: FALSE | G16: paraphrase | H16: 3
B17: He doesn't believe it | C17: FALSE | D17: FALSE | E17: FALSE | F17: TRUE | G17: attribution of emotions | H17: 2
B18: The log cabin has internet access but it doesnt always work. | C18: TRUE | D18: FALSE | E18: FALSE | F18: FALSE | G18: paraphrase | H18: 3
B19: Tau is explaining that. Theory you could use the Ethernet cable to access the internet | C19: TRUE | D19: FALSE | E19: FALSE | F19: FALSE | G19: paraphrase | H19: 3
B20: Tay is explaining that there is a cable that could be used for internet in the log cabin, but she tried it and it did not work so it is something that should work, but does not. | C20: FALSE | D20: TRUE | E20: FALSE | F20: FALSE | G20: broader than dps | H20: 2
B21: that Chrissy should not expect to rely on having a functioning internet connection whilst in the log cabin | C21: FALSE | D21: FALSE | E21: TRUE | F21: FALSE | G21: inference | H21: 3
B22: The log cabin should have an ethernet cable. | C22: TRUE | D22: FALSE | E22: FALSE | F22: FALSE | G22: paraphrase | H22: 3
B23: You are meant to be able to use wired ethernet connection not wired connection. | C23: FALSE | D23: TRUE | E23: FALSE | F23: FALSE | G23: broader than dps | H23: 2
B24: The connection in the cabin does not work. | C24: TRUE | D24: FALSE | E24: FALSE | F24: FALSE | G24: paraphrase | H24: 2
B25: That she knows everything about the holiday they are going to take. She’s in control and likes to know everything she needs to before going. | C25: FALSE | D25: FALSE | E25: TRUE | F25: FALSE | G25: inference | H25: 3
B26: Tay doesn't understand why the Ethernet cable didn't work as she believes theoretically it should have. | C26: FALSE | D26: FALSE | E26: TRUE | F26: FALSE | G26: inference | H26: 2
B27: Tay mentions that the ethernet cable should mean his computer would be able to go online. But he wasn't able to connect in reality | C27: FALSE | D27: TRUE | E27: FALSE | F27: FALSE | G27: broader than dps | H27: 2 | J27: QUD | K27: What kind of internet access is available where you're staying?
B28: That there is internet in the log cabin, but you have to use a cable connection | C28: FALSE | D28: TRUE | E28: FALSE | F28: FALSE | G28: broader than dps | H28: 2
C34: =COUNTIF(C3:C32, TRUE) -> 11 | D34: =COUNTIF(D3:D32, TRUE) -> 5 | E34: =COUNTIF(E3:E32, TRUE) -> 5 | F34: =COUNTIF(F3:F32, TRUE) -> 3 | G34: =SUM(C34:F34) -> 24

Sheet Work availability
B1: QID85 | G1: COMMENT | H1: CERTAINTY
A2: Excluded? | B2: philosophers in theory should be able to go into anything as well | C2: PAR | D2: SIT | E2: INF | F2: EVA
B3: That philosophers cannot really choose what field they go into | C3: FALSE | D3: FALSE | E3: TRUE | F3: FALSE | G3: inference | H3: 3 | J3: Iris and Matt are discussing Matt's future career: Iris: You could become a full-time philosopher. Matt: Yeah, cos there's lots of work for full-time philosophers... philosophising all day. Iris: Is there a lot of work for English literature students? Matt: Of course there is. Iris: Is there? Matt: Because you can go into anything. Iris: Like what? Matt: Well, anything that's not science, and you can just get additional training for anything, but to be a philosopher, like— Iris: Well, philosophers in theory should be able to go into anything as well. Matt: Well, yeah, if you do a philosophy degree. What do you think is conveyed by Iris in the underlined text?
B4: Philosophy has a broad range of transferable skills and information, suitable for a variety of jobs | C4: FALSE | D4: TRUE | E4: FALSE | F4: FALSE | G4: beyond dps | H4: 2
B5: That philosophy is equivalent to any other humanities degree | C5: FALSE | D5: TRUE | E5: FALSE | F5: FALSE | G5: beyond dps | H5: 2
B6: A degree in philosophy has multiple applications rather than one thing. | C6: TRUE | D6: FALSE | E6: FALSE | F6: FALSE | G6: paraphrase | H6: 3
A7: X | B7: justification of a choice of philosophy | C7: FALSE | D7: FALSE | E7: FALSE | F7: FALSE
B8: That as philosophy is such a broad abstract study, Matt thinks about everything and anything. He can 'go into' any sector through thought. | C8: TRUE | D8: FALSE | E8: FALSE | F8: FALSE | G8: paraphrase | H8: 3
B9: that anyone can do anything | C9: FALSE | D9: FALSE | E9: TRUE | F9: FALSE | G9: inference | H9: 3
B10: Iris is saying being a philosopher opens opportunities into other working fields. | C10: TRUE | D10: FALSE | E10: FALSE | F10: FALSE | G10: paraphrase | H10: 3
B11: Suggesting that Matt could do quite a few things as a profession | C11: FALSE | D11: TRUE | E11: FALSE | F11: FALSE | G11: discourse | H11: 3
B12: People with a philosophy degree should be able to use it to secure a wide array of jobs. | C12: TRUE | D12: FALSE | E12: FALSE | F12: FALSE | G12: paraphrase | H12: 3
B13: skills can be transferable | C13: FALSE | D13: FALSE | E13: TRUE | F13: FALSE | G13: inference | H13: 3
B14: that philosophers could do almost any sort of job | C14: TRUE | D14: FALSE | E14: FALSE | F14: FALSE | G14: paraphrase | H14: 3
B15: People who study philosophy could potentially work in any area they choose. | C15: TRUE | D15: FALSE | E15: FALSE | F15: FALSE | G15: paraphrase | H15: 3
B16: Philosophy is a thought provoking and academic subject that shows quality of thought IAnyone who studies that subject is therefore clever so could apply for a wide variety of jobs that may just need a little specific training. | C16: FALSE | D16: TRUE | E16: FALSE | F16: FALSE | G16: beyond dps | H16: 2
B17: That they can be anything, she is making a joke as philosiphers make theorys | C17: FALSE | D17: FALSE | E17: TRUE | F17: FALSE | G17: picked up on a joke that doesn't exist, love that a lot | H17: 3
B18: That a philosopher isnt just tied to philosophy they can enter other fields of work | C18: TRUE | D18: FALSE | E18: FALSE | F18: FALSE | G18: paraphrase | H18: 3
B19: Those who complete degrees in philosophy have the same work opportunities as those who complete other degrees | C19: TRUE | D19: FALSE | E19: FALSE | F19: FALSE | G19: paraphrase | H19: 3
... B26: Philosophers can go into any work area just like any other humanities subject | C26: TRUE | D26: FALSE | E26: FALSE | F26: FALSE | G26: paraphrase | H26: 3
B27: It suggested that, because in theory philosophers have the ablility to use critical thinking and reasoning, they should be well-equipped to adapt to any subject | C27: TRUE | D27: FALSE | E27: FALSE | F27: FALSE | G27: paraphrase | H27: 3 | J27: QUD | K27: Should philosophers be able to go into anything, like other graduates?
C34: =COUNTIF(C3:C32, TRUE) -> 15 | D34: =COUNTIF(D3:D32, TRUE) -> 5 | E34: =COUNTIF(E3:E32, TRUE) -> 4 | F34: =COUNTIF(F3:F32, TRUE) -> 0 | G34: =SUM(C34:F34) -> 24

Sheet summary 
A1: Column1 | B1: PAR | C1: SIT | D1: INF | E1: EVA
A2: s1 | B2: ='Einstein''s Theory'!C34 -> 12 | C2: ='Einstein''s Theory'!D34 -> 3 | D2: ='Einstein''s Theory'!E34 -> 9 | E2: ='Einstein''s Theory'!F34 -> 0
A3: d2 | B3: =Philosophy!C34 -> 3 | C3: =Philosophy!D34 -> 3 | D3: =Philosophy!E34 -> 10 | E3: =Philosophy!F34 -> 8
A4: d3 | B4: ='Conspiracy Theory'!C34 -> 12 | C4: ='Conspiracy Theory'!D34 -> 2 | D4: ='Conspiracy Theory'!E34 -> 5 | E4: ='Conspiracy Theory'!F34 -> 5
A5: d4 | B5: ='Ethernet cable'!C34 -> 11 | C5: ='Ethernet cable'!D34 -> 5 | D5: ='Ethernet cable'!E34 -> 5 | E5: ='Ethernet cable'!F34 -> 3
A6: d5 | B6: ='Work availability'!C34 -> 15 | C6: ='Work availability'!D34 -> 5 | D6: ='Work availability'!E34 -> 4 | E6: ='Work availability'!F34 -> 0
A9: Column1 | B9: PAR | C9: SIT | D9: INF | E9: EVA
A10: totals | B10: =SUM(Table6[PAR]) -> 53 | C10: =SUM(Table6[SIT]) -> 18 | D10: =SUM(Table6[INF]) -> 33 | E10: =SUM(Table6[EVA]) -> 16
A13: Column1 | B13: PAR | C13: SIT | D13: INF | E13: EVA | F13: total
A14: s1 | B14: =B2/Table69[[#This Row],[total]] -> 0.5 | C14: =C2/Table69[[#This Row],[total]] -> 0.125 | D14: =D2/Table69[[#This Row],[total]] -> 0.375 | E14: =E2/Table69[[#This Row],[total]] -> 0 | F14: =SUM(B2:E2) -> 24
A15: d2 | B15: =B3/Table69[[#This Row],[total]] -> 0.125 | C15: =C3/Table69[[#This Row],[total]] -> 0.125 | D15: =D3/Table69[[#This Row],[total]] -> 0.41666667 | E15: =E3/Table69[[#This Row],[total]] -> 0.33333333 | F15: =SUM(B3:E3) -> 24
A16: d3 | B16: =B4/Table69[[#This Row],[total]] -> 0.5 | C16: =C4/Table69[[#This Row],[total]] -> 0.083333333 | D16: =D4/Table69[[#This Row],[total]] -> 0.20833333 | E16: =E4/Table69[[#This Row],[total]] -> 0.20833333 | F16: =SUM(B4:E4) -> 24
A17: d4 | B17: =B5/Table69[[#This Row],[total]] -> 0.45833333 | C17: =C5/Table69[[#This Row],[total]] -> 0.20833333 | D17: =D5/Table69[[#This Row],[total]] -> 0.20833333 | E17: =E5/Table69[[#This Row],[total]] -> 0.125 | F17: =SUM(B5:E5) -> 24
A18: d5 | B18: =B6/Table69[[#This Row],[total]] -> 0.625 | C18: =C6/Table69[[#This Row],[total]] -> 0.20833333 | D18: =D6/Table69[[#This Row],[total]] -> 0.16666667 | E18: =E6/Table69[[#This Row],[total]] -> 0 | F18: =SUM(B6:E6) -> 24
