Workbook

Sheet Sheet0
A1: Q4 | B1: Q5 | C1: Q15 | D1: QID71 | E1: QID61 | F1: QID51 | G1: QID42 | H1: QID33
A2: What is your age? | B2: What is your highest level of education? | C2: Please select the domain that best describes your current occupation: | D2: Maisy, Brad and Rececca are discussing Maisy's recent holiday: Maisy: There's so many people trying to sell you stuff. Brad: Mm. Maisy: Fob you off and overcharge you. Brad: Oh, a selfie stick to sell you? Rebecca: Not take a photo of you? Maisy: No, to sell you. Brad: Oh right. Maisy: And you, if you eat by the water. Brad: Mm. Maisy: The price of eating by the water is insane compared to like the little— Rebecca: Backstreets. Maisy: —Pizza places in the backstreets you could get some really good food. Brad: Right. What do you think is conveyed by Maisy in the underlined text? | E2: Harry, Jose, and Susie are discussing cooking: Harry: You shouldn't salt beef. Jose: What do you mean, you should salt beef? Harry: Before you cook it because all the water - all the juices leech out of it. Jose: You salt and pepper, don't you? Susie: Apparently, yeah, like joints of beef and stuff like that. Harry: Any beef I've been told. Susie: Yeah, but any dish you salt... Jose: Like er shoulder, if you like salt a shoulder before you put it in the oven. Harry: That's different, but if you're say frying pieces of beef or stir-fried beef or something, you shouldn't salt it. Jose: I wouldn't salt a steak before frying it because it makes it dry, doesn't it? Harry: Yeah, because it draws out all the water. Susie: I don't salt my steaks, no. What do you think is conveyed by Harry in the underlined text? | F2: Rebecca and Katherine are discussing restaurants: Rebecca: So there's no overheads for the food and they're not paying any staff fee, so if they're paying five pounds for that meal that's actual pure profit. Unlike a real restaurant, where probably the biggest expense is wages, and then the food itself. So that could actually be subsidising the other café where people can't afford to pay as much. Katherine: True, but don't they have to rent premises to do this? Rebecca: Mm yeah. Katherine: Oh I mean that's massive. Rebecca: So they do have that overhead. Katherine: Yeah, that's a massive expense. Rebecca: Plus the electricity and water. Katherine: Mm, and there's no guaranteed levels of income here, you know. What do you think is conveyed by Rebecca in the underlined text? | G2: Annemarie and Charles are discussing health: Annemarie: Yeah, the thing is, what you've got to do on a plane is to look after your body. That's the most important thing you've got to do. Charles: Yeah, yeah, yeah. Annemarie: And the only way you can do that is to drink as much water as possible. Charles: Yeah. Annemarie: Not too much water but- Charles: No, no, no. Annemarie: Just keep yourself hydrated. Flying at that altitude and drinking alcohol is like a kamikaze wish for me. What do you think is conveyed by Annemarie in the underlined text? | H2: Alecia, Phil, and Ida are discussing each others' homes: Alecia: Do you keep water in the fridge? Phil: No. Ida: No. Alecia: Oh, you don't? Phil: It's cold enough out the tap. Ida: It's nice just being able to drink it out the tap. Water does taste different in different places though, doesn't it? Alecia: Yeah, definitely. Ida: It's different here to back at my mum's. Alecia: It's even different, er, in different parts of England. Phil: Yeah, that's what I mean. What do you think is conveyed by Ida in the underlined text?
A3: 45 - 54 | B3: Master’s Degree (e.g. MA. MSc) | C3: Sales and Marketing
A4: 25 - 34 | B4: GCSE/O-level | C4: Finance and Banking | D4: Inflation is going up, eating with a view is expensive.
A5: 35 - 44 | B5: Bachelors Degree (e.g BA, BSc) | C5: Unemployed
A6: 35 - 44 | B6: Vocational Qualifications (e.g. NVQs, BTEC) | C6: Information Technology and Software Development
A7: 55 - 64 | B7: Higher National Certificate/higher National Diploma | C7: Information Technology and Software Development
A8: 25 - 34 | B8: Bachelors Degree (e.g BA, BSc) | C8: Engineering and Manufacturing | H8: Ida is saying the tap water here tastes different from the water at her mum’s house.
A9: 25 - 34 | B9: Bachelors Degree (e.g BA, BSc) | C9: Nonprofit and Social Services | G9: Bossy
A10: 55 - 64 | B10: Master’s Degree (e.g. MA. MSc) | C10: Engineering and Manufacturing | E10: Salting beef draws liwu8d from tue meat when its being cooked
A11: 35 - 44 | B11: A-levels/Highers | C11: Nonprofit and Social Services
A12: 55 - 64 | B12: A-levels/Highers | C12: Retired | H12: Ida is suggesting that she thinks that water tastes different in different homes, areas, places etc. the coldness may also alter the taste
A13: 55 - 64 | B13: Bachelors Degree (e.g BA, BSc) | C13: Retired
A14: 35 - 44 | B14: Bachelors Degree (e.g BA, BSc) | C14: Retail and Customer Service | D14: Holiday was in a rip off place.
A15: 35 - 44 | B15: Vocational Qualifications (e.g. NVQs, BTEC) | C15: Law and Legal Services | E15: That using salt before cooking will dry out the meat
A16: 25 - 34 | B16: Bachelors Degree (e.g BA, BSc) | C16: Education and Training
A17: 35 - 44 | B17: GCSE/O-level | C17: Unemployed | F17: She is adding on to the discussion about the other bills they have to pay at the restaurant
A18: 35 - 44 | B18: Bachelors Degree (e.g BA, BSc) | C18: Healthcare and Medicine
A19: 25 - 34 | B19: Master’s Degree (e.g. MA. MSc) | C19: Consulting and Business Services | D19: The expense of tourism
A20: 25 - 34 | B20: Master’s Degree (e.g. MA. MSc) | C20: Government and Public Administration
A21: 35 - 44 | B21: Bachelors Degree (e.g BA, BSc) | C21: Government and Public Administration
A22: 35 - 44 | B22: Vocational Qualifications (e.g. NVQs, BTEC) | C22: Law and Legal Services
A23: 25 - 34 | B23: Bachelors Degree (e.g BA, BSc) | C23: Education and Training | H23: That water can be different and taste different, depending on where it's from and temperature.
A24: 25 - 34 | B24: Bachelors Degree (e.g BA, BSc) | C24: Finance and Banking | D24: That it costs a lot more money to eat with a view of the water than it does if you eat elsewhere
A25: 35 - 44 | B25: A-levels/Highers | C25: Unemployed
A26: 25 - 34 | B26: Bachelors Degree (e.g BA, BSc) | C26: Education and Training
A27: 55 - 64 | B27: Bachelors Degree (e.g BA, BSc) | C27: Education and Training
A28: 35 - 44 | B28: A-levels/Highers | C28: Unemployed
A29: 25 - 34 | B29: Bachelors Degree (e.g BA, BSc) | C29: Education and Training | H29: She can taste water differently in other places
A30: 25 - 34 | B30: Vocational Qualifications (e.g. NVQs, BTEC) | C30: Healthcare and Medicine | H30: Water tastes different i. Different places
A31: 35 - 44 | B31: Bachelors Degree (e.g BA, BSc) | C31: Arts and Humanities | G31: to stay hydrated when flying in a plane
A32: 25 - 34 | B32: Vocational Qualifications (e.g. NVQs, BTEC) | C32: Information Technology and Software Development | D32: getting food near a river or lake is more expensive than other locations
A33: 25 - 34 | B33: Bachelors Degree (e.g BA, BSc) | C33: Education and Training | F33: That there are underlying costs such as electricity and water
A34: 25 - 34 | B34: GCSE/O-level | C34: Construction and Skilled Trades
A35: 35 - 44 | B35: Bachelors Degree (e.g BA, BSc) | C35: Unemployed
A36: 35 - 44 | B36: Bachelors Degree (e.g BA, BSc) | C36: Education and Training | E36: The salt draws out all of the water from a piece of beef before you cook it
A37: 25 - 34 | B37: Vocational Qualifications (e.g. NVQs, BTEC) | C37: Retail and Customer Service
A38: 35 - 44 | B38: Master’s Degree (e.g. MA. MSc) | C38: Nonprofit and Social Services | H38: Water tastes differently in difference towns / cities
A39: 25 - 34 | B39: Bachelors Degree (e.g BA, BSc) | C39: Law and Legal Services
A40: 65 - 74 | B40: GCSE/O-level | C40: Transportation and Logistics
...

Sheet the price of eating by the...
B1: QID71 | G1: COMMENT | H1: CERTAINTY
A2: Excluded? | B2: "The price of eating by the water is insane " | C2: PAR | D2: SIT | E2: INF | F2: EVA
B3: Inflation is going up, eating with a view is expensive. | C3: FALSE | D3: FALSE | E3: TRUE | F3: FALSE | G3: inflation is inference | H3: 3
B4: Holiday was in a rip off place. | C4: FALSE | D4: FALSE | E4: TRUE | F4: FALSE | G4: inference | H4: 3 | I4: Maisy, Brad and Rececca are discussing Maisy's recent holiday: Maisy: There's so many people trying to sell you stuff. Brad: Mm. Maisy: Fob you off and overcharge you. Brad: Oh, a selfie stick to sell you? Rebecca: Not take a photo of you? Maisy: No, to sell you. Brad: Oh right. Maisy: And you, if you eat by the water. Brad: Mm. Maisy: The price of eating by the water is insane compared to like the little— Rebecca: Backstreets. Maisy: —Pizza places in the backstreets you could get some really good food. Brad: Right. What do you think is conveyed by Maisy in the underlined text?
B5: The expense of tourism | C5: FALSE | D5: TRUE | E5: FALSE | F5: FALSE | G5: broader discourse inference | H5: 2
B6: That it costs a lot more money to eat with a view of the water than it does if you eat elsewhere | C6: TRUE | D6: FALSE | E6: FALSE | F6: FALSE | G6: paraphrase | H6: 3
B7: getting food near a river or lake is more expensive than other locations | C7: TRUE | D7: FALSE | E7: FALSE | F7: FALSE | G7: paraphrase | H7: 3
A8: X | B8: The price of the water | C8: FALSE | D8: FALSE | E8: FALSE | F8: FALSE | H8: 2
A9: X | B9: that you are charged a high price to sit and eat near a beauty spot next to water they extort the placement fo teh resturante | C9: dps | D9: FALSE | E9: FALSE | F9: FALSE | G9: paraphrase | H9: 3
B10: Popular eateries in specific locations charge more | C10: FALSE | D10: TRUE | E10: FALSE | F10: FALSE | G10: broader inference | H10: 2
B11: Eating in restaurants near the water is more expensive than those on the streets | C11: TRUE | D11: FALSE | E11: FALSE | F11: FALSE | G11: paraphrase | H11: 3
B12: that a certain area is very expensive | C12: FALSE | D12: TRUE | E12: FALSE | F12: FALSE | G12: broader inference | H12: 2
A13: X | B13: Prices | C13: FALSE | D13: FALSE | E13: FALSE | F13: FALSE
B14: That the increased prices when on holiday and in a tourist area are more expensive due to the scenery. | C14: TRUE | D14: FALSE | E14: FALSE | F14: FALSE | G14: paraphrase | H14: 2
B15: it costs more money to eat near the water | C15: TRUE | D15: FALSE | E15: FALSE | F15: FALSE | G15: paraphrase | H15: 2
B16: Maisy is stressing the high cost of eating by the water. She is using the word insane to emphasise how expensive it is | C16: TRUE | D16: FALSE | E16: FALSE | F16: FALSE | G16: paraphrase | H16: 3
B17: Eating by the water on holiday was expensive | C17: TRUE | D17: FALSE | E17: FALSE | F17: FALSE | G17: paraphrase | H17: 3
B18: It’s expensive to eat on the water front on holiday due to the view. | C18: FALSE | D18: TRUE | E18: FALSE | F18: FALSE | G18: due to view is inference | H18: 2
B19: That the cost of living is insane and people are trying yheir hardest to make as much money as possible | C19: FALSE | D19: FALSE | E19: TRUE | F19: FALSE | G19: inference | H19: 3
B20: the price is a lot more when you eat by the water | C20: TRUE | D20: FALSE | E20: FALSE | F20: FALSE | G20: paraphrase | H20: 3
B21: Maisy is saying that eating by the water, in one of the near by restaurants, is really expensive. | C21: TRUE | D21: FALSE | E21: FALSE | F21: FALSE | G21: paraphrase | H21: 3
B22: how expensive it is to purchase food close to the water | C22: TRUE | D22: FALSE | E22: FALSE | F22: FALSE | G22: paraphrase | H22: 3
B23: How overpriced certain areas of a town/city are because of their location. | C23: TRUE | D23: FALSE | E23: FALSE | F23: FALSE | G23: paraphrase | H23: 3
B24: That in a good location, services cost more. | C24: FALSE | D24: FALSE | E24: TRUE | F24: FALSE | G24: inference | H24: 3
B25: She is highlighting this sentence as she feels strongly about this | C25: FALSE | D25: FALSE | E25: FALSE | F25: TRUE | G25: inference | H25: 3
... B29: That the prices in restaurants located by the water, i.e. by the river or the sea, are very high | C29: TRUE | D29: FALSE | E29: FALSE | F29: FALSE | G29: paraphrase | H29: 3
I31: QUD: | J31: "What was the experience like on Maisy's holiday?"
C34: =COUNTIF(C2:C32, TRUE) -> 13 | D34: =COUNTIF(D2:D32, TRUE) -> 6 | E34: =COUNTIF(E2:E32, TRUE) -> 4 | F34: =COUNTIF(F2:F32, TRUE) -> 1 | G34: =SUM(C34:F34) -> 24

Sheet Salt draws water from....
B1: QID61 | G1: COMMENT | H1: CERTAINTY
A2: Excluded? | B2: it draws out all the water | C2: PAR | D2: SIT | E2: INF | F2: EVA
B3: Salting beef draws liwu8d from tue meat when its being cooked | C3: TRUE | D3: FALSE | E3: FALSE | F3: FALSE | G3: paraphrase | H3: 3 | J3: Harry, Jose, and Susie are discussing cooking: Harry: You shouldn't salt beef. Jose: What do you mean, you should salt beef? Harry: Before you cook it because all the water - all the juices leech out of it. Jose: You salt and pepper, don't you? Susie: Apparently, yeah, like joints of beef and stuff like that. Harry: Any beef I've been told. Susie: Yeah, but any dish you salt... Jose: Like er shoulder, if you like salt a shoulder before you put it in the oven. Harry: That's different, but if you're say frying pieces of beef or stir-fried beef or something, you shouldn't salt it. Jose: I wouldn't salt a steak before frying it because it makes it dry, doesn't it? Harry: Yeah, because it draws out all the water. Susie: I don't salt my steaks, no. What do you think is conveyed by Harry in the underlined text?
B4: That using salt before cooking will dry out the meat | C4: TRUE | D4: FALSE | E4: FALSE | F4: FALSE | G4: paraphrase | H4: 3
B5: The salt draws out all of the water from a piece of beef before you cook it | C5: TRUE | D5: FALSE | E5: FALSE | F5: FALSE | G5: paraphrase | H5: 3
B6: Salt dehydrates beef | C6: TRUE | D6: FALSE | E6: FALSE | F6: FALSE | G6: paraphrase | H6: 3
B7: explaining why the steak goes dry | C7: TRUE | D7: FALSE | E7: FALSE | F7: FALSE | G7: paraphrase | H7: 3
A8: X | B8: salt draws out water | C8: dps | D8: FALSE | E8: FALSE | F8: FALSE | G8: paraphrase | H8: 3
B9: They are confiming pointing out that the salt dries out the steak | C9: TRUE | D9: FALSE | E9: FALSE | F9: FALSE | G9: paraphrase | H9: 3
B10: He knows how to cook | C10: FALSE | D10: FALSE | E10: TRUE | F10: FALSE | G10: inference | H10: 3
B11: Drawing out the water in a steak makes it worse as a meal. | C11: FALSE | D11: FALSE | E11: TRUE | F11: FALSE | G11: inference | H11: 3
B12: the steak will be spoilt if salt is added | C12: FALSE | D12: FALSE | E12: TRUE | F12: FALSE | G12: inference | H12: 3
B13: Steak shouldnt be salted as it will make it dry | C13: TRUE | D13: FALSE | E13: FALSE | F13: FALSE | G13: paraphrase | H13: 3
B14: That salting beef before cooking draws the flavour out of the meat | C14: FALSE | D14: FALSE | E14: TRUE | F14: FALSE | G14: flavour is an implication | H14: 2
B15: You shouldn’t salt the meat because it makes it dry | C15: TRUE | D15: FALSE | E15: FALSE | F15: FALSE | G15: paraphrase | H15: 3
B16: Salt spoils the steak | C16: FALSE | D16: FALSE | E16: TRUE | F16: FALSE | G16: spoiling is an inference | H16: 2
B17: the disadvanteges of salting beef before cooking (what is conveyed is wrong!!) | C17: TRUE | D17: FALSE | E17: FALSE | F17: FALSE | G17: paraphrase | H17: 3
B18: Salt makes food dry by removing all the fluid contents | C18: TRUE | D18: FALSE | E18: FALSE | F18: FALSE | G18: paraphrase | H18: 3
A19: X | B19: Same as all the juices leeching out of it above | C19: dps | D19: FALSE | E19: FALSE | F19: FALSE | G19: paraphrase | H19: 3
B20: Salting food before cooking reduces the water content of the food being cooked. | C20: TRUE | D20: FALSE | E20: FALSE | F20: FALSE | G20: paraphrase | H20: 3
B21: quite literally, it draws out the water. | C21: TRUE | D21: FALSE | E21: FALSE | F21: FALSE | G21: paraphrase | H21: 3
B22: That you shouldn't salt beef when cooking it as it draws out the moisture and makes the meat dry. | C22: TRUE | D22: FALSE | E22: FALSE | F22: FALSE | G22: paraphrase | H22: 3
B23: That salt takes all the water out which is why the steak becomes dry | C23: TRUE | D23: FALSE | E23: FALSE | F23: FALSE | G23: paraphrase | H23: 3
B24: Harry is conveying that salt draws water out of steak. | C24: TRUE | D24: FALSE | E24: FALSE | F24: FALSE | G24: paraphrase | H24: 3
A25: X | B25: Seasoning beef before cooking. | C25: FALSE | D25: FALSE | E25: FALSE | F25: FALSE
B26: Harry is trying to explain why you shouldn't salt certain types of beef before you cook it and is telling Josie the reason why it makes the steak dry as it draws out all the water and juices from the meat making it dry. | C26: TRUE | D26: FALSE | E26: FALSE | F26: FALSE | G26: paraphrase | H26: 3
B27: Harry is trying to tell the reason why Jose or Jose or Susie or anyone in general shouldn't salt meat because if you do so, it will drain all the water from the meat and it may not taste and cook well if all salt/taste has gone from the meat. | C27: FALSE | D27: FALSE | E27: TRUE | F27: FALSE | G27: taste is inference | H27: 3 | J27: QUD | K27: Should you salt beef before cooking it?
B28: Frustration because he's having to repeat himself and explain | C28: FALSE | D28: FALSE | E28: FALSE | F28: TRUE | G28: asribing emotions definitely | H28: 3
B29: That salting steak draws out all of the water | C29: TRUE | D29: FALSE | E29: FALSE | F29: FALSE | H29: 3
C34: =COUNTIF(C3:C32, TRUE) -> 17 | D34: =COUNTIF(D3:D32, TRUE) -> 0 | E34: =COUNTIF(E3:E32, TRUE) -> 6 | F34: =COUNTIF(F3:F32, TRUE) -> 1 | G34: =SUM(C34:F34) -> 24

Sheet Restuarant overheads 
B1: QID51 | G1: comment | H1: certainty
A2: Excluded? | B2: Plus the electricity and water | C2: PAR | D2: SIT | E2: INF | F2: EVA | J2: Rebecca and Katherine are discussing restaurants: Rebecca: So there's no overheads for the food and they're not paying any staff fee, so if they're paying five pounds for that meal that's actual pure profit. Unlike a real restaurant, where probably the biggest expense is wages, and then the food itself. So that could actually be subsidising the other café where people can't afford to pay as much. Katherine: True, but don't they have to rent premises to do this? Rebecca: Mm yeah. Katherine: Oh I mean that's massive. Rebecca: So they do have that overhead. Katherine: Yeah, that's a massive expense. Rebecca: Plus the electricity and water. Katherine: Mm, and there's no guaranteed levels of income here, you know. What do you think is conveyed by Rebecca in the underlined text?
B3: She is adding on to the discussion about the other bills they have to pay at the restaurant | C3: TRUE | D3: FALSE | E3: FALSE | F3: FALSE | G3: paraphrase | H3: 3
A4: X | B4: That there are underlying costs such as electricity and water | C4: dps | D4: FALSE | E4: FALSE | F4: FALSE | G4: paraphrase | H4: 3
B5: even more expense | C5: TRUE | D5: FALSE | E5: FALSE | F5: FALSE | G5: paraphrase | H5: 2
B6: she is clarifying the overall expenses of running a business. | C6: TRUE | D6: FALSE | E6: FALSE | F6: FALSE | G6: paraphrase | H6: 2
A7: X | B7: Saying that there's extra cost | C7: dps | D7: FALSE | E7: FALSE | F7: FALSE | G7: paraphrase | H7: 2
B8: The cost of electricity and water that will be incurred by running a restaurant. | C8: TRUE | D8: FALSE | E8: FALSE | F8: FALSE | G8: paraphrase | H8: 3
B9: Rebecca conveys an acknowledgment that running a restaurant involves additional operating costs beyond rent. She adds to Katherine's point about overhead expenses by mentioning utilities, highlighting her understanding of the various factors that contribute to a restaurant's financial burden. This suggests Rebecca's effort to present a more comprehensive view of the expenses involved. | C9: FALSE | D9: TRUE | E9: FALSE | F9: FALSE | G9: more general than dps | H9: 2
B10: The price of everything these days | C10: FALSE | D10: FALSE | E10: TRUE | F10: FALSE | G10: inference | H10: 3
B11: shes saying electricity and water are an additional expense | C11: TRUE | D11: FALSE | E11: FALSE | F11: FALSE | G11: paraphrase | H11: 3
B12: That electricity and water is another expense | C12: TRUE | D12: FALSE | E12: FALSE | F12: FALSE | G12: paraphrase | H12: 3
A13: X | B13: There will be electricity and water costs to pay | C13: dps | D13: FALSE | E13: FALSE | F13: FALSE | G13: paraphrase | H13: 3
B14: The cost of running a restaurant | C14: FALSE | D14: TRUE | E14: FALSE | F14: FALSE | G14: more general than dps | H14: 2
B15: th extra added costs they would have to accommodate | C15: TRUE | D15: FALSE | E15: FALSE | F15: FALSE | G15: paraphrase | H15: 2
B16: The restaurant has to pay for the electricity and water they use | C16: TRUE | D16: FALSE | E16: FALSE | F16: FALSE | G16: paraphrase | H16: 3
B17: that water and elecrticity are expensive to run | C17: FALSE | D17: FALSE | E17: TRUE | F17: FALSE | G17: inference, never said it was expensive | H17: 2
A18: X | B18: She is emphasizing that restaurants that are not real ones like online ones have very low overheads and bills | C18: FALSE | D18: FALSE | E18: inf | F18: FALSE | G18: inference | H18: 3
B19: the electricity and water are a major expense for a cafe | C19: FALSE | D19: FALSE | E19: TRUE | F19: FALSE | G19: major expense is an inference | H19: 2
B20: That restaurants have utility bills to pay such as electricity and water. | C20: TRUE | D20: FALSE | E20: FALSE | F20: FALSE | G20: paraphrase | H20: 3
B21: A disbelief in what Katherine is saying and that Katherine has misunderstood | C21: FALSE | D21: FALSE | E21: FALSE | F21: TRUE | G21: EVA | H21: 2
B22: there are extra costs | C22: TRUE | D22: FALSE | E22: FALSE | F22: FALSE | G22: paraphrase | H22: 2
B23: That there is additional expenses | C23: TRUE | D23: FALSE | E23: FALSE | F23: FALSE | G23: paraphrase | H23: 2
B24: She talks about there being no overheads for a restaurant, such as staff and bills. | C24: FALSE | D24: TRUE | E24: FALSE | F24: FALSE | G24: more general than dps | H24: 2
B25: That electric and water bills are very expensive and mean that the business running in that place needs to be able to foot this bill | C25: FALSE | D25: FALSE | E25: TRUE | F25: FALSE | G25: being very expensive is an inference | H25: 3
B26: she has understood that there are costs incolved for the restaurants rather than what she previously thought | C26: FALSE | D26: TRUE | E26: FALSE | F26: FALSE | G26: more general than dps | H26: 2
A27: X | B27: There are more expenses than Katherine realises | C27: FALSE | D27: sit | E27: FALSE | F27: FALSE | G27: more general than dps | H27: 2
B28: Implying the cost of electricity and water is a large overhead | C28: FALSE | D28: FALSE | E28: TRUE | F28: FALSE | G28: implication | H28: 3
B29: That she had possibly changed her mind and that she is considering katherines view point and her example, leading on from what she said, thinking of another expenditure. | C29: FALSE | D29: FALSE | E29: TRUE | F29: FALSE | G29: inference | H29: 3
B30: The expenses that Cafes and restaurants have to pay before any profit is made. | C30: TRUE | D30: FALSE | E30: FALSE | F30: FALSE | G30: paraphrase | H30: 3
B31: the discussion of bills and the added cost of electricity and water to a restaurant | C31: TRUE | D31: FALSE | E31: FALSE | F31: FALSE | G31: paraphrase | H31: 3
C34: =COUNTIF(C3:C32, TRUE) -> 13 | D34: =COUNTIF(D3:D32, TRUE) -> 4 | E34: =COUNTIF(E3:E32, TRUE) -> 6 | F34: =COUNTIF(F3:F32, TRUE) -> 1 | G34: =SUM(C34:F34) -> 24
J36: QUD | K36: What are the expenses involved in running a café/restaurant?"

Sheet Drink on the plane
B1: QID42 | G1: comment | H1: certainty
A2: Excluded? | B2: drink as much water as possible. | C2: PAR | D2: SIT | E2: INF | F2: EVA | J2: Annemarie and Charles are discussing health: Annemarie: Yeah, the thing is, what you've got to do on a plane is to look after your body. That's the most important thing you've got to do. Charles: Yeah, yeah, yeah. Annemarie: And the only way you can do that is to drink as much water as possible. Charles: Yeah. Annemarie: Not too much water but- Charles: No, no, no. Annemarie: Just keep yourself hydrated. Flying at that altitude and drinking alcohol is like a kamikaze wish for me. What do you think is conveyed by Annemarie in the underlined text?
B3: Bossy | C3: FALSE | D3: FALSE | E3: FALSE | F3: TRUE | G3: evaluation | H3: 3
B4: to stay hydrated when flying in a plane | C4: TRUE | D4: FALSE | E4: FALSE | F4: FALSE | G4: paraphrase | H4: 3
A5: X | B5: to drink enough water | C5: dps | D5: FALSE | E5: FALSE | F5: FALSE | G5: paraphrase | H5: 3
B6: Clear advice to keep hydrated on a plane | C6: TRUE | D6: FALSE | E6: FALSE | F6: FALSE | G6: paraphrase | H6: 3
B7: To have a comfortable flight you should drink a lot of water during the flight | C7: TRUE | D7: FALSE | E7: FALSE | F7: FALSE | G7: paraphrase | H7: 3
B8: Drink lots of water to keep yourself healthy | C8: TRUE | D8: FALSE | E8: FALSE | F8: FALSE | G8: paraphrase | H8: 3
B9: Annemarie is suggesting to hydrate well by drinking a lot of water. It seems like she is emphasising the importance of staying hydrated. | C9: TRUE | D9: FALSE | E9: FALSE | F9: FALSE | G9: paraphrase | H9: 3
B10: To hydrate oneself | C10: TRUE | D10: FALSE | E10: FALSE | F10: FALSE | G10: paraphrase | H10: 3
B11: She is emphasising just how much water you should drink during a flight | C11: TRUE | D11: FALSE | E11: FALSE | F11: FALSE | G11: paraphrase | H11: 3
B12: Keep hydrated and not drink alcohol | C12: FALSE | D12: TRUE | E12: FALSE | F12: FALSE | G12: alcohol is from an implicature | H12: 2
B13: That flying is bad for your body and drinking lots of water helps balance this. | C13: FALSE | D13: FALSE | E13: TRUE | F13: FALSE | G13: flying bad is an implicature | H13: 2
B14: that drinking water is healthy | C14: FALSE | D14: FALSE | E14: TRUE | F14: FALSE | G14: healthy is an implicature | H14: 2
B15: Keep drinking water to stay hydrated. | C15: TRUE | D15: FALSE | E15: FALSE | F15: FALSE | G15: paraphrase | H15: 2
B16: This one feels more self explanatory. Annemarie is just saying it’s important to stay hydrated so you should drink as much water as you can to stay hydrated. | C16: TRUE | D16: FALSE | E16: FALSE | F16: FALSE | G16: paraphrase | H16: 3
B17: Drinking water prior and after flying prevents dehydration | C17: FALSE | D17: TRUE | E17: FALSE | F17: FALSE | G17: prior to and after is inferred | H17: 2
... B21: She is encouraging her friend to drink plenty of water on a plane to ensure she stays hydrated | C21: TRUE | D21: FALSE | E21: FALSE | F21: FALSE | G21: perephrese | H21: 3
A22: X | B22: that staying hydrated is healthy especially during flights | C22: dps | D22: FALSE | E22: FALSE | F22: FALSE | G22: paraphrase | H22: 3
B23: Annemarie is conveying her care for Charles by telling him he needs to drink water and keep himself hydrated. | C23: FALSE | D23: FALSE | E23: FALSE | F23: TRUE | G23: care for charles | H23: 3
B24: The solution to looking after your body on the plane is to drink as much water as possible. This is the most important factor. | C24: TRUE | D24: FALSE | E24: FALSE | F24: FALSE | G24: paraphrase | H24: 3 | J24: QUD | K24: How should you take care of your body while flying?
B25: To drink the amount of water comfortable enough for you to drink but also how much is made available | C25: FALSE | D25: TRUE | E25: FALSE | F25: FALSE | G25: much is available is an inference | H25: 2
B26: keeping hydrated on a flight | C26: TRUE | D26: FALSE | E26: FALSE | F26: FALSE | G26: paraphrase | H26: 3
B27: that you need to keep yourself hydrated to make sure you feel good while flying | C27: TRUE | D27: FALSE | E27: FALSE | F27: FALSE | G27: paraphrase | H27: 3
B28: To drink water at every opportunity assuming no negative repercussions | C28: FALSE | D28: TRUE | E28: FALSE | F28: FALSE | G28: no negative is implied | H28: 2
C34: =COUNTIF(C3:C32, TRUE) -> 16 | D34: =COUNTIF(D3:D32, TRUE) -> 4 | E34: =COUNTIF(E3:E32, TRUE) -> 2 | F34: =COUNTIF(F3:F32, TRUE) -> 2 | G34: =SUM(C34:F34) -> 24

Sheet Tap water tastes different...
B1: QID33 | G1: comment | H1: certainty
A2: Excluded? | B2: Water does taste different in different places though | C2: PAR | D2: SIT | E2: INF | F2: EVA | J2: Alecia, Phil, and Ida are discussing each others' homes: Alecia: Do you keep water in the fridge? Phil: No. Ida: No. Alecia: Oh, you don't? Phil: It's cold enough out the tap. Ida: It's nice just being able to drink it out the tap. Water does taste different in different places though, doesn't it? Alecia: Yeah, definitely. Ida: It's different here to back at my mum's. Alecia: It's even different, er, in different parts of England. Phil: Yeah, that's what I mean. What do you think is conveyed by Ida in the underlined text?
B3: Ida is saying the tap water here tastes different from the water at her mum’s house. | C3: TRUE | D3: FALSE | E3: FALSE | F3: FALSE | G3: paraphrase | H3: 3
B4: Ida is suggesting that she thinks that water tastes different in different homes, areas, places etc. the coldness may also alter the taste | C4: FALSE | D4: FALSE | E4: TRUE | F4: FALSE | G4: coldness inferred | H4: 2
B5: That water can be different and taste different, depending on where it's from and temperature. | C5: FALSE | D5: TRUE | E5: FALSE | F5: FALSE | G5: temperature is broader discourse | H5: 2
B6: She can taste water differently in other places | C6: TRUE | D6: FALSE | E6: FALSE | F6: FALSE | G6: paraphrase | H6: 3
B7: Water tastes different i. Different places | C7: TRUE | D7: FALSE | E7: FALSE | F7: FALSE | G7: paraphrase | H7: 3
B8: Water tastes differently in difference towns / cities | C8: TRUE | D8: FALSE | E8: FALSE | F8: FALSE | G8: paraphrase | H8: 3
B9: It doesn't matter where you store your water, it's going to taste different. | C9: TRUE | D9: FALSE | E9: FALSE | F9: FALSE | G9: paraphrase | H9: 3
B10: water from different regions tastes different | C10: TRUE | D10: FALSE | E10: FALSE | F10: FALSE | G10: paraphrase | H10: 3
B11: Water tastes differently depending on region | C11: TRUE | D11: FALSE | E11: FALSE | F11: FALSE | G11: paraphrase | H11: 3
A12: X | B12: Yo but bottled water | C12: FALSE | D12: FALSE | E12: FALSE | F12: FALSE
A13: X | B13: She is confirming what she believes she already knows | C13: FALSE | D13: FALSE | E13: FALSE | F13: FALSE
B14: water in different parts of the world, and in england tastes different due to different minerals in the water | C14: FALSE | D14: FALSE | E14: TRUE | F14: FALSE | G14: minerals is inferred | H14: 3
B15: Water in England tastes different based on water supply | C15: FALSE | D15: TRUE | E15: FALSE | F15: FALSE | G15: based on supply | H15: 2
B16: That water tastes different in other places. | C16: TRUE | D16: FALSE | E16: FALSE | F16: FALSE | G16: paraphrase | H16: 3
B17: that water out of the tap tastes differently from different places. likr scotland and england | C17: TRUE | D17: FALSE | E17: FALSE | F17: FALSE | G17: paraphrase | H17: 3
B18: She realises that water is different in lots of different situations, but without favouring one type of water over another. | C18: FALSE | D18: FALSE | E18: TRUE | F18: FALSE | G18: not fabouring one over other is inference | H18: 3
B19: The water tastes different in other geographical regions. | C19: TRUE | D19: FALSE | E19: FALSE | F19: FALSE | G19: paraphrase | H19: 3
B20: The water has a different taste in different regions | C20: TRUE | D20: FALSE | E20: FALSE | F20: FALSE | G20: paraphrase | H20: 3
B21: That water tastes different in different places. | C21: TRUE | D21: FALSE | E21: FALSE | F21: FALSE | G21: paraphrase | H21: 3
B22: The difference in the taste in different parts of the country. | C22: TRUE | D22: FALSE | E22: FALSE | F22: FALSE | G22: paraphrase | H22: 3
B23: Ida is conveying that water is possibly of a different quality depending on where you live and will taste better in some regions. | C23: FALSE | D23: FALSE | E23: TRUE | F23: FALSE | G23: quality is inferred | H23: 3
B24: Sort of trying to placate Alecia into not thinking she's the odd one out | C24: FALSE | D24: FALSE | E24: TRUE | F24: FALSE | G24: inference | H24: 2 | J24: QUD | K24: What are your preferences or habits around drinking water?
B25: water tastes different in different places | C25: TRUE | D25: FALSE | E25: FALSE | F25: FALSE | G25: paraphrase | H25: 3
B26: Ida is expressing her opinion about how water tastes differently in different parts of the country. This could be the way different water companies treat the water and also the level of water quality. | C26: FALSE | D26: FALSE | E26: TRUE | F26: FALSE | G26: hypothesises about why | H26: 2
B27: Ida is suggesting that water taste differently depending where it comes from. | C27: TRUE | D27: FALSE | E27: FALSE | F27: FALSE | G27: paraphrase | H27: 3
B28: That water tastes different from different parts of the world or country. | C28: TRUE | D28: FALSE | E28: FALSE | F28: FALSE | G28: paraphrase | H28: 3
C34: =COUNTIF(C3:C32, TRUE) -> 16 | D34: =COUNTIF(D3:D32, TRUE) -> 2 | E34: =COUNTIF(E3:E32, TRUE) -> 6 | F34: =COUNTIF(F3:F32, TRUE) -> 0 | G34: =SUM(C34:F34) -> 24

Sheet Summary 
A1: Dialogue | B1: PAR | C1: SIT | D1: INF | E1: EVA | F1: total
A2: D1 | B2: ='the price of eating by the...'!C34 -> 13 | C2: ='the price of eating by the...'!D34 -> 6 | D2: ='the price of eating by the...'!E34 -> 4 | E2: ='the price of eating by the...'!F34 -> 1 | F2: =SUM(Table8[[#This Row],[PAR]:[EVA]]) -> 24
A3: D2 | B3: ='Salt draws water from....'!C34 -> 17 | C3: ='Salt draws water from....'!D34 -> 0 | D3: ='Salt draws water from....'!E34 -> 6 | E3: ='Salt draws water from....'!F34 -> 1 | F3: =SUM(Table8[[#This Row],[PAR]:[EVA]]) -> 24
A4: D3 | B4: ='Restuarant overheads '!C34 -> 13 | C4: ='Restuarant overheads '!D34 -> 4 | D4: ='Restuarant overheads '!E34 -> 6 | E4: ='Restuarant overheads '!F34 -> 1 | F4: =SUM(Table8[[#This Row],[PAR]:[EVA]]) -> 24
A5: D4 | B5: ='Drink on the plane'!C34 -> 16 | C5: ='Drink on the plane'!D34 -> 4 | D5: ='Drink on the plane'!E34 -> 2 | E5: ='Drink on the plane'!F34 -> 2 | F5: =SUM(Table8[[#This Row],[PAR]:[EVA]]) -> 24
A6: D5 | B6: ='Tap water tastes different...'!C34 -> 16 | C6: ='Tap water tastes different...'!D34 -> 2 | D6: ='Tap water tastes different...'!E34 -> 6 | E6: ='Tap water tastes different...'!F34 -> 0 | F6: =SUM(Table8[[#This Row],[PAR]:[EVA]]) -> 24
A12: Water | B12: PAR | C12: SIT | D12: INF | E12: EVA
A13: total | B13: =SUM(B2:B6) -> 75 | C13: =SUM(C2:C6) -> 16 | D13: =SUM(D2:D6) -> 24 | E13: =SUM(E2:E6) -> 5
A16: Dialogue | B16: PAR | C16: SIT | D16: INF | E16: EVA
A17: D1 | B17: =B2/F2 -> 0.54166667 | C17: =C2/F2 -> 0.25 | D17: =D2/F2 -> 0.16666667 | E17: =E2/F2 -> 0.041666667
A18: D2 | B18: =B3/F3 -> 0.70833333 | C18: =C3/F3 -> 0 | D18: =D3/F3 -> 0.25 | E18: =E3/F3 -> 0.041666667
A19: D3 | B19: =B4/F4 -> 0.54166667 | C19: =C4/F4 -> 0.16666667 | D19: =D4/F4 -> 0.25 | E19: =E4/F4 -> 0.041666667
A20: D4 | B20: =B5/F5 -> 0.66666667 | C20: =C5/F5 -> 0.16666667 | D20: =D5/F5 -> 0.083333333 | E20: =E5/F5 -> 0.083333333
A21: D5 | B21: =B6/F6 -> 0.66666667 | C21: =C6/F6 -> 0.083333333 | D21: =D6/F6 -> 0.25 | E21: =E6/F6 -> 0
